package net.evildead.mod.worldgen.structure;

//Schematic to java Structure by jajo_11 | inspired by "MITHION'S .SCHEMATIC TO JAVA CONVERTINGTOOL"

import java.util.Random;

import net.minecraft.block.Block;
import net.minecraft.block.material.Material;
import net.minecraft.init.Blocks;
import net.minecraft.world.World;
import net.minecraft.world.gen.feature.WorldGenerator;


public class EvilCabin extends WorldGenerator
{
	private static Block UNKBLOCKA = Blocks.air;
	
	protected Block[] GetValidSpawnBlocks()
	{
		return new Block[]
		{
			Blocks.grass,
			Blocks.red_flower,
			Blocks.yellow_flower,
			Blocks.tallgrass,
			Blocks.sapling,
		};
	}

	public boolean LocationIsValidSpawn(World world, int x, int y, int z)
	{
		Block checkBlock = world.getBlock(x, y - 1, z);
		Block blockAbove = world.getBlock(x, y , z);
		Block blockBelow = world.getBlock(x, y - 2, z);

		for (Block i : GetValidSpawnBlocks())
		{
			if (blockAbove != Blocks.air)
			{
				return false;
			}
			if (checkBlock == i)
			{
				return true;
			}
			else if (checkBlock == Blocks.snow_layer && blockBelow == i)
			{
				return true;
			}
			else if (checkBlock.getMaterial() == Material.plants && blockBelow == i)
			{
				return true;
			}
		}
		return false;
	}

	public boolean generate(World world, Random rand, int x, int y, int z)
	{
		int i = 0;//rand.nextInt(1);

		if(i == 0)
		{
		    generate_r0(world, rand, x, y, z);
		}

     return true;

	}

	public boolean generate_r0(World world, Random rand, int x, int y, int z)
	{
		if(!LocationIsValidSpawn(world, x, y, z) || !LocationIsValidSpawn(world, x + 14, y, z))// || !LocationIsValidSpawn(world, x + 14, y, z + 29) || !LocationIsValidSpawn(world, x, y, z + 29))
		{
			return false;
		}

		System.out.println("CABIN GEN! - X:" + x + ", Y:" + y + ", Z:" + z);
		
		world.setBlock(x + 0, y + -7, z + 0, Blocks.stone, 0, 3);
		world.setBlock(x + 1, y + -7, z + 0, Blocks.stone, 0, 3);
		world.setBlock(x + 2, y + -7, z + 0, Blocks.stone, 0, 3);
		world.setBlock(x + 3, y + -7, z + 0, Blocks.stone, 0, 3);
		world.setBlock(x + 4, y + -7, z + 0, Blocks.monster_egg, 0, 3);
		world.setBlock(x + 5, y + -7, z + 0, Blocks.stone, 0, 3);
		world.setBlock(x + 6, y + -7, z + 0, Blocks.stone, 0, 3);
		world.setBlock(x + 7, y + -7, z + 0, Blocks.gravel, 0, 3);
		world.setBlock(x + 8, y + -7, z + 0, Blocks.gravel, 0, 3);
		world.setBlock(x + 9, y + -7, z + 0, Blocks.gravel, 0, 3);
		world.setBlock(x + 10, y + -7, z + 0, Blocks.gravel, 0, 3);
		world.setBlock(x + 11, y + -7, z + 0, Blocks.gravel, 0, 3);
		world.setBlock(x + 12, y + -7, z + 0, Blocks.stone, 0, 3);
		world.setBlock(x + 13, y + -7, z + 0, Blocks.stone, 0, 3);
		world.setBlock(x + 14, y + -7, z + 0, Blocks.stone, 0, 3);
		world.setBlock(x + 0, y + -7, z + 1, Blocks.stone, 0, 3);
		world.setBlock(x + 1, y + -7, z + 1, Blocks.stone, 0, 3);
		world.setBlock(x + 2, y + -7, z + 1, Blocks.stone, 0, 3);
		world.setBlock(x + 3, y + -7, z + 1, Blocks.stone, 0, 3);
		world.setBlock(x + 4, y + -7, z + 1, Blocks.stone, 0, 3);
		world.setBlock(x + 5, y + -7, z + 1, Blocks.stone, 0, 3);
		world.setBlock(x + 6, y + -7, z + 1, Blocks.stone, 0, 3);
		world.setBlock(x + 7, y + -7, z + 1, Blocks.gravel, 0, 3);
		world.setBlock(x + 8, y + -7, z + 1, Blocks.gravel, 0, 3);
		world.setBlock(x + 9, y + -7, z + 1, Blocks.gravel, 0, 3);
		world.setBlock(x + 10, y + -7, z + 1, Blocks.gravel, 0, 3);
		world.setBlock(x + 11, y + -7, z + 1, Blocks.gravel, 0, 3);
		world.setBlock(x + 12, y + -7, z + 1, Blocks.gravel, 0, 3);
		world.setBlock(x + 13, y + -7, z + 1, Blocks.stone, 0, 3);
		world.setBlock(x + 14, y + -7, z + 1, Blocks.stone, 0, 3);
		world.setBlock(x + 0, y + -7, z + 2, Blocks.coal_ore, 0, 3);
		world.setBlock(x + 1, y + -7, z + 2, Blocks.dirt, 0, 3);
		world.setBlock(x + 2, y + -7, z + 2, Blocks.dirt, 0, 3);
		world.setBlock(x + 3, y + -7, z + 2, Blocks.monster_egg, 0, 3);
		world.setBlock(x + 4, y + -7, z + 2, Blocks.stone, 0, 3);
		world.setBlock(x + 5, y + -7, z + 2, Blocks.stone, 0, 3);
		world.setBlock(x + 6, y + -7, z + 2, Blocks.stone, 0, 3);
		world.setBlock(x + 7, y + -7, z + 2, Blocks.stone, 0, 3);
		world.setBlock(x + 8, y + -7, z + 2, Blocks.gravel, 0, 3);
		world.setBlock(x + 9, y + -7, z + 2, Blocks.gravel, 0, 3);
		world.setBlock(x + 10, y + -7, z + 2, Blocks.gravel, 0, 3);
		world.setBlock(x + 11, y + -7, z + 2, Blocks.gravel, 0, 3);
		world.setBlock(x + 12, y + -7, z + 2, Blocks.gravel, 0, 3);
		world.setBlock(x + 13, y + -7, z + 2, Blocks.gravel, 0, 3);
		world.setBlock(x + 14, y + -7, z + 2, Blocks.stone, 0, 3);
		world.setBlock(x + 0, y + -7, z + 3, Blocks.coal_ore, 0, 3);
		world.setBlock(x + 1, y + -7, z + 3, Blocks.dirt, 0, 3);
		world.setBlock(x + 2, y + -7, z + 3, Blocks.dirt, 0, 3);
		world.setBlock(x + 3, y + -7, z + 3, Blocks.stone, 0, 3);
		world.setBlock(x + 4, y + -7, z + 3, Blocks.stone, 0, 3);
		world.setBlock(x + 5, y + -7, z + 3, Blocks.stone, 0, 3);
		world.setBlock(x + 6, y + -7, z + 3, Blocks.stone, 0, 3);
		world.setBlock(x + 7, y + -7, z + 3, Blocks.stone, 0, 3);
		world.setBlock(x + 8, y + -7, z + 3, Blocks.stone, 0, 3);
		world.setBlock(x + 9, y + -7, z + 3, Blocks.stone, 0, 3);
		world.setBlock(x + 10, y + -7, z + 3, Blocks.gravel, 0, 3);
		world.setBlock(x + 11, y + -7, z + 3, Blocks.gravel, 0, 3);
		world.setBlock(x + 12, y + -7, z + 3, Blocks.gravel, 0, 3);
		world.setBlock(x + 13, y + -7, z + 3, Blocks.dirt, 0, 3);
		world.setBlock(x + 14, y + -7, z + 3, Blocks.dirt, 0, 3);
		world.setBlock(x + 0, y + -7, z + 4, Blocks.stone, 0, 3);
		world.setBlock(x + 1, y + -7, z + 4, Blocks.dirt, 0, 3);
		world.setBlock(x + 2, y + -7, z + 4, Blocks.dirt, 0, 3);
		world.setBlock(x + 3, y + -7, z + 4, Blocks.dirt, 0, 3);
		world.setBlock(x + 4, y + -7, z + 4, Blocks.dirt, 0, 3);
		world.setBlock(x + 5, y + -7, z + 4, Blocks.dirt, 0, 3);
		world.setBlock(x + 6, y + -7, z + 4, Blocks.dirt, 0, 3);
		world.setBlock(x + 7, y + -7, z + 4, Blocks.dirt, 0, 3);
		world.setBlock(x + 8, y + -7, z + 4, Blocks.dirt, 0, 3);
		world.setBlock(x + 9, y + -7, z + 4, Blocks.dirt, 0, 3);
		world.setBlock(x + 10, y + -7, z + 4, Blocks.dirt, 0, 3);
		world.setBlock(x + 11, y + -7, z + 4, Blocks.dirt, 0, 3);
		world.setBlock(x + 12, y + -7, z + 4, Blocks.dirt, 0, 3);
		world.setBlock(x + 13, y + -7, z + 4, Blocks.dirt, 0, 3);
		world.setBlock(x + 14, y + -7, z + 4, Blocks.dirt, 0, 3);
		world.setBlock(x + 0, y + -7, z + 5, Blocks.stone, 0, 3);
		world.setBlock(x + 1, y + -7, z + 5, Blocks.dirt, 0, 3);
		world.setBlock(x + 2, y + -7, z + 5, Blocks.dirt, 0, 3);
		world.setBlock(x + 3, y + -7, z + 5, Blocks.dirt, 0, 3);
		world.setBlock(x + 4, y + -7, z + 5, Blocks.dirt, 0, 3);
		world.setBlock(x + 5, y + -7, z + 5, Blocks.dirt, 0, 3);
		world.setBlock(x + 6, y + -7, z + 5, Blocks.dirt, 0, 3);
		world.setBlock(x + 7, y + -7, z + 5, Blocks.dirt, 0, 3);
		world.setBlock(x + 8, y + -7, z + 5, Blocks.dirt, 0, 3);
		world.setBlock(x + 9, y + -7, z + 5, Blocks.dirt, 0, 3);
		world.setBlock(x + 10, y + -7, z + 5, Blocks.dirt, 0, 3);
		world.setBlock(x + 11, y + -7, z + 5, Blocks.dirt, 0, 3);
		world.setBlock(x + 12, y + -7, z + 5, Blocks.dirt, 0, 3);
		world.setBlock(x + 13, y + -7, z + 5, Blocks.dirt, 0, 3);
		world.setBlock(x + 14, y + -7, z + 5, Blocks.stone, 0, 3);
		world.setBlock(x + 0, y + -7, z + 6, Blocks.stone, 0, 3);
		world.setBlock(x + 1, y + -7, z + 6, Blocks.dirt, 0, 3);
		world.setBlock(x + 2, y + -7, z + 6, Blocks.dirt, 0, 3);
		world.setBlock(x + 3, y + -7, z + 6, Blocks.dirt, 0, 3);
		world.setBlock(x + 4, y + -7, z + 6, Blocks.dirt, 0, 3);
		world.setBlock(x + 5, y + -7, z + 6, Blocks.dirt, 0, 3);
		world.setBlock(x + 6, y + -7, z + 6, Blocks.dirt, 0, 3);
		world.setBlock(x + 7, y + -7, z + 6, Blocks.dirt, 0, 3);
		world.setBlock(x + 8, y + -7, z + 6, Blocks.dirt, 0, 3);
		world.setBlock(x + 9, y + -7, z + 6, Blocks.dirt, 0, 3);
		world.setBlock(x + 10, y + -7, z + 6, Blocks.dirt, 0, 3);
		world.setBlock(x + 11, y + -7, z + 6, Blocks.dirt, 0, 3);
		world.setBlock(x + 12, y + -7, z + 6, Blocks.dirt, 0, 3);
		world.setBlock(x + 13, y + -7, z + 6, Blocks.dirt, 0, 3);
		world.setBlock(x + 14, y + -7, z + 6, Blocks.dirt, 0, 3);
		world.setBlock(x + 0, y + -7, z + 7, Blocks.monster_egg, 0, 3);
		world.setBlock(x + 1, y + -7, z + 7, Blocks.dirt, 0, 3);
		world.setBlock(x + 2, y + -7, z + 7, Blocks.dirt, 0, 3);
		world.setBlock(x + 3, y + -7, z + 7, Blocks.dirt, 0, 3);
		world.setBlock(x + 4, y + -7, z + 7, Blocks.dirt, 0, 3);
		world.setBlock(x + 5, y + -7, z + 7, Blocks.dirt, 0, 3);
		world.setBlock(x + 6, y + -7, z + 7, Blocks.dirt, 0, 3);
		world.setBlock(x + 7, y + -7, z + 7, Blocks.dirt, 0, 3);
		world.setBlock(x + 8, y + -7, z + 7, Blocks.dirt, 0, 3);
		world.setBlock(x + 9, y + -7, z + 7, Blocks.dirt, 0, 3);
		world.setBlock(x + 10, y + -7, z + 7, Blocks.dirt, 0, 3);
		world.setBlock(x + 11, y + -7, z + 7, Blocks.dirt, 0, 3);
		world.setBlock(x + 12, y + -7, z + 7, Blocks.dirt, 0, 3);
		world.setBlock(x + 13, y + -7, z + 7, Blocks.dirt, 0, 3);
		world.setBlock(x + 14, y + -7, z + 7, Blocks.stone, 0, 3);
		world.setBlock(x + 0, y + -7, z + 8, Blocks.stone, 0, 3);
		world.setBlock(x + 1, y + -7, z + 8, Blocks.dirt, 0, 3);
		world.setBlock(x + 2, y + -7, z + 8, Blocks.dirt, 0, 3);
		world.setBlock(x + 3, y + -7, z + 8, Blocks.dirt, 0, 3);
		world.setBlock(x + 4, y + -7, z + 8, Blocks.dirt, 0, 3);
		world.setBlock(x + 5, y + -7, z + 8, Blocks.dirt, 0, 3);
		world.setBlock(x + 6, y + -7, z + 8, Blocks.dirt, 0, 3);
		world.setBlock(x + 7, y + -7, z + 8, Blocks.dirt, 0, 3);
		world.setBlock(x + 8, y + -7, z + 8, Blocks.dirt, 0, 3);
		world.setBlock(x + 9, y + -7, z + 8, Blocks.dirt, 0, 3);
		world.setBlock(x + 10, y + -7, z + 8, Blocks.dirt, 0, 3);
		world.setBlock(x + 11, y + -7, z + 8, Blocks.dirt, 0, 3);
		world.setBlock(x + 12, y + -7, z + 8, Blocks.dirt, 0, 3);
		world.setBlock(x + 13, y + -7, z + 8, Blocks.dirt, 0, 3);
		world.setBlock(x + 14, y + -7, z + 8, Blocks.stone, 0, 3);
		world.setBlock(x + 0, y + -7, z + 9, Blocks.iron_ore, 0, 3);
		world.setBlock(x + 1, y + -7, z + 9, Blocks.dirt, 0, 3);
		world.setBlock(x + 2, y + -7, z + 9, Blocks.dirt, 0, 3);
		world.setBlock(x + 3, y + -7, z + 9, Blocks.dirt, 0, 3);
		world.setBlock(x + 4, y + -7, z + 9, Blocks.dirt, 0, 3);
		world.setBlock(x + 5, y + -7, z + 9, Blocks.dirt, 0, 3);
		world.setBlock(x + 6, y + -7, z + 9, Blocks.dirt, 0, 3);
		world.setBlock(x + 7, y + -7, z + 9, Blocks.dirt, 0, 3);
		world.setBlock(x + 8, y + -7, z + 9, Blocks.dirt, 0, 3);
		world.setBlock(x + 9, y + -7, z + 9, Blocks.dirt, 0, 3);
		world.setBlock(x + 10, y + -7, z + 9, Blocks.dirt, 0, 3);
		world.setBlock(x + 11, y + -7, z + 9, Blocks.dirt, 0, 3);
		world.setBlock(x + 12, y + -7, z + 9, Blocks.dirt, 0, 3);
		world.setBlock(x + 13, y + -7, z + 9, Blocks.dirt, 0, 3);
		world.setBlock(x + 14, y + -7, z + 9, Blocks.stone, 0, 3);
		world.setBlock(x + 0, y + -7, z + 10, Blocks.iron_ore, 0, 3);
		world.setBlock(x + 1, y + -7, z + 10, Blocks.dirt, 0, 3);
		world.setBlock(x + 2, y + -7, z + 10, Blocks.dirt, 0, 3);
		world.setBlock(x + 3, y + -7, z + 10, Blocks.dirt, 0, 3);
		world.setBlock(x + 4, y + -7, z + 10, Blocks.dirt, 0, 3);
		world.setBlock(x + 5, y + -7, z + 10, Blocks.dirt, 0, 3);
		world.setBlock(x + 6, y + -7, z + 10, Blocks.dirt, 0, 3);
		world.setBlock(x + 7, y + -7, z + 10, Blocks.dirt, 0, 3);
		world.setBlock(x + 8, y + -7, z + 10, Blocks.dirt, 0, 3);
		world.setBlock(x + 9, y + -7, z + 10, Blocks.dirt, 0, 3);
		world.setBlock(x + 10, y + -7, z + 10, Blocks.dirt, 0, 3);
		world.setBlock(x + 11, y + -7, z + 10, Blocks.dirt, 0, 3);
		world.setBlock(x + 12, y + -7, z + 10, Blocks.dirt, 0, 3);
		world.setBlock(x + 13, y + -7, z + 10, Blocks.dirt, 0, 3);
		world.setBlock(x + 14, y + -7, z + 10, Blocks.stone, 0, 3);
		world.setBlock(x + 0, y + -7, z + 11, Blocks.stone, 0, 3);
		world.setBlock(x + 1, y + -7, z + 11, Blocks.dirt, 0, 3);
		world.setBlock(x + 2, y + -7, z + 11, Blocks.dirt, 0, 3);
		world.setBlock(x + 3, y + -7, z + 11, Blocks.dirt, 0, 3);
		world.setBlock(x + 4, y + -7, z + 11, Blocks.dirt, 0, 3);
		world.setBlock(x + 5, y + -7, z + 11, Blocks.dirt, 0, 3);
		world.setBlock(x + 6, y + -7, z + 11, Blocks.dirt, 0, 3);
		world.setBlock(x + 7, y + -7, z + 11, Blocks.dirt, 0, 3);
		world.setBlock(x + 8, y + -7, z + 11, Blocks.dirt, 0, 3);
		world.setBlock(x + 9, y + -7, z + 11, Blocks.dirt, 0, 3);
		world.setBlock(x + 10, y + -7, z + 11, Blocks.dirt, 0, 3);
		world.setBlock(x + 11, y + -7, z + 11, Blocks.dirt, 0, 3);
		world.setBlock(x + 12, y + -7, z + 11, Blocks.dirt, 0, 3);
		world.setBlock(x + 13, y + -7, z + 11, Blocks.dirt, 0, 3);
		world.setBlock(x + 14, y + -7, z + 11, Blocks.stone, 0, 3);
		world.setBlock(x + 0, y + -7, z + 12, Blocks.stone, 0, 3);
		world.setBlock(x + 1, y + -7, z + 12, Blocks.dirt, 0, 3);
		world.setBlock(x + 2, y + -7, z + 12, Blocks.dirt, 0, 3);
		world.setBlock(x + 3, y + -7, z + 12, Blocks.dirt, 0, 3);
		world.setBlock(x + 4, y + -7, z + 12, Blocks.dirt, 0, 3);
		world.setBlock(x + 5, y + -7, z + 12, Blocks.dirt, 0, 3);
		world.setBlock(x + 6, y + -7, z + 12, Blocks.dirt, 0, 3);
		world.setBlock(x + 7, y + -7, z + 12, Blocks.dirt, 0, 3);
		world.setBlock(x + 8, y + -7, z + 12, Blocks.dirt, 0, 3);
		world.setBlock(x + 9, y + -7, z + 12, Blocks.dirt, 0, 3);
		world.setBlock(x + 10, y + -7, z + 12, Blocks.dirt, 0, 3);
		world.setBlock(x + 11, y + -7, z + 12, Blocks.dirt, 0, 3);
		world.setBlock(x + 12, y + -7, z + 12, Blocks.dirt, 0, 3);
		world.setBlock(x + 13, y + -7, z + 12, Blocks.dirt, 0, 3);
		world.setBlock(x + 14, y + -7, z + 12, Blocks.stone, 0, 3);
		world.setBlock(x + 0, y + -7, z + 13, Blocks.stone, 0, 3);
		world.setBlock(x + 1, y + -7, z + 13, Blocks.dirt, 0, 3);
		world.setBlock(x + 2, y + -7, z + 13, Blocks.dirt, 0, 3);
		world.setBlock(x + 3, y + -7, z + 13, Blocks.dirt, 0, 3);
		world.setBlock(x + 4, y + -7, z + 13, Blocks.dirt, 0, 3);
		world.setBlock(x + 5, y + -7, z + 13, Blocks.dirt, 0, 3);
		world.setBlock(x + 6, y + -7, z + 13, Blocks.dirt, 0, 3);
		world.setBlock(x + 7, y + -7, z + 13, Blocks.dirt, 0, 3);
		world.setBlock(x + 8, y + -7, z + 13, Blocks.dirt, 0, 3);
		world.setBlock(x + 9, y + -7, z + 13, Blocks.dirt, 0, 3);
		world.setBlock(x + 10, y + -7, z + 13, Blocks.dirt, 0, 3);
		world.setBlock(x + 11, y + -7, z + 13, Blocks.dirt, 0, 3);
		world.setBlock(x + 12, y + -7, z + 13, Blocks.dirt, 0, 3);
		world.setBlock(x + 13, y + -7, z + 13, Blocks.dirt, 0, 3);
		world.setBlock(x + 14, y + -7, z + 13, Blocks.stone, 0, 3);
		world.setBlock(x + 0, y + -7, z + 14, Blocks.stone, 0, 3);
		world.setBlock(x + 1, y + -7, z + 14, Blocks.dirt, 0, 3);
		world.setBlock(x + 2, y + -7, z + 14, Blocks.dirt, 0, 3);
		world.setBlock(x + 3, y + -7, z + 14, Blocks.dirt, 0, 3);
		world.setBlock(x + 4, y + -7, z + 14, Blocks.dirt, 0, 3);
		world.setBlock(x + 5, y + -7, z + 14, Blocks.dirt, 0, 3);
		world.setBlock(x + 6, y + -7, z + 14, Blocks.dirt, 0, 3);
		world.setBlock(x + 7, y + -7, z + 14, Blocks.dirt, 0, 3);
		world.setBlock(x + 8, y + -7, z + 14, Blocks.dirt, 0, 3);
		world.setBlock(x + 9, y + -7, z + 14, Blocks.dirt, 0, 3);
		world.setBlock(x + 10, y + -7, z + 14, Blocks.dirt, 0, 3);
		world.setBlock(x + 11, y + -7, z + 14, Blocks.dirt, 0, 3);
		world.setBlock(x + 12, y + -7, z + 14, Blocks.dirt, 0, 3);
		world.setBlock(x + 13, y + -7, z + 14, Blocks.dirt, 0, 3);
		world.setBlock(x + 14, y + -7, z + 14, Blocks.stone, 0, 3);
		world.setBlock(x + 0, y + -7, z + 15, Blocks.stone, 0, 3);
		world.setBlock(x + 1, y + -7, z + 15, Blocks.dirt, 0, 3);
		world.setBlock(x + 2, y + -7, z + 15, Blocks.dirt, 0, 3);
		world.setBlock(x + 3, y + -7, z + 15, Blocks.dirt, 0, 3);
		world.setBlock(x + 4, y + -7, z + 15, Blocks.dirt, 0, 3);
		world.setBlock(x + 5, y + -7, z + 15, Blocks.dirt, 0, 3);
		world.setBlock(x + 6, y + -7, z + 15, Blocks.dirt, 0, 3);
		world.setBlock(x + 7, y + -7, z + 15, Blocks.dirt, 0, 3);
		world.setBlock(x + 8, y + -7, z + 15, Blocks.dirt, 0, 3);
		world.setBlock(x + 9, y + -7, z + 15, Blocks.dirt, 0, 3);
		world.setBlock(x + 10, y + -7, z + 15, Blocks.dirt, 0, 3);
		world.setBlock(x + 11, y + -7, z + 15, Blocks.dirt, 0, 3);
		world.setBlock(x + 12, y + -7, z + 15, Blocks.dirt, 0, 3);
		world.setBlock(x + 13, y + -7, z + 15, Blocks.dirt, 0, 3);
		world.setBlock(x + 14, y + -7, z + 15, Blocks.stone, 0, 3);
		world.setBlock(x + 0, y + -7, z + 16, Blocks.stone, 0, 3);
		world.setBlock(x + 1, y + -7, z + 16, Blocks.dirt, 0, 3);
		world.setBlock(x + 2, y + -7, z + 16, Blocks.dirt, 0, 3);
		world.setBlock(x + 3, y + -7, z + 16, Blocks.dirt, 0, 3);
		world.setBlock(x + 4, y + -7, z + 16, Blocks.dirt, 0, 3);
		world.setBlock(x + 5, y + -7, z + 16, Blocks.dirt, 0, 3);
		world.setBlock(x + 6, y + -7, z + 16, Blocks.dirt, 0, 3);
		world.setBlock(x + 7, y + -7, z + 16, Blocks.dirt, 0, 3);
		world.setBlock(x + 8, y + -7, z + 16, Blocks.dirt, 0, 3);
		world.setBlock(x + 9, y + -7, z + 16, Blocks.dirt, 0, 3);
		world.setBlock(x + 10, y + -7, z + 16, Blocks.dirt, 0, 3);
		world.setBlock(x + 11, y + -7, z + 16, Blocks.dirt, 0, 3);
		world.setBlock(x + 12, y + -7, z + 16, Blocks.dirt, 0, 3);
		world.setBlock(x + 13, y + -7, z + 16, Blocks.dirt, 0, 3);
		world.setBlock(x + 14, y + -7, z + 16, Blocks.stone, 0, 3);
		world.setBlock(x + 0, y + -7, z + 17, Blocks.stone, 0, 3);
		world.setBlock(x + 1, y + -7, z + 17, Blocks.dirt, 0, 3);
		world.setBlock(x + 2, y + -7, z + 17, Blocks.dirt, 0, 3);
		world.setBlock(x + 3, y + -7, z + 17, Blocks.dirt, 0, 3);
		world.setBlock(x + 4, y + -7, z + 17, Blocks.dirt, 0, 3);
		world.setBlock(x + 5, y + -7, z + 17, Blocks.dirt, 0, 3);
		world.setBlock(x + 6, y + -7, z + 17, Blocks.dirt, 0, 3);
		world.setBlock(x + 7, y + -7, z + 17, Blocks.dirt, 0, 3);
		world.setBlock(x + 8, y + -7, z + 17, Blocks.dirt, 0, 3);
		world.setBlock(x + 9, y + -7, z + 17, Blocks.dirt, 0, 3);
		world.setBlock(x + 10, y + -7, z + 17, Blocks.dirt, 0, 3);
		world.setBlock(x + 11, y + -7, z + 17, Blocks.dirt, 0, 3);
		world.setBlock(x + 12, y + -7, z + 17, Blocks.dirt, 0, 3);
		world.setBlock(x + 13, y + -7, z + 17, Blocks.dirt, 0, 3);
		world.setBlock(x + 14, y + -7, z + 17, Blocks.stone, 0, 3);
		world.setBlock(x + 0, y + -7, z + 18, Blocks.stone, 0, 3);
		world.setBlock(x + 1, y + -7, z + 18, Blocks.dirt, 0, 3);
		world.setBlock(x + 2, y + -7, z + 18, Blocks.dirt, 0, 3);
		world.setBlock(x + 3, y + -7, z + 18, Blocks.dirt, 0, 3);
		world.setBlock(x + 4, y + -7, z + 18, Blocks.dirt, 0, 3);
		world.setBlock(x + 5, y + -7, z + 18, Blocks.dirt, 0, 3);
		world.setBlock(x + 6, y + -7, z + 18, Blocks.dirt, 0, 3);
		world.setBlock(x + 7, y + -7, z + 18, Blocks.dirt, 0, 3);
		world.setBlock(x + 8, y + -7, z + 18, Blocks.dirt, 0, 3);
		world.setBlock(x + 9, y + -7, z + 18, Blocks.dirt, 0, 3);
		world.setBlock(x + 10, y + -7, z + 18, Blocks.dirt, 0, 3);
		world.setBlock(x + 11, y + -7, z + 18, Blocks.dirt, 0, 3);
		world.setBlock(x + 12, y + -7, z + 18, Blocks.dirt, 0, 3);
		world.setBlock(x + 13, y + -7, z + 18, Blocks.dirt, 0, 3);
		world.setBlock(x + 14, y + -7, z + 18, Blocks.stone, 0, 3);
		world.setBlock(x + 0, y + -7, z + 19, Blocks.stone, 0, 3);
		world.setBlock(x + 1, y + -7, z + 19, Blocks.dirt, 0, 3);
		world.setBlock(x + 2, y + -7, z + 19, Blocks.dirt, 0, 3);
		world.setBlock(x + 3, y + -7, z + 19, Blocks.dirt, 0, 3);
		world.setBlock(x + 4, y + -7, z + 19, Blocks.dirt, 0, 3);
		world.setBlock(x + 5, y + -7, z + 19, Blocks.dirt, 0, 3);
		world.setBlock(x + 6, y + -7, z + 19, Blocks.dirt, 0, 3);
		world.setBlock(x + 7, y + -7, z + 19, Blocks.dirt, 0, 3);
		world.setBlock(x + 8, y + -7, z + 19, Blocks.dirt, 0, 3);
		world.setBlock(x + 9, y + -7, z + 19, Blocks.dirt, 0, 3);
		world.setBlock(x + 10, y + -7, z + 19, Blocks.dirt, 0, 3);
		world.setBlock(x + 11, y + -7, z + 19, Blocks.dirt, 0, 3);
		world.setBlock(x + 12, y + -7, z + 19, Blocks.dirt, 0, 3);
		world.setBlock(x + 13, y + -7, z + 19, Blocks.dirt, 0, 3);
		world.setBlock(x + 14, y + -7, z + 19, Blocks.stone, 0, 3);
		world.setBlock(x + 0, y + -7, z + 20, Blocks.stone, 0, 3);
		world.setBlock(x + 1, y + -7, z + 20, Blocks.dirt, 0, 3);
		world.setBlock(x + 2, y + -7, z + 20, Blocks.dirt, 0, 3);
		world.setBlock(x + 3, y + -7, z + 20, Blocks.dirt, 0, 3);
		world.setBlock(x + 4, y + -7, z + 20, Blocks.dirt, 0, 3);
		world.setBlock(x + 5, y + -7, z + 20, Blocks.dirt, 0, 3);
		world.setBlock(x + 6, y + -7, z + 20, Blocks.dirt, 0, 3);
		world.setBlock(x + 7, y + -7, z + 20, Blocks.dirt, 0, 3);
		world.setBlock(x + 8, y + -7, z + 20, Blocks.dirt, 0, 3);
		world.setBlock(x + 9, y + -7, z + 20, Blocks.dirt, 0, 3);
		world.setBlock(x + 10, y + -7, z + 20, Blocks.dirt, 0, 3);
		world.setBlock(x + 11, y + -7, z + 20, Blocks.dirt, 0, 3);
		world.setBlock(x + 12, y + -7, z + 20, Blocks.dirt, 0, 3);
		world.setBlock(x + 13, y + -7, z + 20, Blocks.dirt, 0, 3);
		world.setBlock(x + 14, y + -7, z + 20, Blocks.stone, 0, 3);
		world.setBlock(x + 0, y + -7, z + 21, Blocks.stone, 0, 3);
		world.setBlock(x + 1, y + -7, z + 21, Blocks.dirt, 0, 3);
		world.setBlock(x + 2, y + -7, z + 21, Blocks.dirt, 0, 3);
		world.setBlock(x + 3, y + -7, z + 21, Blocks.dirt, 0, 3);
		world.setBlock(x + 4, y + -7, z + 21, Blocks.dirt, 0, 3);
		world.setBlock(x + 5, y + -7, z + 21, Blocks.dirt, 0, 3);
		world.setBlock(x + 6, y + -7, z + 21, Blocks.dirt, 0, 3);
		world.setBlock(x + 7, y + -7, z + 21, Blocks.dirt, 0, 3);
		world.setBlock(x + 8, y + -7, z + 21, Blocks.dirt, 0, 3);
		world.setBlock(x + 9, y + -7, z + 21, Blocks.dirt, 0, 3);
		world.setBlock(x + 10, y + -7, z + 21, Blocks.dirt, 0, 3);
		world.setBlock(x + 11, y + -7, z + 21, Blocks.dirt, 0, 3);
		world.setBlock(x + 12, y + -7, z + 21, Blocks.dirt, 0, 3);
		world.setBlock(x + 13, y + -7, z + 21, Blocks.dirt, 0, 3);
		world.setBlock(x + 14, y + -7, z + 21, Blocks.stone, 0, 3);
		world.setBlock(x + 0, y + -7, z + 22, Blocks.stone, 0, 3);
		world.setBlock(x + 1, y + -7, z + 22, Blocks.dirt, 0, 3);
		world.setBlock(x + 2, y + -7, z + 22, Blocks.dirt, 0, 3);
		world.setBlock(x + 3, y + -7, z + 22, Blocks.dirt, 0, 3);
		world.setBlock(x + 4, y + -7, z + 22, Blocks.dirt, 0, 3);
		world.setBlock(x + 5, y + -7, z + 22, Blocks.dirt, 0, 3);
		world.setBlock(x + 6, y + -7, z + 22, Blocks.dirt, 0, 3);
		world.setBlock(x + 7, y + -7, z + 22, Blocks.dirt, 0, 3);
		world.setBlock(x + 8, y + -7, z + 22, Blocks.dirt, 0, 3);
		world.setBlock(x + 9, y + -7, z + 22, Blocks.dirt, 0, 3);
		world.setBlock(x + 10, y + -7, z + 22, Blocks.dirt, 0, 3);
		world.setBlock(x + 11, y + -7, z + 22, Blocks.dirt, 0, 3);
		world.setBlock(x + 12, y + -7, z + 22, Blocks.dirt, 0, 3);
		world.setBlock(x + 13, y + -7, z + 22, Blocks.dirt, 0, 3);
		world.setBlock(x + 14, y + -7, z + 22, Blocks.coal_ore, 0, 3);
		world.setBlock(x + 0, y + -7, z + 23, Blocks.stone, 0, 3);
		world.setBlock(x + 1, y + -7, z + 23, Blocks.dirt, 0, 3);
		world.setBlock(x + 2, y + -7, z + 23, Blocks.dirt, 0, 3);
		world.setBlock(x + 3, y + -7, z + 23, Blocks.dirt, 0, 3);
		world.setBlock(x + 4, y + -7, z + 23, Blocks.dirt, 0, 3);
		world.setBlock(x + 5, y + -7, z + 23, Blocks.dirt, 0, 3);
		world.setBlock(x + 6, y + -7, z + 23, Blocks.dirt, 0, 3);
		world.setBlock(x + 7, y + -7, z + 23, Blocks.dirt, 0, 3);
		world.setBlock(x + 8, y + -7, z + 23, Blocks.dirt, 0, 3);
		world.setBlock(x + 9, y + -7, z + 23, Blocks.dirt, 0, 3);
		world.setBlock(x + 10, y + -7, z + 23, Blocks.dirt, 0, 3);
		world.setBlock(x + 11, y + -7, z + 23, Blocks.dirt, 0, 3);
		world.setBlock(x + 12, y + -7, z + 23, Blocks.dirt, 0, 3);
		world.setBlock(x + 13, y + -7, z + 23, Blocks.dirt, 0, 3);
		world.setBlock(x + 14, y + -7, z + 23, Blocks.stone, 0, 3);
		world.setBlock(x + 0, y + -7, z + 24, Blocks.stone, 0, 3);
		world.setBlock(x + 1, y + -7, z + 24, Blocks.dirt, 0, 3);
		world.setBlock(x + 2, y + -7, z + 24, Blocks.dirt, 0, 3);
		world.setBlock(x + 3, y + -7, z + 24, Blocks.dirt, 0, 3);
		world.setBlock(x + 4, y + -7, z + 24, Blocks.dirt, 0, 3);
		world.setBlock(x + 5, y + -7, z + 24, Blocks.dirt, 0, 3);
		world.setBlock(x + 6, y + -7, z + 24, Blocks.dirt, 0, 3);
		world.setBlock(x + 7, y + -7, z + 24, Blocks.dirt, 0, 3);
		world.setBlock(x + 8, y + -7, z + 24, Blocks.dirt, 0, 3);
		world.setBlock(x + 9, y + -7, z + 24, Blocks.dirt, 0, 3);
		world.setBlock(x + 10, y + -7, z + 24, Blocks.dirt, 0, 3);
		world.setBlock(x + 11, y + -7, z + 24, Blocks.dirt, 0, 3);
		world.setBlock(x + 12, y + -7, z + 24, Blocks.dirt, 0, 3);
		world.setBlock(x + 13, y + -7, z + 24, Blocks.dirt, 0, 3);
		world.setBlock(x + 14, y + -7, z + 24, Blocks.stone, 0, 3);
		world.setBlock(x + 0, y + -7, z + 25, Blocks.stone, 0, 3);
		world.setBlock(x + 1, y + -7, z + 25, Blocks.dirt, 0, 3);
		world.setBlock(x + 2, y + -7, z + 25, Blocks.dirt, 0, 3);
		world.setBlock(x + 3, y + -7, z + 25, Blocks.dirt, 0, 3);
		world.setBlock(x + 4, y + -7, z + 25, Blocks.dirt, 0, 3);
		world.setBlock(x + 5, y + -7, z + 25, Blocks.dirt, 0, 3);
		world.setBlock(x + 6, y + -7, z + 25, Blocks.dirt, 0, 3);
		world.setBlock(x + 7, y + -7, z + 25, Blocks.dirt, 0, 3);
		world.setBlock(x + 8, y + -7, z + 25, Blocks.dirt, 0, 3);
		world.setBlock(x + 9, y + -7, z + 25, Blocks.dirt, 0, 3);
		world.setBlock(x + 10, y + -7, z + 25, Blocks.dirt, 0, 3);
		world.setBlock(x + 11, y + -7, z + 25, Blocks.dirt, 0, 3);
		world.setBlock(x + 12, y + -7, z + 25, Blocks.dirt, 0, 3);
		world.setBlock(x + 13, y + -7, z + 25, Blocks.dirt, 0, 3);
		world.setBlock(x + 14, y + -7, z + 25, Blocks.stone, 0, 3);
		world.setBlock(x + 0, y + -7, z + 26, Blocks.stone, 0, 3);
		world.setBlock(x + 1, y + -7, z + 26, Blocks.dirt, 0, 3);
		world.setBlock(x + 2, y + -7, z + 26, Blocks.dirt, 0, 3);
		world.setBlock(x + 3, y + -7, z + 26, Blocks.dirt, 0, 3);
		world.setBlock(x + 4, y + -7, z + 26, Blocks.dirt, 0, 3);
		world.setBlock(x + 5, y + -7, z + 26, Blocks.dirt, 0, 3);
		world.setBlock(x + 6, y + -7, z + 26, Blocks.dirt, 0, 3);
		world.setBlock(x + 7, y + -7, z + 26, Blocks.dirt, 0, 3);
		world.setBlock(x + 8, y + -7, z + 26, Blocks.dirt, 0, 3);
		world.setBlock(x + 9, y + -7, z + 26, Blocks.dirt, 0, 3);
		world.setBlock(x + 10, y + -7, z + 26, Blocks.dirt, 0, 3);
		world.setBlock(x + 11, y + -7, z + 26, Blocks.dirt, 0, 3);
		world.setBlock(x + 12, y + -7, z + 26, Blocks.dirt, 0, 3);
		world.setBlock(x + 13, y + -7, z + 26, Blocks.dirt, 0, 3);
		world.setBlock(x + 14, y + -7, z + 26, Blocks.stone, 0, 3);
		world.setBlock(x + 0, y + -7, z + 27, Blocks.stone, 0, 3);
		world.setBlock(x + 1, y + -7, z + 27, Blocks.dirt, 0, 3);
		world.setBlock(x + 2, y + -7, z + 27, Blocks.dirt, 0, 3);
		world.setBlock(x + 3, y + -7, z + 27, Blocks.dirt, 0, 3);
		world.setBlock(x + 4, y + -7, z + 27, Blocks.dirt, 0, 3);
		world.setBlock(x + 5, y + -7, z + 27, Blocks.dirt, 0, 3);
		world.setBlock(x + 6, y + -7, z + 27, Blocks.dirt, 0, 3);
		world.setBlock(x + 7, y + -7, z + 27, Blocks.dirt, 0, 3);
		world.setBlock(x + 8, y + -7, z + 27, Blocks.dirt, 0, 3);
		world.setBlock(x + 9, y + -7, z + 27, Blocks.dirt, 0, 3);
		world.setBlock(x + 10, y + -7, z + 27, Blocks.dirt, 0, 3);
		world.setBlock(x + 11, y + -7, z + 27, Blocks.dirt, 0, 3);
		world.setBlock(x + 12, y + -7, z + 27, Blocks.dirt, 0, 3);
		world.setBlock(x + 13, y + -7, z + 27, Blocks.dirt, 0, 3);
		world.setBlock(x + 14, y + -7, z + 27, Blocks.stone, 0, 3);
		world.setBlock(x + 0, y + -7, z + 28, Blocks.stone, 0, 3);
		world.setBlock(x + 1, y + -7, z + 28, Blocks.dirt, 0, 3);
		world.setBlock(x + 2, y + -7, z + 28, Blocks.dirt, 0, 3);
		world.setBlock(x + 3, y + -7, z + 28, Blocks.dirt, 0, 3);
		world.setBlock(x + 4, y + -7, z + 28, Blocks.dirt, 0, 3);
		world.setBlock(x + 5, y + -7, z + 28, Blocks.dirt, 0, 3);
		world.setBlock(x + 6, y + -7, z + 28, Blocks.dirt, 0, 3);
		world.setBlock(x + 7, y + -7, z + 28, Blocks.dirt, 0, 3);
		world.setBlock(x + 8, y + -7, z + 28, Blocks.dirt, 0, 3);
		world.setBlock(x + 9, y + -7, z + 28, Blocks.dirt, 0, 3);
		world.setBlock(x + 10, y + -7, z + 28, Blocks.dirt, 0, 3);
		world.setBlock(x + 11, y + -7, z + 28, Blocks.dirt, 0, 3);
		world.setBlock(x + 12, y + -7, z + 28, Blocks.dirt, 0, 3);
		world.setBlock(x + 13, y + -7, z + 28, Blocks.dirt, 0, 3);
		world.setBlock(x + 14, y + -7, z + 28, Blocks.stone, 0, 3);
		world.setBlock(x + 0, y + -7, z + 29, Blocks.stone, 0, 3);
		world.setBlock(x + 1, y + -7, z + 29, Blocks.stone, 0, 3);
		world.setBlock(x + 2, y + -7, z + 29, Blocks.stone, 0, 3);
		world.setBlock(x + 3, y + -7, z + 29, Blocks.stone, 0, 3);
		world.setBlock(x + 4, y + -7, z + 29, Blocks.stone, 0, 3);
		world.setBlock(x + 5, y + -7, z + 29, Blocks.stone, 0, 3);
		world.setBlock(x + 6, y + -7, z + 29, Blocks.stone, 0, 3);
		world.setBlock(x + 7, y + -7, z + 29, Blocks.stone, 0, 3);
		world.setBlock(x + 8, y + -7, z + 29, Blocks.stone, 0, 3);
		world.setBlock(x + 9, y + -7, z + 29, Blocks.stone, 0, 3);
		world.setBlock(x + 10, y + -7, z + 29, Blocks.stone, 0, 3);
		world.setBlock(x + 11, y + -7, z + 29, Blocks.stone, 0, 3);
		world.setBlock(x + 12, y + -7, z + 29, Blocks.stone, 0, 3);
		world.setBlock(x + 13, y + -7, z + 29, Blocks.stone, 0, 3);
		world.setBlock(x + 14, y + -7, z + 29, Blocks.stone, 0, 3);
		world.setBlock(x + 0, y + -6, z + 0, Blocks.dirt, 0, 3);
		world.setBlock(x + 1, y + -6, z + 0, Blocks.dirt, 0, 3);
		world.setBlock(x + 2, y + -6, z + 0, Blocks.dirt, 0, 3);
		world.setBlock(x + 3, y + -6, z + 0, Blocks.dirt, 0, 3);
		world.setBlock(x + 4, y + -6, z + 0, Blocks.dirt, 0, 3);
		world.setBlock(x + 5, y + -6, z + 0, Blocks.dirt, 0, 3);
		world.setBlock(x + 6, y + -6, z + 0, Blocks.dirt, 0, 3);
		world.setBlock(x + 7, y + -6, z + 0, Blocks.dirt, 0, 3);
		world.setBlock(x + 8, y + -6, z + 0, Blocks.dirt, 0, 3);
		world.setBlock(x + 9, y + -6, z + 0, Blocks.dirt, 0, 3);
		world.setBlock(x + 10, y + -6, z + 0, Blocks.dirt, 0, 3);
		world.setBlock(x + 11, y + -6, z + 0, Blocks.dirt, 0, 3);
		world.setBlock(x + 12, y + -6, z + 0, Blocks.dirt, 0, 3);
		world.setBlock(x + 13, y + -6, z + 0, Blocks.dirt, 0, 3);
		world.setBlock(x + 14, y + -6, z + 0, Blocks.stone, 0, 3);
		world.setBlock(x + 0, y + -6, z + 1, Blocks.dirt, 0, 3);
		world.setBlock(x + 1, y + -6, z + 1, Blocks.dirt, 0, 3);
		world.setBlock(x + 2, y + -6, z + 1, Blocks.dirt, 0, 3);
		world.setBlock(x + 3, y + -6, z + 1, Blocks.dirt, 0, 3);
		world.setBlock(x + 4, y + -6, z + 1, Blocks.dirt, 0, 3);
		world.setBlock(x + 5, y + -6, z + 1, Blocks.dirt, 0, 3);
		world.setBlock(x + 6, y + -6, z + 1, Blocks.dirt, 0, 3);
		world.setBlock(x + 7, y + -6, z + 1, Blocks.dirt, 0, 3);
		world.setBlock(x + 8, y + -6, z + 1, Blocks.dirt, 0, 3);
		world.setBlock(x + 9, y + -6, z + 1, Blocks.dirt, 0, 3);
		world.setBlock(x + 10, y + -6, z + 1, Blocks.dirt, 0, 3);
		world.setBlock(x + 11, y + -6, z + 1, Blocks.dirt, 0, 3);
		world.setBlock(x + 12, y + -6, z + 1, Blocks.dirt, 0, 3);
		world.setBlock(x + 13, y + -6, z + 1, Blocks.dirt, 0, 3);
		world.setBlock(x + 14, y + -6, z + 1, Blocks.stone, 0, 3);
		world.setBlock(x + 0, y + -6, z + 2, Blocks.dirt, 0, 3);
		world.setBlock(x + 1, y + -6, z + 2, Blocks.dirt, 0, 3);
		world.setBlock(x + 2, y + -6, z + 2, Blocks.dirt, 0, 3);
		world.setBlock(x + 3, y + -6, z + 2, Blocks.dirt, 0, 3);
		world.setBlock(x + 4, y + -6, z + 2, Blocks.dirt, 0, 3);
		world.setBlock(x + 5, y + -6, z + 2, Blocks.dirt, 0, 3);
		world.setBlock(x + 6, y + -6, z + 2, Blocks.dirt, 0, 3);
		world.setBlock(x + 7, y + -6, z + 2, Blocks.dirt, 0, 3);
		world.setBlock(x + 8, y + -6, z + 2, Blocks.dirt, 0, 3);
		world.setBlock(x + 9, y + -6, z + 2, Blocks.dirt, 0, 3);
		world.setBlock(x + 10, y + -6, z + 2, Blocks.dirt, 0, 3);
		world.setBlock(x + 11, y + -6, z + 2, Blocks.dirt, 0, 3);
		world.setBlock(x + 12, y + -6, z + 2, Blocks.dirt, 0, 3);
		world.setBlock(x + 13, y + -6, z + 2, Blocks.dirt, 0, 3);
		world.setBlock(x + 14, y + -6, z + 2, Blocks.dirt, 0, 3);
		world.setBlock(x + 0, y + -6, z + 3, Blocks.dirt, 0, 3);
		world.setBlock(x + 1, y + -6, z + 3, Blocks.dirt, 0, 3);
		world.setBlock(x + 2, y + -6, z + 3, Blocks.dirt, 0, 3);
		world.setBlock(x + 3, y + -6, z + 3, Blocks.dirt, 0, 3);
		world.setBlock(x + 4, y + -6, z + 3, Blocks.dirt, 0, 3);
		world.setBlock(x + 5, y + -6, z + 3, Blocks.dirt, 0, 3);
		world.setBlock(x + 6, y + -6, z + 3, Blocks.dirt, 0, 3);
		world.setBlock(x + 7, y + -6, z + 3, Blocks.dirt, 0, 3);
		world.setBlock(x + 8, y + -6, z + 3, Blocks.dirt, 0, 3);
		world.setBlock(x + 9, y + -6, z + 3, Blocks.dirt, 0, 3);
		world.setBlock(x + 10, y + -6, z + 3, Blocks.dirt, 0, 3);
		world.setBlock(x + 11, y + -6, z + 3, Blocks.dirt, 0, 3);
		world.setBlock(x + 12, y + -6, z + 3, Blocks.dirt, 0, 3);
		world.setBlock(x + 13, y + -6, z + 3, Blocks.dirt, 0, 3);
		world.setBlock(x + 14, y + -6, z + 3, Blocks.stone, 0, 3);
		world.setBlock(x + 0, y + -6, z + 4, Blocks.dirt, 0, 3);
		world.setBlock(x + 1, y + -6, z + 4, Blocks.dirt, 0, 3);
		world.setBlock(x + 2, y + -6, z + 4, Blocks.dirt, 0, 3);
		world.setBlock(x + 3, y + -6, z + 4, Blocks.dirt, 0, 3);
		world.setBlock(x + 4, y + -6, z + 4, Blocks.dirt, 0, 3);
		world.setBlock(x + 5, y + -6, z + 4, Blocks.dirt, 0, 3);
		world.setBlock(x + 6, y + -6, z + 4, Blocks.dirt, 0, 3);
		world.setBlock(x + 7, y + -6, z + 4, Blocks.dirt, 0, 3);
		world.setBlock(x + 8, y + -6, z + 4, Blocks.dirt, 0, 3);
		world.setBlock(x + 9, y + -6, z + 4, Blocks.dirt, 0, 3);
		world.setBlock(x + 10, y + -6, z + 4, Blocks.dirt, 0, 3);
		world.setBlock(x + 11, y + -6, z + 4, Blocks.dirt, 0, 3);
		world.setBlock(x + 12, y + -6, z + 4, Blocks.dirt, 0, 3);
		world.setBlock(x + 13, y + -6, z + 4, Blocks.dirt, 0, 3);
		world.setBlock(x + 14, y + -6, z + 4, Blocks.dirt, 0, 3);
		world.setBlock(x + 0, y + -6, z + 5, Blocks.dirt, 0, 3);
		world.setBlock(x + 1, y + -6, z + 5, Blocks.dirt, 0, 3);
		world.setBlock(x + 2, y + -6, z + 5, Blocks.dirt, 0, 3);
		world.setBlock(x + 3, y + -6, z + 5, Blocks.dirt, 0, 3);
		world.setBlock(x + 4, y + -6, z + 5, Blocks.dirt, 0, 3);
		world.setBlock(x + 5, y + -6, z + 5, Blocks.dirt, 0, 3);
		world.setBlock(x + 6, y + -6, z + 5, Blocks.dirt, 0, 3);
		world.setBlock(x + 7, y + -6, z + 5, Blocks.dirt, 0, 3);
		world.setBlock(x + 8, y + -6, z + 5, Blocks.dirt, 0, 3);
		world.setBlock(x + 9, y + -6, z + 5, Blocks.dirt, 0, 3);
		world.setBlock(x + 10, y + -6, z + 5, Blocks.dirt, 0, 3);
		world.setBlock(x + 11, y + -6, z + 5, Blocks.dirt, 0, 3);
		world.setBlock(x + 12, y + -6, z + 5, Blocks.dirt, 0, 3);
		world.setBlock(x + 13, y + -6, z + 5, Blocks.dirt, 0, 3);
		world.setBlock(x + 14, y + -6, z + 5, Blocks.stone, 0, 3);
		world.setBlock(x + 0, y + -6, z + 6, Blocks.dirt, 0, 3);
		world.setBlock(x + 1, y + -6, z + 6, Blocks.dirt, 0, 3);
		world.setBlock(x + 2, y + -6, z + 6, Blocks.dirt, 0, 3);
		world.setBlock(x + 3, y + -6, z + 6, Blocks.gravel, 0, 3);
		world.setBlock(x + 4, y + -6, z + 6, Blocks.gravel, 0, 3);
		world.setBlock(x + 5, y + -6, z + 6, Blocks.gravel, 0, 3);
		world.setBlock(x + 6, y + -6, z + 6, Blocks.gravel, 0, 3);
		world.setBlock(x + 7, y + -6, z + 6, Blocks.dirt, 0, 3);
		world.setBlock(x + 8, y + -6, z + 6, Blocks.dirt, 0, 3);
		world.setBlock(x + 9, y + -6, z + 6, Blocks.gravel, 0, 3);
		world.setBlock(x + 10, y + -6, z + 6, Blocks.gravel, 0, 3);
		world.setBlock(x + 11, y + -6, z + 6, Blocks.gravel, 0, 3);
		world.setBlock(x + 12, y + -6, z + 6, Blocks.dirt, 0, 3);
		world.setBlock(x + 13, y + -6, z + 6, Blocks.dirt, 0, 3);
		world.setBlock(x + 14, y + -6, z + 6, Blocks.stone, 0, 3);
		world.setBlock(x + 0, y + -6, z + 7, Blocks.dirt, 0, 3);
		world.setBlock(x + 1, y + -6, z + 7, Blocks.dirt, 0, 3);
		world.setBlock(x + 2, y + -6, z + 7, Blocks.dirt, 0, 3);
		world.setBlock(x + 3, y + -6, z + 7, Blocks.gravel, 0, 3);
		world.setBlock(x + 4, y + -6, z + 7, Blocks.gravel, 0, 3);
		world.setBlock(x + 5, y + -6, z + 7, Blocks.gravel, 0, 3);
		world.setBlock(x + 6, y + -6, z + 7, Blocks.gravel, 0, 3);
		world.setBlock(x + 7, y + -6, z + 7, Blocks.dirt, 0, 3);
		world.setBlock(x + 8, y + -6, z + 7, Blocks.dirt, 0, 3);
		world.setBlock(x + 9, y + -6, z + 7, Blocks.gravel, 0, 3);
		world.setBlock(x + 10, y + -6, z + 7, Blocks.gravel, 0, 3);
		world.setBlock(x + 11, y + -6, z + 7, Blocks.gravel, 0, 3);
		world.setBlock(x + 12, y + -6, z + 7, Blocks.dirt, 0, 3);
		world.setBlock(x + 13, y + -6, z + 7, Blocks.dirt, 0, 3);
		world.setBlock(x + 14, y + -6, z + 7, Blocks.stone, 0, 3);
		world.setBlock(x + 0, y + -6, z + 8, Blocks.dirt, 0, 3);
		world.setBlock(x + 1, y + -6, z + 8, Blocks.dirt, 0, 3);
		world.setBlock(x + 2, y + -6, z + 8, Blocks.dirt, 0, 3);
		world.setBlock(x + 3, y + -6, z + 8, Blocks.gravel, 0, 3);
		world.setBlock(x + 4, y + -6, z + 8, Blocks.gravel, 0, 3);
		world.setBlock(x + 5, y + -6, z + 8, Blocks.gravel, 0, 3);
		world.setBlock(x + 6, y + -6, z + 8, Blocks.gravel, 0, 3);
		world.setBlock(x + 7, y + -6, z + 8, Blocks.dirt, 0, 3);
		world.setBlock(x + 8, y + -6, z + 8, Blocks.dirt, 0, 3);
		world.setBlock(x + 9, y + -6, z + 8, Blocks.gravel, 0, 3);
		world.setBlock(x + 10, y + -6, z + 8, Blocks.gravel, 0, 3);
		world.setBlock(x + 11, y + -6, z + 8, Blocks.gravel, 0, 3);
		world.setBlock(x + 12, y + -6, z + 8, Blocks.dirt, 0, 3);
		world.setBlock(x + 13, y + -6, z + 8, Blocks.dirt, 0, 3);
		world.setBlock(x + 14, y + -6, z + 8, Blocks.stone, 0, 3);
		world.setBlock(x + 0, y + -6, z + 9, Blocks.dirt, 0, 3);
		world.setBlock(x + 1, y + -6, z + 9, Blocks.dirt, 0, 3);
		world.setBlock(x + 2, y + -6, z + 9, Blocks.dirt, 0, 3);
		world.setBlock(x + 3, y + -6, z + 9, Blocks.gravel, 0, 3);
		world.setBlock(x + 4, y + -6, z + 9, Blocks.gravel, 0, 3);
		world.setBlock(x + 5, y + -6, z + 9, Blocks.gravel, 0, 3);
		world.setBlock(x + 6, y + -6, z + 9, Blocks.gravel, 0, 3);
		world.setBlock(x + 7, y + -6, z + 9, Blocks.dirt, 0, 3);
		world.setBlock(x + 8, y + -6, z + 9, Blocks.dirt, 0, 3);
		world.setBlock(x + 9, y + -6, z + 9, Blocks.gravel, 0, 3);
		world.setBlock(x + 10, y + -6, z + 9, Blocks.gravel, 0, 3);
		world.setBlock(x + 11, y + -6, z + 9, Blocks.gravel, 0, 3);
		world.setBlock(x + 12, y + -6, z + 9, Blocks.dirt, 0, 3);
		world.setBlock(x + 13, y + -6, z + 9, Blocks.dirt, 0, 3);
		world.setBlock(x + 14, y + -6, z + 9, Blocks.stone, 0, 3);
		world.setBlock(x + 0, y + -6, z + 10, Blocks.dirt, 0, 3);
		world.setBlock(x + 1, y + -6, z + 10, Blocks.dirt, 0, 3);
		world.setBlock(x + 2, y + -6, z + 10, Blocks.dirt, 0, 3);
		world.setBlock(x + 3, y + -6, z + 10, Blocks.gravel, 0, 3);
		world.setBlock(x + 4, y + -6, z + 10, Blocks.gravel, 0, 3);
		world.setBlock(x + 5, y + -6, z + 10, Blocks.gravel, 0, 3);
		world.setBlock(x + 6, y + -6, z + 10, Blocks.gravel, 0, 3);
		world.setBlock(x + 7, y + -6, z + 10, Blocks.gravel, 0, 3);
		world.setBlock(x + 8, y + -6, z + 10, Blocks.gravel, 0, 3);
		world.setBlock(x + 9, y + -6, z + 10, Blocks.gravel, 0, 3);
		world.setBlock(x + 10, y + -6, z + 10, Blocks.gravel, 0, 3);
		world.setBlock(x + 11, y + -6, z + 10, Blocks.gravel, 0, 3);
		world.setBlock(x + 12, y + -6, z + 10, Blocks.dirt, 0, 3);
		world.setBlock(x + 13, y + -6, z + 10, Blocks.dirt, 0, 3);
		world.setBlock(x + 14, y + -6, z + 10, Blocks.stone, 0, 3);
		world.setBlock(x + 0, y + -6, z + 11, Blocks.dirt, 0, 3);
		world.setBlock(x + 1, y + -6, z + 11, Blocks.dirt, 0, 3);
		world.setBlock(x + 2, y + -6, z + 11, Blocks.dirt, 0, 3);
		world.setBlock(x + 3, y + -6, z + 11, Blocks.gravel, 0, 3);
		world.setBlock(x + 4, y + -6, z + 11, Blocks.gravel, 0, 3);
		world.setBlock(x + 5, y + -6, z + 11, Blocks.gravel, 0, 3);
		world.setBlock(x + 6, y + -6, z + 11, Blocks.gravel, 0, 3);
		world.setBlock(x + 7, y + -6, z + 11, Blocks.gravel, 0, 3);
		world.setBlock(x + 8, y + -6, z + 11, Blocks.gravel, 0, 3);
		world.setBlock(x + 9, y + -6, z + 11, Blocks.gravel, 0, 3);
		world.setBlock(x + 10, y + -6, z + 11, Blocks.gravel, 0, 3);
		world.setBlock(x + 11, y + -6, z + 11, Blocks.gravel, 0, 3);
		world.setBlock(x + 12, y + -6, z + 11, Blocks.dirt, 0, 3);
		world.setBlock(x + 13, y + -6, z + 11, Blocks.dirt, 0, 3);
		world.setBlock(x + 14, y + -6, z + 11, Blocks.stone, 0, 3);
		world.setBlock(x + 0, y + -6, z + 12, Blocks.dirt, 0, 3);
		world.setBlock(x + 1, y + -6, z + 12, Blocks.dirt, 0, 3);
		world.setBlock(x + 2, y + -6, z + 12, Blocks.dirt, 0, 3);
		world.setBlock(x + 3, y + -6, z + 12, Blocks.gravel, 0, 3);
		world.setBlock(x + 4, y + -6, z + 12, Blocks.gravel, 0, 3);
		world.setBlock(x + 5, y + -6, z + 12, Blocks.gravel, 0, 3);
		world.setBlock(x + 6, y + -6, z + 12, Blocks.gravel, 0, 3);
		world.setBlock(x + 7, y + -6, z + 12, Blocks.gravel, 0, 3);
		world.setBlock(x + 8, y + -6, z + 12, Blocks.gravel, 0, 3);
		world.setBlock(x + 9, y + -6, z + 12, Blocks.gravel, 0, 3);
		world.setBlock(x + 10, y + -6, z + 12, Blocks.gravel, 0, 3);
		world.setBlock(x + 11, y + -6, z + 12, Blocks.gravel, 0, 3);
		world.setBlock(x + 12, y + -6, z + 12, Blocks.dirt, 0, 3);
		world.setBlock(x + 13, y + -6, z + 12, Blocks.dirt, 0, 3);
		world.setBlock(x + 14, y + -6, z + 12, Blocks.stone, 0, 3);
		world.setBlock(x + 0, y + -6, z + 13, Blocks.dirt, 0, 3);
		world.setBlock(x + 1, y + -6, z + 13, Blocks.dirt, 0, 3);
		world.setBlock(x + 2, y + -6, z + 13, Blocks.dirt, 0, 3);
		world.setBlock(x + 3, y + -6, z + 13, Blocks.gravel, 0, 3);
		world.setBlock(x + 4, y + -6, z + 13, Blocks.gravel, 0, 3);
		world.setBlock(x + 5, y + -6, z + 13, Blocks.gravel, 0, 3);
		world.setBlock(x + 6, y + -6, z + 13, Blocks.gravel, 0, 3);
		world.setBlock(x + 7, y + -6, z + 13, Blocks.gravel, 0, 3);
		world.setBlock(x + 8, y + -6, z + 13, Blocks.gravel, 0, 3);
		world.setBlock(x + 9, y + -6, z + 13, Blocks.gravel, 0, 3);
		world.setBlock(x + 10, y + -6, z + 13, Blocks.gravel, 0, 3);
		world.setBlock(x + 11, y + -6, z + 13, Blocks.gravel, 0, 3);
		world.setBlock(x + 12, y + -6, z + 13, Blocks.dirt, 0, 3);
		world.setBlock(x + 13, y + -6, z + 13, Blocks.dirt, 0, 3);
		world.setBlock(x + 14, y + -6, z + 13, Blocks.stone, 0, 3);
		world.setBlock(x + 0, y + -6, z + 14, Blocks.dirt, 0, 3);
		world.setBlock(x + 1, y + -6, z + 14, Blocks.dirt, 0, 3);
		world.setBlock(x + 2, y + -6, z + 14, Blocks.dirt, 0, 3);
		world.setBlock(x + 3, y + -6, z + 14, Blocks.gravel, 0, 3);
		world.setBlock(x + 4, y + -6, z + 14, Blocks.gravel, 0, 3);
		world.setBlock(x + 5, y + -6, z + 14, Blocks.gravel, 0, 3);
		world.setBlock(x + 6, y + -6, z + 14, Blocks.gravel, 0, 3);
		world.setBlock(x + 7, y + -6, z + 14, Blocks.gravel, 0, 3);
		world.setBlock(x + 8, y + -6, z + 14, Blocks.gravel, 0, 3);
		world.setBlock(x + 9, y + -6, z + 14, Blocks.gravel, 0, 3);
		world.setBlock(x + 10, y + -6, z + 14, Blocks.gravel, 0, 3);
		world.setBlock(x + 11, y + -6, z + 14, Blocks.gravel, 0, 3);
		world.setBlock(x + 12, y + -6, z + 14, Blocks.dirt, 0, 3);
		world.setBlock(x + 13, y + -6, z + 14, Blocks.dirt, 0, 3);
		world.setBlock(x + 14, y + -6, z + 14, Blocks.stone, 0, 3);
		world.setBlock(x + 0, y + -6, z + 15, Blocks.dirt, 0, 3);
		world.setBlock(x + 1, y + -6, z + 15, Blocks.dirt, 0, 3);
		world.setBlock(x + 2, y + -6, z + 15, Blocks.dirt, 0, 3);
		world.setBlock(x + 3, y + -6, z + 15, Blocks.gravel, 0, 3);
		world.setBlock(x + 4, y + -6, z + 15, Blocks.gravel, 0, 3);
		world.setBlock(x + 5, y + -6, z + 15, Blocks.gravel, 0, 3);
		world.setBlock(x + 6, y + -6, z + 15, Blocks.gravel, 0, 3);
		world.setBlock(x + 7, y + -6, z + 15, Blocks.gravel, 0, 3);
		world.setBlock(x + 8, y + -6, z + 15, Blocks.gravel, 0, 3);
		world.setBlock(x + 9, y + -6, z + 15, Blocks.gravel, 0, 3);
		world.setBlock(x + 10, y + -6, z + 15, Blocks.gravel, 0, 3);
		world.setBlock(x + 11, y + -6, z + 15, Blocks.gravel, 0, 3);
		world.setBlock(x + 12, y + -6, z + 15, Blocks.dirt, 0, 3);
		world.setBlock(x + 13, y + -6, z + 15, Blocks.dirt, 0, 3);
		world.setBlock(x + 14, y + -6, z + 15, Blocks.stone, 0, 3);
		world.setBlock(x + 0, y + -6, z + 16, Blocks.dirt, 0, 3);
		world.setBlock(x + 1, y + -6, z + 16, Blocks.dirt, 0, 3);
		world.setBlock(x + 2, y + -6, z + 16, Blocks.dirt, 0, 3);
		world.setBlock(x + 3, y + -6, z + 16, Blocks.gravel, 0, 3);
		world.setBlock(x + 4, y + -6, z + 16, Blocks.gravel, 0, 3);
		world.setBlock(x + 5, y + -6, z + 16, Blocks.gravel, 0, 3);
		world.setBlock(x + 6, y + -6, z + 16, Blocks.gravel, 0, 3);
		world.setBlock(x + 7, y + -6, z + 16, Blocks.gravel, 0, 3);
		world.setBlock(x + 8, y + -6, z + 16, Blocks.gravel, 0, 3);
		world.setBlock(x + 9, y + -6, z + 16, Blocks.gravel, 0, 3);
		world.setBlock(x + 10, y + -6, z + 16, Blocks.gravel, 0, 3);
		world.setBlock(x + 11, y + -6, z + 16, Blocks.gravel, 0, 3);
		world.setBlock(x + 12, y + -6, z + 16, Blocks.dirt, 0, 3);
		world.setBlock(x + 13, y + -6, z + 16, Blocks.dirt, 0, 3);
		world.setBlock(x + 14, y + -6, z + 16, Blocks.stone, 0, 3);
		world.setBlock(x + 0, y + -6, z + 17, Blocks.dirt, 0, 3);
		world.setBlock(x + 1, y + -6, z + 17, Blocks.dirt, 0, 3);
		world.setBlock(x + 2, y + -6, z + 17, Blocks.dirt, 0, 3);
		world.setBlock(x + 3, y + -6, z + 17, Blocks.gravel, 0, 3);
		world.setBlock(x + 4, y + -6, z + 17, Blocks.gravel, 0, 3);
		world.setBlock(x + 5, y + -6, z + 17, Blocks.gravel, 0, 3);
		world.setBlock(x + 6, y + -6, z + 17, Blocks.gravel, 0, 3);
		world.setBlock(x + 7, y + -6, z + 17, Blocks.gravel, 0, 3);
		world.setBlock(x + 8, y + -6, z + 17, Blocks.gravel, 0, 3);
		world.setBlock(x + 9, y + -6, z + 17, Blocks.gravel, 0, 3);
		world.setBlock(x + 10, y + -6, z + 17, Blocks.gravel, 0, 3);
		world.setBlock(x + 11, y + -6, z + 17, Blocks.gravel, 0, 3);
		world.setBlock(x + 12, y + -6, z + 17, Blocks.dirt, 0, 3);
		world.setBlock(x + 13, y + -6, z + 17, Blocks.dirt, 0, 3);
		world.setBlock(x + 14, y + -6, z + 17, Blocks.stone, 0, 3);
		world.setBlock(x + 0, y + -6, z + 18, Blocks.dirt, 0, 3);
		world.setBlock(x + 1, y + -6, z + 18, Blocks.dirt, 0, 3);
		world.setBlock(x + 2, y + -6, z + 18, Blocks.dirt, 0, 3);
		world.setBlock(x + 3, y + -6, z + 18, Blocks.gravel, 0, 3);
		world.setBlock(x + 4, y + -6, z + 18, Blocks.gravel, 0, 3);
		world.setBlock(x + 5, y + -6, z + 18, Blocks.gravel, 0, 3);
		world.setBlock(x + 6, y + -6, z + 18, Blocks.gravel, 0, 3);
		world.setBlock(x + 7, y + -6, z + 18, Blocks.gravel, 0, 3);
		world.setBlock(x + 8, y + -6, z + 18, Blocks.gravel, 0, 3);
		world.setBlock(x + 9, y + -6, z + 18, Blocks.gravel, 0, 3);
		world.setBlock(x + 10, y + -6, z + 18, Blocks.gravel, 0, 3);
		world.setBlock(x + 11, y + -6, z + 18, Blocks.gravel, 0, 3);
		world.setBlock(x + 12, y + -6, z + 18, Blocks.dirt, 0, 3);
		world.setBlock(x + 13, y + -6, z + 18, Blocks.dirt, 0, 3);
		world.setBlock(x + 14, y + -6, z + 18, Blocks.stone, 0, 3);
		world.setBlock(x + 0, y + -6, z + 19, Blocks.dirt, 0, 3);
		world.setBlock(x + 1, y + -6, z + 19, Blocks.dirt, 0, 3);
		world.setBlock(x + 2, y + -6, z + 19, Blocks.dirt, 0, 3);
		world.setBlock(x + 3, y + -6, z + 19, Blocks.gravel, 0, 3);
		world.setBlock(x + 4, y + -6, z + 19, Blocks.gravel, 0, 3);
		world.setBlock(x + 5, y + -6, z + 19, Blocks.gravel, 0, 3);
		world.setBlock(x + 6, y + -6, z + 19, Blocks.gravel, 0, 3);
		world.setBlock(x + 7, y + -6, z + 19, Blocks.gravel, 0, 3);
		world.setBlock(x + 8, y + -6, z + 19, Blocks.gravel, 0, 3);
		world.setBlock(x + 9, y + -6, z + 19, Blocks.gravel, 0, 3);
		world.setBlock(x + 10, y + -6, z + 19, Blocks.gravel, 0, 3);
		world.setBlock(x + 11, y + -6, z + 19, Blocks.gravel, 0, 3);
		world.setBlock(x + 12, y + -6, z + 19, Blocks.dirt, 0, 3);
		world.setBlock(x + 13, y + -6, z + 19, Blocks.dirt, 0, 3);
		world.setBlock(x + 14, y + -6, z + 19, Blocks.stone, 0, 3);
		world.setBlock(x + 0, y + -6, z + 20, Blocks.dirt, 0, 3);
		world.setBlock(x + 1, y + -6, z + 20, Blocks.dirt, 0, 3);
		world.setBlock(x + 2, y + -6, z + 20, Blocks.dirt, 0, 3);
		world.setBlock(x + 3, y + -6, z + 20, Blocks.gravel, 0, 3);
		world.setBlock(x + 4, y + -6, z + 20, Blocks.gravel, 0, 3);
		world.setBlock(x + 5, y + -6, z + 20, Blocks.gravel, 0, 3);
		world.setBlock(x + 6, y + -6, z + 20, Blocks.gravel, 0, 3);
		world.setBlock(x + 7, y + -6, z + 20, Blocks.gravel, 0, 3);
		world.setBlock(x + 8, y + -6, z + 20, Blocks.gravel, 0, 3);
		world.setBlock(x + 9, y + -6, z + 20, Blocks.gravel, 0, 3);
		world.setBlock(x + 10, y + -6, z + 20, Blocks.gravel, 0, 3);
		world.setBlock(x + 11, y + -6, z + 20, Blocks.gravel, 0, 3);
		world.setBlock(x + 12, y + -6, z + 20, Blocks.dirt, 0, 3);
		world.setBlock(x + 13, y + -6, z + 20, Blocks.dirt, 0, 3);
		world.setBlock(x + 14, y + -6, z + 20, Blocks.stone, 0, 3);
		world.setBlock(x + 0, y + -6, z + 21, Blocks.dirt, 0, 3);
		world.setBlock(x + 1, y + -6, z + 21, Blocks.dirt, 0, 3);
		world.setBlock(x + 2, y + -6, z + 21, Blocks.dirt, 0, 3);
		world.setBlock(x + 3, y + -6, z + 21, Blocks.gravel, 0, 3);
		world.setBlock(x + 4, y + -6, z + 21, Blocks.gravel, 0, 3);
		world.setBlock(x + 5, y + -6, z + 21, Blocks.gravel, 0, 3);
		world.setBlock(x + 6, y + -6, z + 21, Blocks.gravel, 0, 3);
		world.setBlock(x + 7, y + -6, z + 21, Blocks.gravel, 0, 3);
		world.setBlock(x + 8, y + -6, z + 21, Blocks.gravel, 0, 3);
		world.setBlock(x + 9, y + -6, z + 21, Blocks.gravel, 0, 3);
		world.setBlock(x + 10, y + -6, z + 21, Blocks.gravel, 0, 3);
		world.setBlock(x + 11, y + -6, z + 21, Blocks.gravel, 0, 3);
		world.setBlock(x + 12, y + -6, z + 21, Blocks.dirt, 0, 3);
		world.setBlock(x + 13, y + -6, z + 21, Blocks.dirt, 0, 3);
		world.setBlock(x + 14, y + -6, z + 21, Blocks.stone, 0, 3);
		world.setBlock(x + 0, y + -6, z + 22, Blocks.dirt, 0, 3);
		world.setBlock(x + 1, y + -6, z + 22, Blocks.dirt, 0, 3);
		world.setBlock(x + 2, y + -6, z + 22, Blocks.dirt, 0, 3);
		world.setBlock(x + 3, y + -6, z + 22, Blocks.gravel, 0, 3);
		world.setBlock(x + 4, y + -6, z + 22, Blocks.gravel, 0, 3);
		world.setBlock(x + 5, y + -6, z + 22, Blocks.gravel, 0, 3);
		world.setBlock(x + 6, y + -6, z + 22, Blocks.gravel, 0, 3);
		world.setBlock(x + 7, y + -6, z + 22, Blocks.gravel, 0, 3);
		world.setBlock(x + 8, y + -6, z + 22, Blocks.gravel, 0, 3);
		world.setBlock(x + 9, y + -6, z + 22, Blocks.gravel, 0, 3);
		world.setBlock(x + 10, y + -6, z + 22, Blocks.gravel, 0, 3);
		world.setBlock(x + 11, y + -6, z + 22, Blocks.gravel, 0, 3);
		world.setBlock(x + 12, y + -6, z + 22, Blocks.dirt, 0, 3);
		world.setBlock(x + 13, y + -6, z + 22, Blocks.dirt, 0, 3);
		world.setBlock(x + 14, y + -6, z + 22, Blocks.coal_ore, 0, 3);
		world.setBlock(x + 0, y + -6, z + 23, Blocks.dirt, 0, 3);
		world.setBlock(x + 1, y + -6, z + 23, Blocks.dirt, 0, 3);
		world.setBlock(x + 2, y + -6, z + 23, Blocks.dirt, 0, 3);
		world.setBlock(x + 3, y + -6, z + 23, Blocks.gravel, 0, 3);
		world.setBlock(x + 4, y + -6, z + 23, Blocks.gravel, 0, 3);
		world.setBlock(x + 5, y + -6, z + 23, Blocks.gravel, 0, 3);
		world.setBlock(x + 6, y + -6, z + 23, Blocks.gravel, 0, 3);
		world.setBlock(x + 7, y + -6, z + 23, Blocks.gravel, 0, 3);
		world.setBlock(x + 8, y + -6, z + 23, Blocks.gravel, 0, 3);
		world.setBlock(x + 9, y + -6, z + 23, Blocks.gravel, 0, 3);
		world.setBlock(x + 10, y + -6, z + 23, Blocks.gravel, 0, 3);
		world.setBlock(x + 11, y + -6, z + 23, Blocks.gravel, 0, 3);
		world.setBlock(x + 12, y + -6, z + 23, Blocks.dirt, 0, 3);
		world.setBlock(x + 13, y + -6, z + 23, Blocks.dirt, 0, 3);
		world.setBlock(x + 14, y + -6, z + 23, Blocks.stone, 0, 3);
		world.setBlock(x + 0, y + -6, z + 24, Blocks.dirt, 0, 3);
		world.setBlock(x + 1, y + -6, z + 24, Blocks.dirt, 0, 3);
		world.setBlock(x + 2, y + -6, z + 24, Blocks.dirt, 0, 3);
		world.setBlock(x + 3, y + -6, z + 24, Blocks.gravel, 0, 3);
		world.setBlock(x + 4, y + -6, z + 24, Blocks.gravel, 0, 3);
		world.setBlock(x + 5, y + -6, z + 24, Blocks.gravel, 0, 3);
		world.setBlock(x + 6, y + -6, z + 24, Blocks.gravel, 0, 3);
		world.setBlock(x + 7, y + -6, z + 24, Blocks.gravel, 0, 3);
		world.setBlock(x + 8, y + -6, z + 24, Blocks.gravel, 0, 3);
		world.setBlock(x + 9, y + -6, z + 24, Blocks.gravel, 0, 3);
		world.setBlock(x + 10, y + -6, z + 24, Blocks.gravel, 0, 3);
		world.setBlock(x + 11, y + -6, z + 24, Blocks.gravel, 0, 3);
		world.setBlock(x + 12, y + -6, z + 24, Blocks.dirt, 0, 3);
		world.setBlock(x + 13, y + -6, z + 24, Blocks.dirt, 0, 3);
		world.setBlock(x + 14, y + -6, z + 24, Blocks.stone, 0, 3);
		world.setBlock(x + 0, y + -6, z + 25, Blocks.dirt, 0, 3);
		world.setBlock(x + 1, y + -6, z + 25, Blocks.dirt, 0, 3);
		world.setBlock(x + 2, y + -6, z + 25, Blocks.dirt, 0, 3);
		world.setBlock(x + 3, y + -6, z + 25, Blocks.gravel, 0, 3);
		world.setBlock(x + 4, y + -6, z + 25, Blocks.gravel, 0, 3);
		world.setBlock(x + 5, y + -6, z + 25, Blocks.gravel, 0, 3);
		world.setBlock(x + 6, y + -6, z + 25, Blocks.gravel, 0, 3);
		world.setBlock(x + 7, y + -6, z + 25, Blocks.gravel, 0, 3);
		world.setBlock(x + 8, y + -6, z + 25, Blocks.gravel, 0, 3);
		world.setBlock(x + 9, y + -6, z + 25, Blocks.gravel, 0, 3);
		world.setBlock(x + 10, y + -6, z + 25, Blocks.gravel, 0, 3);
		world.setBlock(x + 11, y + -6, z + 25, Blocks.gravel, 0, 3);
		world.setBlock(x + 12, y + -6, z + 25, Blocks.dirt, 0, 3);
		world.setBlock(x + 13, y + -6, z + 25, Blocks.dirt, 0, 3);
		world.setBlock(x + 14, y + -6, z + 25, Blocks.stone, 0, 3);
		world.setBlock(x + 0, y + -6, z + 26, Blocks.dirt, 0, 3);
		world.setBlock(x + 1, y + -6, z + 26, Blocks.dirt, 0, 3);
		world.setBlock(x + 2, y + -6, z + 26, Blocks.dirt, 0, 3);
		world.setBlock(x + 3, y + -6, z + 26, Blocks.gravel, 0, 3);
		world.setBlock(x + 4, y + -6, z + 26, Blocks.gravel, 0, 3);
		world.setBlock(x + 5, y + -6, z + 26, Blocks.gravel, 0, 3);
		world.setBlock(x + 6, y + -6, z + 26, Blocks.gravel, 0, 3);
		world.setBlock(x + 7, y + -6, z + 26, Blocks.gravel, 0, 3);
		world.setBlock(x + 8, y + -6, z + 26, Blocks.gravel, 0, 3);
		world.setBlock(x + 9, y + -6, z + 26, Blocks.gravel, 0, 3);
		world.setBlock(x + 10, y + -6, z + 26, Blocks.gravel, 0, 3);
		world.setBlock(x + 11, y + -6, z + 26, Blocks.gravel, 0, 3);
		world.setBlock(x + 12, y + -6, z + 26, Blocks.dirt, 0, 3);
		world.setBlock(x + 13, y + -6, z + 26, Blocks.dirt, 0, 3);
		world.setBlock(x + 14, y + -6, z + 26, Blocks.stone, 0, 3);
		world.setBlock(x + 0, y + -6, z + 27, Blocks.dirt, 0, 3);
		world.setBlock(x + 1, y + -6, z + 27, Blocks.dirt, 0, 3);
		world.setBlock(x + 2, y + -6, z + 27, Blocks.dirt, 0, 3);
		world.setBlock(x + 3, y + -6, z + 27, Blocks.dirt, 0, 3);
		world.setBlock(x + 4, y + -6, z + 27, Blocks.dirt, 0, 3);
		world.setBlock(x + 5, y + -6, z + 27, Blocks.dirt, 0, 3);
		world.setBlock(x + 6, y + -6, z + 27, Blocks.dirt, 0, 3);
		world.setBlock(x + 7, y + -6, z + 27, Blocks.dirt, 0, 3);
		world.setBlock(x + 8, y + -6, z + 27, Blocks.dirt, 0, 3);
		world.setBlock(x + 9, y + -6, z + 27, Blocks.dirt, 0, 3);
		world.setBlock(x + 10, y + -6, z + 27, Blocks.dirt, 0, 3);
		world.setBlock(x + 11, y + -6, z + 27, Blocks.dirt, 0, 3);
		world.setBlock(x + 12, y + -6, z + 27, Blocks.dirt, 0, 3);
		world.setBlock(x + 13, y + -6, z + 27, Blocks.dirt, 0, 3);
		world.setBlock(x + 14, y + -6, z + 27, Blocks.stone, 0, 3);
		world.setBlock(x + 0, y + -6, z + 28, Blocks.dirt, 0, 3);
		world.setBlock(x + 1, y + -6, z + 28, Blocks.dirt, 0, 3);
		world.setBlock(x + 2, y + -6, z + 28, Blocks.dirt, 0, 3);
		world.setBlock(x + 3, y + -6, z + 28, Blocks.dirt, 0, 3);
		world.setBlock(x + 4, y + -6, z + 28, Blocks.dirt, 0, 3);
		world.setBlock(x + 5, y + -6, z + 28, Blocks.dirt, 0, 3);
		world.setBlock(x + 6, y + -6, z + 28, Blocks.dirt, 0, 3);
		world.setBlock(x + 7, y + -6, z + 28, Blocks.dirt, 0, 3);
		world.setBlock(x + 8, y + -6, z + 28, Blocks.dirt, 0, 3);
		world.setBlock(x + 9, y + -6, z + 28, Blocks.dirt, 0, 3);
		world.setBlock(x + 10, y + -6, z + 28, Blocks.dirt, 0, 3);
		world.setBlock(x + 11, y + -6, z + 28, Blocks.dirt, 0, 3);
		world.setBlock(x + 12, y + -6, z + 28, Blocks.dirt, 0, 3);
		world.setBlock(x + 13, y + -6, z + 28, Blocks.dirt, 0, 3);
		world.setBlock(x + 14, y + -6, z + 28, Blocks.stone, 0, 3);
		world.setBlock(x + 0, y + -6, z + 29, Blocks.dirt, 0, 3);
		world.setBlock(x + 1, y + -6, z + 29, Blocks.dirt, 0, 3);
		world.setBlock(x + 2, y + -6, z + 29, Blocks.dirt, 0, 3);
		world.setBlock(x + 3, y + -6, z + 29, Blocks.dirt, 0, 3);
		world.setBlock(x + 4, y + -6, z + 29, Blocks.dirt, 0, 3);
		world.setBlock(x + 5, y + -6, z + 29, Blocks.dirt, 0, 3);
		world.setBlock(x + 6, y + -6, z + 29, Blocks.dirt, 0, 3);
		world.setBlock(x + 7, y + -6, z + 29, Blocks.dirt, 0, 3);
		world.setBlock(x + 8, y + -6, z + 29, Blocks.dirt, 0, 3);
		world.setBlock(x + 9, y + -6, z + 29, Blocks.dirt, 0, 3);
		world.setBlock(x + 10, y + -6, z + 29, Blocks.dirt, 0, 3);
		world.setBlock(x + 11, y + -6, z + 29, Blocks.dirt, 0, 3);
		world.setBlock(x + 12, y + -6, z + 29, Blocks.dirt, 0, 3);
		world.setBlock(x + 13, y + -6, z + 29, Blocks.dirt, 0, 3);
		world.setBlock(x + 14, y + -6, z + 29, Blocks.air, 0, 3);
		world.setBlock(x + 0, y + -5, z + 0, Blocks.dirt, 0, 3);
		world.setBlock(x + 1, y + -5, z + 0, Blocks.dirt, 0, 3);
		world.setBlock(x + 2, y + -5, z + 0, Blocks.dirt, 0, 3);
		world.setBlock(x + 3, y + -5, z + 0, Blocks.dirt, 0, 3);
		world.setBlock(x + 4, y + -5, z + 0, Blocks.dirt, 0, 3);
		world.setBlock(x + 5, y + -5, z + 0, Blocks.dirt, 0, 3);
		world.setBlock(x + 6, y + -5, z + 0, Blocks.dirt, 0, 3);
		world.setBlock(x + 7, y + -5, z + 0, Blocks.dirt, 0, 3);
		world.setBlock(x + 8, y + -5, z + 0, Blocks.dirt, 0, 3);
		world.setBlock(x + 9, y + -5, z + 0, Blocks.dirt, 0, 3);
		world.setBlock(x + 10, y + -5, z + 0, Blocks.dirt, 0, 3);
		world.setBlock(x + 11, y + -5, z + 0, Blocks.dirt, 0, 3);
		world.setBlock(x + 12, y + -5, z + 0, Blocks.dirt, 0, 3);
		world.setBlock(x + 13, y + -5, z + 0, Blocks.dirt, 0, 3);
		world.setBlock(x + 14, y + -5, z + 0, Blocks.dirt, 0, 3);
		world.setBlock(x + 0, y + -5, z + 1, Blocks.dirt, 0, 3);
		world.setBlock(x + 1, y + -5, z + 1, Blocks.dirt, 0, 3);
		world.setBlock(x + 2, y + -5, z + 1, Blocks.dirt, 0, 3);
		world.setBlock(x + 3, y + -5, z + 1, Blocks.dirt, 0, 3);
		world.setBlock(x + 4, y + -5, z + 1, Blocks.dirt, 0, 3);
		world.setBlock(x + 5, y + -5, z + 1, Blocks.dirt, 0, 3);
		world.setBlock(x + 6, y + -5, z + 1, Blocks.dirt, 0, 3);
		world.setBlock(x + 7, y + -5, z + 1, Blocks.dirt, 0, 3);
		world.setBlock(x + 8, y + -5, z + 1, Blocks.dirt, 0, 3);
		world.setBlock(x + 9, y + -5, z + 1, Blocks.dirt, 0, 3);
		world.setBlock(x + 10, y + -5, z + 1, Blocks.dirt, 0, 3);
		world.setBlock(x + 11, y + -5, z + 1, Blocks.dirt, 0, 3);
		world.setBlock(x + 12, y + -5, z + 1, Blocks.dirt, 0, 3);
		world.setBlock(x + 13, y + -5, z + 1, Blocks.dirt, 0, 3);
		world.setBlock(x + 14, y + -5, z + 1, Blocks.dirt, 0, 3);
		world.setBlock(x + 0, y + -5, z + 2, Blocks.dirt, 0, 3);
		world.setBlock(x + 1, y + -5, z + 2, Blocks.dirt, 0, 3);
		world.setBlock(x + 2, y + -5, z + 2, Blocks.dirt, 0, 3);
		world.setBlock(x + 3, y + -5, z + 2, Blocks.dirt, 0, 3);
		world.setBlock(x + 4, y + -5, z + 2, Blocks.dirt, 0, 3);
		world.setBlock(x + 5, y + -5, z + 2, Blocks.dirt, 0, 3);
		world.setBlock(x + 6, y + -5, z + 2, Blocks.dirt, 0, 3);
		world.setBlock(x + 7, y + -5, z + 2, Blocks.dirt, 0, 3);
		world.setBlock(x + 8, y + -5, z + 2, Blocks.dirt, 0, 3);
		world.setBlock(x + 9, y + -5, z + 2, Blocks.dirt, 0, 3);
		world.setBlock(x + 10, y + -5, z + 2, Blocks.dirt, 0, 3);
		world.setBlock(x + 11, y + -5, z + 2, Blocks.dirt, 0, 3);
		world.setBlock(x + 12, y + -5, z + 2, Blocks.dirt, 0, 3);
		world.setBlock(x + 13, y + -5, z + 2, Blocks.dirt, 0, 3);
		world.setBlock(x + 14, y + -5, z + 2, Blocks.dirt, 0, 3);
		world.setBlock(x + 0, y + -5, z + 3, Blocks.dirt, 0, 3);
		world.setBlock(x + 1, y + -5, z + 3, Blocks.dirt, 0, 3);
		world.setBlock(x + 2, y + -5, z + 3, Blocks.dirt, 0, 3);
		world.setBlock(x + 3, y + -5, z + 3, Blocks.dirt, 0, 3);
		world.setBlock(x + 4, y + -5, z + 3, Blocks.dirt, 0, 3);
		world.setBlock(x + 5, y + -5, z + 3, Blocks.dirt, 0, 3);
		world.setBlock(x + 6, y + -5, z + 3, Blocks.dirt, 0, 3);
		world.setBlock(x + 7, y + -5, z + 3, Blocks.dirt, 0, 3);
		world.setBlock(x + 8, y + -5, z + 3, Blocks.dirt, 0, 3);
		world.setBlock(x + 9, y + -5, z + 3, Blocks.dirt, 0, 3);
		world.setBlock(x + 10, y + -5, z + 3, Blocks.dirt, 0, 3);
		world.setBlock(x + 11, y + -5, z + 3, Blocks.dirt, 0, 3);
		world.setBlock(x + 12, y + -5, z + 3, Blocks.dirt, 0, 3);
		world.setBlock(x + 13, y + -5, z + 3, Blocks.dirt, 0, 3);
		world.setBlock(x + 14, y + -5, z + 3, Blocks.dirt, 0, 3);
		world.setBlock(x + 0, y + -5, z + 4, Blocks.dirt, 0, 3);
		world.setBlock(x + 1, y + -5, z + 4, Blocks.dirt, 0, 3);
		world.setBlock(x + 2, y + -5, z + 4, Blocks.dirt, 0, 3);
		world.setBlock(x + 3, y + -5, z + 4, Blocks.dirt, 0, 3);
		world.setBlock(x + 4, y + -5, z + 4, Blocks.dirt, 0, 3);
		world.setBlock(x + 5, y + -5, z + 4, Blocks.dirt, 0, 3);
		world.setBlock(x + 6, y + -5, z + 4, Blocks.dirt, 0, 3);
		world.setBlock(x + 7, y + -5, z + 4, Blocks.dirt, 0, 3);
		world.setBlock(x + 8, y + -5, z + 4, Blocks.dirt, 0, 3);
		world.setBlock(x + 9, y + -5, z + 4, Blocks.dirt, 0, 3);
		world.setBlock(x + 10, y + -5, z + 4, Blocks.dirt, 0, 3);
		world.setBlock(x + 11, y + -5, z + 4, Blocks.dirt, 0, 3);
		world.setBlock(x + 12, y + -5, z + 4, Blocks.dirt, 0, 3);
		world.setBlock(x + 13, y + -5, z + 4, Blocks.dirt, 0, 3);
		world.setBlock(x + 14, y + -5, z + 4, Blocks.dirt, 0, 3);
		world.setBlock(x + 0, y + -5, z + 5, Blocks.dirt, 0, 3);
		world.setBlock(x + 1, y + -5, z + 5, Blocks.dirt, 0, 3);
		world.setBlock(x + 2, y + -5, z + 5, Blocks.cobblestone, 0, 3);
		world.setBlock(x + 3, y + -5, z + 5, Blocks.cobblestone, 0, 3);
		world.setBlock(x + 4, y + -5, z + 5, Blocks.cobblestone, 0, 3);
		world.setBlock(x + 5, y + -5, z + 5, Blocks.cobblestone, 0, 3);
		world.setBlock(x + 6, y + -5, z + 5, Blocks.cobblestone, 0, 3);
		world.setBlock(x + 7, y + -5, z + 5, Blocks.cobblestone, 0, 3);
		world.setBlock(x + 8, y + -5, z + 5, Blocks.cobblestone, 0, 3);
		world.setBlock(x + 9, y + -5, z + 5, Blocks.cobblestone, 0, 3);
		world.setBlock(x + 10, y + -5, z + 5, Blocks.monster_egg, 1, 3);
		world.setBlock(x + 11, y + -5, z + 5, Blocks.monster_egg, 1, 3);
		world.setBlock(x + 12, y + -5, z + 5, Blocks.cobblestone, 0, 3);
		world.setBlock(x + 13, y + -5, z + 5, Blocks.dirt, 0, 3);
		world.setBlock(x + 14, y + -5, z + 5, Blocks.dirt, 0, 3);
		world.setBlock(x + 0, y + -5, z + 6, Blocks.dirt, 0, 3);
		world.setBlock(x + 1, y + -5, z + 6, Blocks.dirt, 0, 3);
		world.setBlock(x + 2, y + -5, z + 6, Blocks.cobblestone, 0, 3);
		world.setBlock(x + 3, y + -5, z + 6, Blocks.planks, 0, 3);
		world.setBlock(x + 4, y + -5, z + 6, Blocks.planks, 0, 3);
		world.setBlock(x + 5, y + -5, z + 6, Blocks.web, 0, 3);
		world.setBlock(x + 6, y + -5, z + 6, Blocks.planks, 0, 3);
		world.setBlock(x + 7, y + -5, z + 6, Blocks.cobblestone, 0, 3);
		world.setBlock(x + 8, y + -5, z + 6, Blocks.monster_egg, 1, 3);
		world.setBlock(x + 9, y + -5, z + 6, Blocks.air, 0, 3);
		world.setBlock(x + 10, y + -5, z + 6, Blocks.air, 0, 3);
		world.setBlock(x + 11, y + -5, z + 6, Blocks.stonebrick, 0, 3);
		world.setBlock(x + 12, y + -5, z + 6, Blocks.monster_egg, 1, 3);
		world.setBlock(x + 13, y + -5, z + 6, Blocks.dirt, 0, 3);
		world.setBlock(x + 14, y + -5, z + 6, Blocks.dirt, 0, 3);
		world.setBlock(x + 0, y + -5, z + 7, Blocks.dirt, 0, 3);
		world.setBlock(x + 1, y + -5, z + 7, Blocks.dirt, 0, 3);
		world.setBlock(x + 2, y + -5, z + 7, Blocks.cobblestone, 0, 3);
		world.setBlock(x + 3, y + -5, z + 7, Blocks.planks, 2, 3);
		world.setBlock(x + 4, y + -5, z + 7, Blocks.air, 0, 3);
		world.setBlock(x + 5, y + -5, z + 7, Blocks.air, 0, 3);
		world.setBlock(x + 6, y + -5, z + 7, Blocks.chest, 4, 3);
		world.setBlock(x + 7, y + -5, z + 7, Blocks.cobblestone, 0, 3);
		world.setBlock(x + 8, y + -5, z + 7, Blocks.cobblestone, 0, 3);
		world.setBlock(x + 9, y + -5, z + 7, Blocks.air, 0, 3);
		world.setBlock(x + 10, y + -5, z + 7, Blocks.air, 0, 3);
		world.setBlock(x + 11, y + -5, z + 7, Blocks.quartz_block, 0, 3);
		world.setBlock(x + 12, y + -5, z + 7, Blocks.cobblestone, 0, 3);
		world.setBlock(x + 13, y + -5, z + 7, Blocks.dirt, 0, 3);
		world.setBlock(x + 14, y + -5, z + 7, Blocks.dirt, 0, 3);
		world.setBlock(x + 0, y + -5, z + 8, Blocks.dirt, 0, 3);
		world.setBlock(x + 1, y + -5, z + 8, Blocks.dirt, 0, 3);
		world.setBlock(x + 2, y + -5, z + 8, Blocks.cobblestone, 0, 3);
		world.setBlock(x + 3, y + -5, z + 8, Blocks.air, 0, 3);
		world.setBlock(x + 4, y + -5, z + 8, Blocks.air, 0, 3);
		world.setBlock(x + 5, y + -5, z + 8, Blocks.air, 0, 3);
		world.setBlock(x + 6, y + -5, z + 8, Blocks.chest, 4, 3);
		world.setBlock(x + 7, y + -5, z + 8, Blocks.cobblestone, 0, 3);
		world.setBlock(x + 8, y + -5, z + 8, Blocks.cobblestone, 0, 3);
		world.setBlock(x + 9, y + -5, z + 8, Blocks.air, 0, 3);
		world.setBlock(x + 10, y + -5, z + 8, Blocks.air, 0, 3);
		world.setBlock(x + 11, y + -5, z + 8, Blocks.stonebrick, 0, 3);
		world.setBlock(x + 12, y + -5, z + 8, Blocks.cobblestone, 0, 3);
		world.setBlock(x + 13, y + -5, z + 8, Blocks.dirt, 0, 3);
		world.setBlock(x + 14, y + -5, z + 8, Blocks.dirt, 0, 3);
		world.setBlock(x + 0, y + -5, z + 9, Blocks.dirt, 0, 3);
		world.setBlock(x + 1, y + -5, z + 9, Blocks.dirt, 0, 3);
		world.setBlock(x + 2, y + -5, z + 9, Blocks.cobblestone, 0, 3);
		world.setBlock(x + 3, y + -5, z + 9, Blocks.air, 0, 3);
		world.setBlock(x + 4, y + -5, z + 9, Blocks.air, 0, 3);
		world.setBlock(x + 5, y + -5, z + 9, Blocks.air, 0, 3);
		world.setBlock(x + 6, y + -5, z + 9, Blocks.air, 0, 3);
		world.setBlock(x + 7, y + -5, z + 9, Blocks.cobblestone, 0, 3);
		world.setBlock(x + 8, y + -5, z + 9, Blocks.cobblestone, 0, 3);
		world.setBlock(x + 9, y + -5, z + 9, Blocks.jungle_stairs, 3, 3);
		world.setBlock(x + 10, y + -5, z + 9, Blocks.air, 0, 3);
		world.setBlock(x + 11, y + -5, z + 9, Blocks.stonebrick, 0, 3);
		world.setBlock(x + 12, y + -5, z + 9, Blocks.cobblestone, 0, 3);
		world.setBlock(x + 13, y + -5, z + 9, Blocks.dirt, 0, 3);
		world.setBlock(x + 14, y + -5, z + 9, Blocks.dirt, 0, 3);
		world.setBlock(x + 0, y + -5, z + 10, Blocks.dirt, 0, 3);
		world.setBlock(x + 1, y + -5, z + 10, Blocks.dirt, 0, 3);
		world.setBlock(x + 2, y + -5, z + 10, Blocks.cobblestone, 0, 3);
		world.setBlock(x + 3, y + -5, z + 10, Blocks.air, 0, 3);
		world.setBlock(x + 4, y + -5, z + 10, Blocks.air, 0, 3);
		world.setBlock(x + 5, y + -5, z + 10, Blocks.air, 0, 3);
		world.setBlock(x + 6, y + -5, z + 10, Blocks.air, 0, 3);
		world.setBlock(x + 7, y + -5, z + 10, Blocks.planks, 0, 3);
		world.setBlock(x + 8, y + -5, z + 10, Blocks.planks, 2, 3);
		world.setBlock(x + 9, y + -5, z + 10, Blocks.air, 0, 3);
		world.setBlock(x + 10, y + -5, z + 10, Blocks.air, 0, 3);
		world.setBlock(x + 11, y + -5, z + 10, Blocks.stonebrick, 0, 3);
		world.setBlock(x + 12, y + -5, z + 10, Blocks.cobblestone, 0, 3);
		world.setBlock(x + 13, y + -5, z + 10, Blocks.dirt, 0, 3);
		world.setBlock(x + 14, y + -5, z + 10, Blocks.dirt, 0, 3);
		world.setBlock(x + 0, y + -5, z + 11, Blocks.dirt, 0, 3);
		world.setBlock(x + 1, y + -5, z + 11, Blocks.dirt, 0, 3);
		world.setBlock(x + 2, y + -5, z + 11, Blocks.cobblestone, 0, 3);
		world.setBlock(x + 3, y + -5, z + 11, Blocks.planks, 1, 3);
		world.setBlock(x + 4, y + -5, z + 11, Blocks.air, 0, 3);
		world.setBlock(x + 5, y + -5, z + 11, Blocks.air, 0, 3);
		world.setBlock(x + 6, y + -5, z + 11, Blocks.air, 0, 3);
		world.setBlock(x + 7, y + -5, z + 11, Blocks.chest, 5, 3);
		world.setBlock(x + 8, y + -5, z + 11, Blocks.air, 0, 3);
		world.setBlock(x + 9, y + -5, z + 11, Blocks.air, 0, 3);
		world.setBlock(x + 10, y + -5, z + 11, Blocks.air, 0, 3);
		world.setBlock(x + 11, y + -5, z + 11, Blocks.planks, 1, 3);
		world.setBlock(x + 12, y + -5, z + 11, Blocks.monster_egg, 1, 3);
		world.setBlock(x + 13, y + -5, z + 11, Blocks.dirt, 0, 3);
		world.setBlock(x + 14, y + -5, z + 11, Blocks.dirt, 0, 3);
		world.setBlock(x + 0, y + -5, z + 12, Blocks.dirt, 0, 3);
		world.setBlock(x + 1, y + -5, z + 12, Blocks.dirt, 0, 3);
		world.setBlock(x + 2, y + -5, z + 12, Blocks.cobblestone, 0, 3);
		world.setBlock(x + 3, y + -5, z + 12, Blocks.air, 0, 3);
		world.setBlock(x + 4, y + -5, z + 12, Blocks.air, 0, 3);
		world.setBlock(x + 5, y + -5, z + 12, Blocks.air, 0, 3);
		world.setBlock(x + 6, y + -5, z + 12, Blocks.air, 0, 3);
		world.setBlock(x + 7, y + -5, z + 12, Blocks.air, 0, 3);
		world.setBlock(x + 8, y + -5, z + 12, Blocks.air, 0, 3);
		world.setBlock(x + 9, y + -5, z + 12, Blocks.air, 0, 3);
		world.setBlock(x + 10, y + -5, z + 12, Blocks.air, 0, 3);
		world.setBlock(x + 11, y + -5, z + 12, Blocks.air, 0, 3);
		world.setBlock(x + 12, y + -5, z + 12, Blocks.cobblestone, 0, 3);
		world.setBlock(x + 13, y + -5, z + 12, Blocks.dirt, 0, 3);
		world.setBlock(x + 14, y + -5, z + 12, Blocks.dirt, 0, 3);
		world.setBlock(x + 0, y + -5, z + 13, Blocks.dirt, 0, 3);
		world.setBlock(x + 1, y + -5, z + 13, Blocks.dirt, 0, 3);
		world.setBlock(x + 2, y + -5, z + 13, Blocks.cobblestone, 0, 3);
		world.setBlock(x + 3, y + -5, z + 13, Blocks.air, 0, 3);
		world.setBlock(x + 4, y + -5, z + 13, Blocks.air, 0, 3);
		world.setBlock(x + 5, y + -5, z + 13, Blocks.air, 0, 3);
		world.setBlock(x + 6, y + -5, z + 13, Blocks.air, 0, 3);
		world.setBlock(x + 7, y + -5, z + 13, Blocks.air, 0, 3);
		world.setBlock(x + 8, y + -5, z + 13, Blocks.air, 0, 3);
		world.setBlock(x + 9, y + -5, z + 13, Blocks.air, 0, 3);
		world.setBlock(x + 10, y + -5, z + 13, Blocks.air, 0, 3);
		world.setBlock(x + 11, y + -5, z + 13, Blocks.air, 0, 3);
		world.setBlock(x + 12, y + -5, z + 13, Blocks.cobblestone, 0, 3);
		world.setBlock(x + 13, y + -5, z + 13, Blocks.dirt, 0, 3);
		world.setBlock(x + 14, y + -5, z + 13, Blocks.dirt, 0, 3);
		world.setBlock(x + 0, y + -5, z + 14, Blocks.dirt, 0, 3);
		world.setBlock(x + 1, y + -5, z + 14, Blocks.dirt, 0, 3);
		world.setBlock(x + 2, y + -5, z + 14, Blocks.cobblestone, 0, 3);
		world.setBlock(x + 3, y + -5, z + 14, Blocks.air, 0, 3);
		world.setBlock(x + 4, y + -5, z + 14, Blocks.air, 0, 3);
		world.setBlock(x + 5, y + -5, z + 14, Blocks.air, 0, 3);
		world.setBlock(x + 6, y + -5, z + 14, Blocks.air, 0, 3);
		world.setBlock(x + 7, y + -5, z + 14, Blocks.air, 0, 3);
		world.setBlock(x + 8, y + -5, z + 14, Blocks.air, 0, 3);
		world.setBlock(x + 9, y + -5, z + 14, Blocks.air, 0, 3);
		world.setBlock(x + 10, y + -5, z + 14, Blocks.air, 0, 3);
		world.setBlock(x + 11, y + -5, z + 14, Blocks.air, 0, 3);
		world.setBlock(x + 12, y + -5, z + 14, Blocks.cobblestone, 0, 3);
		world.setBlock(x + 13, y + -5, z + 14, Blocks.dirt, 0, 3);
		world.setBlock(x + 14, y + -5, z + 14, Blocks.dirt, 0, 3);
		world.setBlock(x + 0, y + -5, z + 15, Blocks.dirt, 0, 3);
		world.setBlock(x + 1, y + -5, z + 15, Blocks.dirt, 0, 3);
		world.setBlock(x + 2, y + -5, z + 15, Blocks.cobblestone, 0, 3);
		world.setBlock(x + 3, y + -5, z + 15, Blocks.air, 0, 3);
		world.setBlock(x + 4, y + -5, z + 15, Blocks.air, 0, 3);
		world.setBlock(x + 5, y + -5, z + 15, Blocks.air, 0, 3);
		world.setBlock(x + 6, y + -5, z + 15, Blocks.air, 0, 3);
		world.setBlock(x + 7, y + -5, z + 15, Blocks.air, 0, 3);
		world.setBlock(x + 8, y + -5, z + 15, Blocks.air, 0, 3);
		world.setBlock(x + 9, y + -5, z + 15, Blocks.air, 0, 3);
		world.setBlock(x + 10, y + -5, z + 15, Blocks.air, 0, 3);
		world.setBlock(x + 11, y + -5, z + 15, Blocks.air, 0, 3);
		world.setBlock(x + 12, y + -5, z + 15, Blocks.cobblestone, 0, 3);
		world.setBlock(x + 13, y + -5, z + 15, Blocks.dirt, 0, 3);
		world.setBlock(x + 14, y + -5, z + 15, Blocks.dirt, 0, 3);
		world.setBlock(x + 0, y + -5, z + 16, Blocks.dirt, 0, 3);
		world.setBlock(x + 1, y + -5, z + 16, Blocks.dirt, 0, 3);
		world.setBlock(x + 2, y + -5, z + 16, Blocks.cobblestone, 0, 3);
		world.setBlock(x + 3, y + -5, z + 16, Blocks.air, 0, 3);
		world.setBlock(x + 4, y + -5, z + 16, Blocks.fence, 0, 3);
		world.setBlock(x + 5, y + -5, z + 16, Blocks.lapis_block, 0, 3);
		world.setBlock(x + 6, y + -5, z + 16, Blocks.air, 0, 3);
		world.setBlock(x + 7, y + -5, z + 16, Blocks.fence, 0, 3);
		world.setBlock(x + 8, y + -5, z + 16, Blocks.air, 0, 3);
		world.setBlock(x + 9, y + -5, z + 16, Blocks.air, 0, 3);
		world.setBlock(x + 10, y + -5, z + 16, Blocks.fence, 0, 3);
		world.setBlock(x + 11, y + -5, z + 16, Blocks.crafting_table, 0, 3);
		world.setBlock(x + 12, y + -5, z + 16, Blocks.cobblestone, 0, 3);
		world.setBlock(x + 13, y + -5, z + 16, Blocks.dirt, 0, 3);
		world.setBlock(x + 14, y + -5, z + 16, Blocks.dirt, 0, 3);
		world.setBlock(x + 0, y + -5, z + 17, Blocks.dirt, 0, 3);
		world.setBlock(x + 1, y + -5, z + 17, Blocks.dirt, 0, 3);
		world.setBlock(x + 2, y + -5, z + 17, Blocks.cobblestone, 0, 3);
		world.setBlock(x + 3, y + -5, z + 17, Blocks.cobblestone, 0, 3);
		world.setBlock(x + 4, y + -5, z + 17, Blocks.cobblestone, 0, 3);
		world.setBlock(x + 5, y + -5, z + 17, Blocks.cobblestone, 0, 3);
		world.setBlock(x + 6, y + -5, z + 17, Blocks.cobblestone, 0, 3);
		world.setBlock(x + 7, y + -5, z + 17, Blocks.cobblestone, 0, 3);
		world.setBlock(x + 8, y + -5, z + 17, Blocks.cobblestone, 0, 3);
		world.setBlock(x + 9, y + -5, z + 17, Blocks.air, 0, 3);
		world.setBlock(x + 10, y + -5, z + 17, Blocks.cobblestone, 0, 3);
		world.setBlock(x + 11, y + -5, z + 17, Blocks.cobblestone, 0, 3);
		world.setBlock(x + 12, y + -5, z + 17, Blocks.cobblestone, 0, 3);
		world.setBlock(x + 13, y + -5, z + 17, Blocks.dirt, 0, 3);
		world.setBlock(x + 14, y + -5, z + 17, Blocks.dirt, 0, 3);
		world.setBlock(x + 0, y + -5, z + 18, Blocks.dirt, 0, 3);
		world.setBlock(x + 1, y + -5, z + 18, Blocks.dirt, 0, 3);
		world.setBlock(x + 2, y + -5, z + 18, Blocks.monster_egg, 1, 3);
		world.setBlock(x + 3, y + -5, z + 18, Blocks.planks, 2, 3);
		world.setBlock(x + 4, y + -5, z + 18, Blocks.birch_stairs, 1, 3);
		world.setBlock(x + 5, y + -5, z + 18, Blocks.air, 0, 3);
		world.setBlock(x + 6, y + -5, z + 18, Blocks.wooden_slab, 13, 3);
		world.setBlock(x + 7, y + -5, z + 18, Blocks.wooden_slab, 13, 3);
		world.setBlock(x + 8, y + -5, z + 18, Blocks.air, 0, 3);
		world.setBlock(x + 9, y + -5, z + 18, Blocks.air, 0, 3);
		world.setBlock(x + 10, y + -5, z + 18, Blocks.air, 0, 3);
		world.setBlock(x + 11, y + -5, z + 18, Blocks.chest, 4, 3);
		world.setBlock(x + 12, y + -5, z + 18, Blocks.cobblestone, 0, 3);
		world.setBlock(x + 13, y + -5, z + 18, Blocks.dirt, 0, 3);
		world.setBlock(x + 14, y + -5, z + 18, Blocks.stone, 0, 3);
		world.setBlock(x + 0, y + -5, z + 19, Blocks.dirt, 0, 3);
		world.setBlock(x + 1, y + -5, z + 19, Blocks.dirt, 0, 3);
		world.setBlock(x + 2, y + -5, z + 19, Blocks.cobblestone, 0, 3);
		world.setBlock(x + 3, y + -5, z + 19, Blocks.crafting_table, 0, 3);
		world.setBlock(x + 4, y + -5, z + 19, Blocks.air, 0, 3);
		world.setBlock(x + 5, y + -5, z + 19, Blocks.air, 0, 3);
		world.setBlock(x + 6, y + -5, z + 19, Blocks.air, 0, 3);
		world.setBlock(x + 7, y + -5, z + 19, Blocks.air, 0, 3);
		world.setBlock(x + 8, y + -5, z + 19, Blocks.air, 0, 3);
		world.setBlock(x + 9, y + -5, z + 19, Blocks.air, 0, 3);
		world.setBlock(x + 10, y + -5, z + 19, Blocks.air, 0, 3);
		world.setBlock(x + 11, y + -5, z + 19, Blocks.crafting_table, 0, 3);
		world.setBlock(x + 12, y + -5, z + 19, Blocks.cobblestone, 0, 3);
		world.setBlock(x + 13, y + -5, z + 19, Blocks.dirt, 0, 3);
		world.setBlock(x + 14, y + -5, z + 19, Blocks.stone, 0, 3);
		world.setBlock(x + 0, y + -5, z + 20, Blocks.dirt, 0, 3);
		world.setBlock(x + 1, y + -5, z + 20, Blocks.dirt, 0, 3);
		world.setBlock(x + 2, y + -5, z + 20, Blocks.cobblestone, 0, 3);
		world.setBlock(x + 3, y + -5, z + 20, Blocks.air, 0, 3);
		world.setBlock(x + 4, y + -5, z + 20, Blocks.air, 0, 3);
		world.setBlock(x + 5, y + -5, z + 20, Blocks.air, 0, 3);
		world.setBlock(x + 6, y + -5, z + 20, Blocks.air, 0, 3);
		world.setBlock(x + 7, y + -5, z + 20, Blocks.air, 0, 3);
		world.setBlock(x + 8, y + -5, z + 20, Blocks.air, 0, 3);
		world.setBlock(x + 9, y + -5, z + 20, Blocks.air, 0, 3);
		world.setBlock(x + 10, y + -5, z + 20, Blocks.air, 0, 3);
		world.setBlock(x + 11, y + -5, z + 20, Blocks.web, 0, 3);
		world.setBlock(x + 12, y + -5, z + 20, Blocks.cobblestone, 0, 3);
		world.setBlock(x + 13, y + -5, z + 20, Blocks.dirt, 0, 3);
		world.setBlock(x + 14, y + -5, z + 20, Blocks.dirt, 0, 3);
		world.setBlock(x + 0, y + -5, z + 21, Blocks.dirt, 0, 3);
		world.setBlock(x + 1, y + -5, z + 21, Blocks.dirt, 0, 3);
		world.setBlock(x + 2, y + -5, z + 21, Blocks.cobblestone, 0, 3);
		world.setBlock(x + 3, y + -5, z + 21, Blocks.air, 0, 3);
		world.setBlock(x + 4, y + -5, z + 21, Blocks.air, 0, 3);
		world.setBlock(x + 5, y + -5, z + 21, Blocks.air, 0, 3);
		world.setBlock(x + 6, y + -5, z + 21, Blocks.air, 0, 3);
		world.setBlock(x + 7, y + -5, z + 21, Blocks.air, 0, 3);
		world.setBlock(x + 8, y + -5, z + 21, Blocks.air, 0, 3);
		world.setBlock(x + 9, y + -5, z + 21, Blocks.air, 0, 3);
		world.setBlock(x + 10, y + -5, z + 21, Blocks.bookshelf, 0, 3);
		world.setBlock(x + 11, y + -5, z + 21, Blocks.planks, 2, 3);
		world.setBlock(x + 12, y + -5, z + 21, Blocks.cobblestone, 0, 3);
		world.setBlock(x + 13, y + -5, z + 21, Blocks.dirt, 0, 3);
		world.setBlock(x + 14, y + -5, z + 21, Blocks.stone, 0, 3);
		world.setBlock(x + 0, y + -5, z + 22, Blocks.dirt, 0, 3);
		world.setBlock(x + 1, y + -5, z + 22, Blocks.dirt, 0, 3);
		world.setBlock(x + 2, y + -5, z + 22, Blocks.cobblestone, 0, 3);
		world.setBlock(x + 3, y + -5, z + 22, Blocks.air, 0, 3);
		world.setBlock(x + 4, y + -5, z + 22, Blocks.air, 0, 3);
		world.setBlock(x + 5, y + -5, z + 22, Blocks.air, 0, 3);
		world.setBlock(x + 6, y + -5, z + 22, Blocks.air, 0, 3);
		world.setBlock(x + 7, y + -5, z + 22, Blocks.iron_bars, 0, 3);
		world.setBlock(x + 8, y + -5, z + 22, Blocks.air, 0, 3);
		world.setBlock(x + 9, y + -5, z + 22, Blocks.air, 0, 3);
		world.setBlock(x + 10, y + -5, z + 22, Blocks.web, 0, 3);
		world.setBlock(x + 11, y + -5, z + 22, Blocks.chest, 4, 3);
		world.setBlock(x + 12, y + -5, z + 22, Blocks.cobblestone, 0, 3);
		world.setBlock(x + 13, y + -5, z + 22, Blocks.dirt, 0, 3);
		world.setBlock(x + 14, y + -5, z + 22, Blocks.stone, 0, 3);
		world.setBlock(x + 0, y + -5, z + 23, Blocks.dirt, 0, 3);
		world.setBlock(x + 1, y + -5, z + 23, Blocks.dirt, 0, 3);
		world.setBlock(x + 2, y + -5, z + 23, Blocks.cobblestone, 0, 3);
		world.setBlock(x + 3, y + -5, z + 23, Blocks.air, 0, 3);
		world.setBlock(x + 4, y + -5, z + 23, Blocks.air, 0, 3);
		world.setBlock(x + 5, y + -5, z + 23, Blocks.air, 0, 3);
		world.setBlock(x + 6, y + -5, z + 23, Blocks.anvil, 6, 3);
		world.setBlock(x + 7, y + -5, z + 23, Blocks.fence, 0, 3);
		world.setBlock(x + 8, y + -5, z + 23, Blocks.crafting_table, 0, 3);
		world.setBlock(x + 9, y + -5, z + 23, Blocks.oak_stairs, 6, 3);
		world.setBlock(x + 10, y + -5, z + 23, Blocks.birch_stairs, 0, 3);
		world.setBlock(x + 11, y + -5, z + 23, Blocks.planks, 0, 3);
		world.setBlock(x + 12, y + -5, z + 23, Blocks.cobblestone, 0, 3);
		world.setBlock(x + 13, y + -5, z + 23, Blocks.dirt, 0, 3);
		world.setBlock(x + 14, y + -5, z + 23, Blocks.stone, 0, 3);
		world.setBlock(x + 0, y + -5, z + 24, Blocks.dirt, 0, 3);
		world.setBlock(x + 1, y + -5, z + 24, Blocks.dirt, 0, 3);
		world.setBlock(x + 2, y + -5, z + 24, Blocks.cobblestone, 0, 3);
		world.setBlock(x + 3, y + -5, z + 24, Blocks.air, 0, 3);
		world.setBlock(x + 4, y + -5, z + 24, Blocks.air, 0, 3);
		world.setBlock(x + 5, y + -5, z + 24, Blocks.air, 0, 3);
		world.setBlock(x + 6, y + -5, z + 24, Blocks.air, 0, 3);
		world.setBlock(x + 7, y + -5, z + 24, Blocks.air, 0, 3);
		world.setBlock(x + 8, y + -5, z + 24, Blocks.air, 0, 3);
		world.setBlock(x + 9, y + -5, z + 24, Blocks.air, 0, 3);
		world.setBlock(x + 10, y + -5, z + 24, Blocks.air, 0, 3);
		world.setBlock(x + 11, y + -5, z + 24, Blocks.air, 0, 3);
		world.setBlock(x + 12, y + -5, z + 24, Blocks.cobblestone, 0, 3);
		world.setBlock(x + 13, y + -5, z + 24, Blocks.dirt, 0, 3);
		world.setBlock(x + 14, y + -5, z + 24, Blocks.stone, 0, 3);
		world.setBlock(x + 0, y + -5, z + 25, Blocks.dirt, 0, 3);
		world.setBlock(x + 1, y + -5, z + 25, Blocks.dirt, 0, 3);
		world.setBlock(x + 2, y + -5, z + 25, Blocks.cobblestone, 0, 3);
		world.setBlock(x + 3, y + -5, z + 25, Blocks.chest, 2, 3);
		world.setBlock(x + 4, y + -5, z + 25, Blocks.air, 0, 3);
		world.setBlock(x + 5, y + -5, z + 25, Blocks.air, 0, 3);
		world.setBlock(x + 6, y + -5, z + 25, Blocks.air, 0, 3);
		world.setBlock(x + 7, y + -5, z + 25, Blocks.air, 0, 3);
		world.setBlock(x + 8, y + -5, z + 25, Blocks.air, 0, 3);
		world.setBlock(x + 9, y + -5, z + 25, Blocks.air, 0, 3);
		world.setBlock(x + 10, y + -5, z + 25, Blocks.air, 0, 3);
		world.setBlock(x + 11, y + -5, z + 25, Blocks.air, 0, 3);
		world.setBlock(x + 12, y + -5, z + 25, Blocks.cobblestone, 0, 3);
		world.setBlock(x + 13, y + -5, z + 25, Blocks.dirt, 0, 3);
		world.setBlock(x + 14, y + -5, z + 25, Blocks.stone, 0, 3);
		world.setBlock(x + 0, y + -5, z + 26, Blocks.dirt, 0, 3);
		world.setBlock(x + 1, y + -5, z + 26, Blocks.dirt, 0, 3);
		world.setBlock(x + 2, y + -5, z + 26, Blocks.cobblestone, 0, 3);
		world.setBlock(x + 3, y + -5, z + 26, Blocks.planks, 0, 3);
		world.setBlock(x + 4, y + -5, z + 26, Blocks.planks, 2, 3);
		world.setBlock(x + 5, y + -5, z + 26, Blocks.air, 0, 3);
		world.setBlock(x + 6, y + -5, z + 26, Blocks.iron_bars, 0, 3);
		world.setBlock(x + 7, y + -5, z + 26, Blocks.iron_bars, 0, 3);
		world.setBlock(x + 8, y + -5, z + 26, Blocks.oak_stairs, 5, 3);
		world.setBlock(x + 9, y + -5, z + 26, Blocks.wooden_slab, 8, 3);
		world.setBlock(x + 10, y + -5, z + 26, Blocks.crafting_table, 0, 3);
		world.setBlock(x + 11, y + -5, z + 26, Blocks.chest, 2, 3);
		world.setBlock(x + 12, y + -5, z + 26, Blocks.cobblestone, 0, 3);
		world.setBlock(x + 13, y + -5, z + 26, Blocks.dirt, 0, 3);
		world.setBlock(x + 14, y + -5, z + 26, Blocks.stone, 0, 3);
		world.setBlock(x + 0, y + -5, z + 27, Blocks.dirt, 0, 3);
		world.setBlock(x + 1, y + -5, z + 27, Blocks.dirt, 0, 3);
		world.setBlock(x + 2, y + -5, z + 27, Blocks.cobblestone, 0, 3);
		world.setBlock(x + 3, y + -5, z + 27, Blocks.cobblestone, 0, 3);
		world.setBlock(x + 4, y + -5, z + 27, Blocks.cobblestone, 0, 3);
		world.setBlock(x + 5, y + -5, z + 27, Blocks.cobblestone, 0, 3);
		world.setBlock(x + 6, y + -5, z + 27, Blocks.cobblestone, 0, 3);
		world.setBlock(x + 7, y + -5, z + 27, Blocks.cobblestone, 0, 3);
		world.setBlock(x + 8, y + -5, z + 27, Blocks.cobblestone, 0, 3);
		world.setBlock(x + 9, y + -5, z + 27, Blocks.cobblestone, 0, 3);
		world.setBlock(x + 10, y + -5, z + 27, Blocks.cobblestone, 0, 3);
		world.setBlock(x + 11, y + -5, z + 27, Blocks.cobblestone, 0, 3);
		world.setBlock(x + 12, y + -5, z + 27, Blocks.cobblestone, 0, 3);
		world.setBlock(x + 13, y + -5, z + 27, Blocks.dirt, 0, 3);
		world.setBlock(x + 14, y + -5, z + 27, Blocks.stone, 0, 3);
		world.setBlock(x + 0, y + -5, z + 28, Blocks.dirt, 0, 3);
		world.setBlock(x + 1, y + -5, z + 28, Blocks.dirt, 0, 3);
		world.setBlock(x + 2, y + -5, z + 28, Blocks.dirt, 0, 3);
		world.setBlock(x + 3, y + -5, z + 28, Blocks.dirt, 0, 3);
		world.setBlock(x + 4, y + -5, z + 28, Blocks.dirt, 0, 3);
		world.setBlock(x + 5, y + -5, z + 28, Blocks.dirt, 0, 3);
		world.setBlock(x + 6, y + -5, z + 28, Blocks.dirt, 0, 3);
		world.setBlock(x + 7, y + -5, z + 28, Blocks.dirt, 0, 3);
		world.setBlock(x + 8, y + -5, z + 28, Blocks.dirt, 0, 3);
		world.setBlock(x + 9, y + -5, z + 28, Blocks.dirt, 0, 3);
		world.setBlock(x + 10, y + -5, z + 28, Blocks.dirt, 0, 3);
		world.setBlock(x + 11, y + -5, z + 28, Blocks.dirt, 0, 3);
		world.setBlock(x + 12, y + -5, z + 28, Blocks.dirt, 0, 3);
		world.setBlock(x + 13, y + -5, z + 28, Blocks.dirt, 0, 3);
		world.setBlock(x + 14, y + -5, z + 28, Blocks.stone, 0, 3);
		world.setBlock(x + 0, y + -5, z + 29, Blocks.dirt, 0, 3);
		world.setBlock(x + 1, y + -5, z + 29, Blocks.dirt, 0, 3);
		world.setBlock(x + 2, y + -5, z + 29, Blocks.dirt, 0, 3);
		world.setBlock(x + 3, y + -5, z + 29, Blocks.dirt, 0, 3);
		world.setBlock(x + 4, y + -5, z + 29, Blocks.dirt, 0, 3);
		world.setBlock(x + 5, y + -5, z + 29, Blocks.dirt, 0, 3);
		world.setBlock(x + 6, y + -5, z + 29, Blocks.dirt, 0, 3);
		world.setBlock(x + 7, y + -5, z + 29, Blocks.dirt, 0, 3);
		world.setBlock(x + 8, y + -5, z + 29, Blocks.dirt, 0, 3);
		world.setBlock(x + 9, y + -5, z + 29, Blocks.dirt, 0, 3);
		world.setBlock(x + 10, y + -5, z + 29, Blocks.dirt, 0, 3);
		world.setBlock(x + 11, y + -5, z + 29, Blocks.dirt, 0, 3);
		world.setBlock(x + 12, y + -5, z + 29, Blocks.dirt, 0, 3);
		world.setBlock(x + 13, y + -5, z + 29, Blocks.dirt, 0, 3);
		world.setBlock(x + 14, y + -5, z + 29, Blocks.stone, 0, 3);
		world.setBlock(x + 0, y + -4, z + 0, Blocks.dirt, 0, 3);
		world.setBlock(x + 1, y + -4, z + 0, Blocks.dirt, 0, 3);
		world.setBlock(x + 2, y + -4, z + 0, Blocks.dirt, 0, 3);
		world.setBlock(x + 3, y + -4, z + 0, Blocks.dirt, 0, 3);
		world.setBlock(x + 4, y + -4, z + 0, Blocks.dirt, 0, 3);
		world.setBlock(x + 5, y + -4, z + 0, Blocks.dirt, 0, 3);
		world.setBlock(x + 6, y + -4, z + 0, Blocks.dirt, 0, 3);
		world.setBlock(x + 7, y + -4, z + 0, Blocks.dirt, 0, 3);
		world.setBlock(x + 8, y + -4, z + 0, Blocks.dirt, 0, 3);
		world.setBlock(x + 9, y + -4, z + 0, Blocks.dirt, 0, 3);
		world.setBlock(x + 10, y + -4, z + 0, Blocks.dirt, 0, 3);
		world.setBlock(x + 11, y + -4, z + 0, Blocks.dirt, 0, 3);
		world.setBlock(x + 12, y + -4, z + 0, Blocks.dirt, 0, 3);
		world.setBlock(x + 13, y + -4, z + 0, Blocks.dirt, 0, 3);
		world.setBlock(x + 14, y + -4, z + 0, Blocks.dirt, 0, 3);
		world.setBlock(x + 0, y + -4, z + 1, Blocks.dirt, 0, 3);
		world.setBlock(x + 1, y + -4, z + 1, Blocks.dirt, 0, 3);
		world.setBlock(x + 2, y + -4, z + 1, Blocks.dirt, 0, 3);
		world.setBlock(x + 3, y + -4, z + 1, Blocks.dirt, 0, 3);
		world.setBlock(x + 4, y + -4, z + 1, Blocks.dirt, 0, 3);
		world.setBlock(x + 5, y + -4, z + 1, Blocks.dirt, 0, 3);
		world.setBlock(x + 6, y + -4, z + 1, Blocks.dirt, 0, 3);
		world.setBlock(x + 7, y + -4, z + 1, Blocks.dirt, 0, 3);
		world.setBlock(x + 8, y + -4, z + 1, Blocks.dirt, 0, 3);
		world.setBlock(x + 9, y + -4, z + 1, Blocks.dirt, 0, 3);
		world.setBlock(x + 10, y + -4, z + 1, Blocks.dirt, 0, 3);
		world.setBlock(x + 11, y + -4, z + 1, Blocks.dirt, 0, 3);
		world.setBlock(x + 12, y + -4, z + 1, Blocks.dirt, 0, 3);
		world.setBlock(x + 13, y + -4, z + 1, Blocks.dirt, 0, 3);
		world.setBlock(x + 14, y + -4, z + 1, Blocks.dirt, 0, 3);
		world.setBlock(x + 0, y + -4, z + 2, Blocks.dirt, 0, 3);
		world.setBlock(x + 1, y + -4, z + 2, Blocks.dirt, 0, 3);
		world.setBlock(x + 2, y + -4, z + 2, Blocks.dirt, 0, 3);
		world.setBlock(x + 3, y + -4, z + 2, Blocks.dirt, 0, 3);
		world.setBlock(x + 4, y + -4, z + 2, Blocks.dirt, 0, 3);
		world.setBlock(x + 5, y + -4, z + 2, Blocks.dirt, 0, 3);
		world.setBlock(x + 6, y + -4, z + 2, Blocks.dirt, 0, 3);
		world.setBlock(x + 7, y + -4, z + 2, Blocks.dirt, 0, 3);
		world.setBlock(x + 8, y + -4, z + 2, Blocks.dirt, 0, 3);
		world.setBlock(x + 9, y + -4, z + 2, Blocks.dirt, 0, 3);
		world.setBlock(x + 10, y + -4, z + 2, Blocks.dirt, 0, 3);
		world.setBlock(x + 11, y + -4, z + 2, Blocks.dirt, 0, 3);
		world.setBlock(x + 12, y + -4, z + 2, Blocks.dirt, 0, 3);
		world.setBlock(x + 13, y + -4, z + 2, Blocks.dirt, 0, 3);
		world.setBlock(x + 14, y + -4, z + 2, Blocks.dirt, 0, 3);
		world.setBlock(x + 0, y + -4, z + 3, Blocks.dirt, 0, 3);
		world.setBlock(x + 1, y + -4, z + 3, Blocks.dirt, 0, 3);
		world.setBlock(x + 2, y + -4, z + 3, Blocks.dirt, 0, 3);
		world.setBlock(x + 3, y + -4, z + 3, Blocks.dirt, 0, 3);
		world.setBlock(x + 4, y + -4, z + 3, Blocks.dirt, 0, 3);
		world.setBlock(x + 5, y + -4, z + 3, Blocks.dirt, 0, 3);
		world.setBlock(x + 6, y + -4, z + 3, Blocks.dirt, 0, 3);
		world.setBlock(x + 7, y + -4, z + 3, Blocks.dirt, 0, 3);
		world.setBlock(x + 8, y + -4, z + 3, Blocks.dirt, 0, 3);
		world.setBlock(x + 9, y + -4, z + 3, Blocks.dirt, 0, 3);
		world.setBlock(x + 10, y + -4, z + 3, Blocks.dirt, 0, 3);
		world.setBlock(x + 11, y + -4, z + 3, Blocks.dirt, 0, 3);
		world.setBlock(x + 12, y + -4, z + 3, Blocks.dirt, 0, 3);
		world.setBlock(x + 13, y + -4, z + 3, Blocks.dirt, 0, 3);
		world.setBlock(x + 14, y + -4, z + 3, Blocks.dirt, 0, 3);
		world.setBlock(x + 0, y + -4, z + 4, Blocks.dirt, 0, 3);
		world.setBlock(x + 1, y + -4, z + 4, Blocks.dirt, 0, 3);
		world.setBlock(x + 2, y + -4, z + 4, Blocks.dirt, 0, 3);
		world.setBlock(x + 3, y + -4, z + 4, Blocks.dirt, 0, 3);
		world.setBlock(x + 4, y + -4, z + 4, Blocks.dirt, 0, 3);
		world.setBlock(x + 5, y + -4, z + 4, Blocks.dirt, 0, 3);
		world.setBlock(x + 6, y + -4, z + 4, Blocks.dirt, 0, 3);
		world.setBlock(x + 7, y + -4, z + 4, Blocks.dirt, 0, 3);
		world.setBlock(x + 8, y + -4, z + 4, Blocks.dirt, 0, 3);
		world.setBlock(x + 9, y + -4, z + 4, Blocks.dirt, 0, 3);
		world.setBlock(x + 10, y + -4, z + 4, Blocks.dirt, 0, 3);
		world.setBlock(x + 11, y + -4, z + 4, Blocks.dirt, 0, 3);
		world.setBlock(x + 12, y + -4, z + 4, Blocks.dirt, 0, 3);
		world.setBlock(x + 13, y + -4, z + 4, Blocks.dirt, 0, 3);
		world.setBlock(x + 14, y + -4, z + 4, Blocks.dirt, 0, 3);
		world.setBlock(x + 0, y + -4, z + 5, Blocks.dirt, 0, 3);
		world.setBlock(x + 1, y + -4, z + 5, Blocks.dirt, 0, 3);
		world.setBlock(x + 2, y + -4, z + 5, Blocks.cobblestone, 0, 3);
		world.setBlock(x + 3, y + -4, z + 5, Blocks.cobblestone, 0, 3);
		world.setBlock(x + 4, y + -4, z + 5, Blocks.cobblestone, 0, 3);
		world.setBlock(x + 5, y + -4, z + 5, Blocks.cobblestone, 0, 3);
		world.setBlock(x + 6, y + -4, z + 5, Blocks.cobblestone, 0, 3);
		world.setBlock(x + 7, y + -4, z + 5, Blocks.cobblestone, 0, 3);
		world.setBlock(x + 8, y + -4, z + 5, Blocks.cobblestone, 0, 3);
		world.setBlock(x + 9, y + -4, z + 5, Blocks.cobblestone, 0, 3);
		world.setBlock(x + 10, y + -4, z + 5, Blocks.cobblestone, 0, 3);
		world.setBlock(x + 11, y + -4, z + 5, Blocks.cobblestone, 0, 3);
		world.setBlock(x + 12, y + -4, z + 5, Blocks.cobblestone, 0, 3);
		world.setBlock(x + 13, y + -4, z + 5, Blocks.dirt, 0, 3);
		world.setBlock(x + 14, y + -4, z + 5, Blocks.dirt, 0, 3);
		world.setBlock(x + 0, y + -4, z + 6, Blocks.dirt, 0, 3);
		world.setBlock(x + 1, y + -4, z + 6, Blocks.dirt, 0, 3);
		world.setBlock(x + 2, y + -4, z + 6, Blocks.cobblestone, 0, 3);
		world.setBlock(x + 3, y + -4, z + 6, Blocks.chest, 5, 3);
		world.setBlock(x + 4, y + -4, z + 6, Blocks.air, 0, 3);
		world.setBlock(x + 5, y + -4, z + 6, Blocks.air, 0, 3);
		world.setBlock(x + 6, y + -4, z + 6, Blocks.air, 0, 3);
		world.setBlock(x + 7, y + -4, z + 6, Blocks.cobblestone, 0, 3);
		world.setBlock(x + 8, y + -4, z + 6, Blocks.cobblestone, 0, 3);
		world.setBlock(x + 9, y + -4, z + 6, Blocks.air, 0, 3);
		world.setBlock(x + 10, y + -4, z + 6, Blocks.air, 0, 3);
		world.setBlock(x + 11, y + -4, z + 6, Blocks.air, 0, 3);
		world.setBlock(x + 12, y + -4, z + 6, Blocks.cobblestone, 0, 3);
		world.setBlock(x + 13, y + -4, z + 6, Blocks.dirt, 0, 3);
		world.setBlock(x + 14, y + -4, z + 6, Blocks.dirt, 0, 3);
		world.setBlock(x + 0, y + -4, z + 7, Blocks.dirt, 0, 3);
		world.setBlock(x + 1, y + -4, z + 7, Blocks.dirt, 0, 3);
		world.setBlock(x + 2, y + -4, z + 7, Blocks.cobblestone, 0, 3);
		world.setBlock(x + 3, y + -4, z + 7, Blocks.air, 0, 3);
		world.setBlock(x + 4, y + -4, z + 7, Blocks.air, 0, 3);
		world.setBlock(x + 5, y + -4, z + 7, Blocks.air, 0, 3);
		world.setBlock(x + 6, y + -4, z + 7, Blocks.air, 0, 3);
		world.setBlock(x + 7, y + -4, z + 7, Blocks.cobblestone, 0, 3);
		world.setBlock(x + 8, y + -4, z + 7, Blocks.cobblestone, 0, 3);
		world.setBlock(x + 9, y + -4, z + 7, Blocks.air, 0, 3);
		world.setBlock(x + 10, y + -4, z + 7, Blocks.air, 0, 3);
		world.setBlock(x + 11, y + -4, z + 7, Blocks.quartz_block, 0, 3);
		world.setBlock(x + 12, y + -4, z + 7, Blocks.cobblestone, 0, 3);
		world.setBlock(x + 13, y + -4, z + 7, Blocks.dirt, 0, 3);
		world.setBlock(x + 14, y + -4, z + 7, Blocks.dirt, 0, 3);
		world.setBlock(x + 0, y + -4, z + 8, Blocks.dirt, 0, 3);
		world.setBlock(x + 1, y + -4, z + 8, Blocks.dirt, 0, 3);
		world.setBlock(x + 2, y + -4, z + 8, Blocks.cobblestone, 0, 3);
		world.setBlock(x + 3, y + -4, z + 8, Blocks.air, 0, 3);
		world.setBlock(x + 4, y + -4, z + 8, Blocks.air, 0, 3);
		world.setBlock(x + 5, y + -4, z + 8, Blocks.air, 0, 3);
		world.setBlock(x + 6, y + -4, z + 8, Blocks.air, 0, 3);
		world.setBlock(x + 7, y + -4, z + 8, Blocks.cobblestone, 0, 3);
		world.setBlock(x + 8, y + -4, z + 8, Blocks.cobblestone, 0, 3);
		world.setBlock(x + 9, y + -4, z + 8, Blocks.jungle_stairs, 3, 3);
		world.setBlock(x + 10, y + -4, z + 8, Blocks.air, 0, 3);
		world.setBlock(x + 11, y + -4, z + 8, Blocks.air, 0, 3);
		world.setBlock(x + 12, y + -4, z + 8, Blocks.cobblestone, 0, 3);
		world.setBlock(x + 13, y + -4, z + 8, Blocks.dirt, 0, 3);
		world.setBlock(x + 14, y + -4, z + 8, Blocks.dirt, 0, 3);
		world.setBlock(x + 0, y + -4, z + 9, Blocks.dirt, 0, 3);
		world.setBlock(x + 1, y + -4, z + 9, Blocks.dirt, 0, 3);
		world.setBlock(x + 2, y + -4, z + 9, Blocks.cobblestone, 0, 3);
		world.setBlock(x + 3, y + -4, z + 9, Blocks.air, 0, 3);
		world.setBlock(x + 4, y + -4, z + 9, Blocks.air, 0, 3);
		world.setBlock(x + 5, y + -4, z + 9, Blocks.air, 0, 3);
		world.setBlock(x + 6, y + -4, z + 9, Blocks.air, 0, 3);
		world.setBlock(x + 7, y + -4, z + 9, Blocks.cobblestone, 0, 3);
		world.setBlock(x + 8, y + -4, z + 9, Blocks.cobblestone, 0, 3);
		world.setBlock(x + 9, y + -4, z + 9, Blocks.air, 0, 3);
		world.setBlock(x + 10, y + -4, z + 9, Blocks.air, 0, 3);
		world.setBlock(x + 11, y + -4, z + 9, Blocks.flower_pot, 0, 3);
		world.setBlock(x + 12, y + -4, z + 9, Blocks.cobblestone, 0, 3);
		world.setBlock(x + 13, y + -4, z + 9, Blocks.dirt, 0, 3);
		world.setBlock(x + 14, y + -4, z + 9, Blocks.dirt, 0, 3);

		generate_r02(world, rand, x, y, z);
		return true;

	}
	public boolean generate_r02(World world, Random rand, int x, int y, int z)
	{

		world.setBlock(x + 0, y + -4, z + 10, Blocks.dirt, 0, 3);
		world.setBlock(x + 1, y + -4, z + 10, Blocks.dirt, 0, 3);
		world.setBlock(x + 2, y + -4, z + 10, Blocks.cobblestone, 0, 3);
		world.setBlock(x + 3, y + -4, z + 10, Blocks.air, 0, 3);
		world.setBlock(x + 4, y + -4, z + 10, Blocks.air, 0, 3);
		world.setBlock(x + 5, y + -4, z + 10, Blocks.air, 0, 3);
		world.setBlock(x + 6, y + -4, z + 10, Blocks.air, 0, 3);
		world.setBlock(x + 7, y + -4, z + 10, Blocks.chest, 3, 3);
		world.setBlock(x + 8, y + -4, z + 10, Blocks.air, 0, 3);
		world.setBlock(x + 9, y + -4, z + 10, Blocks.air, 0, 3);
		world.setBlock(x + 10, y + -4, z + 10, Blocks.air, 0, 3);
		world.setBlock(x + 11, y + -4, z + 10, Blocks.air, 0, 3);
		world.setBlock(x + 12, y + -4, z + 10, Blocks.cobblestone, 0, 3);
		world.setBlock(x + 13, y + -4, z + 10, Blocks.dirt, 0, 3);
		world.setBlock(x + 14, y + -4, z + 10, Blocks.dirt, 0, 3);
		world.setBlock(x + 0, y + -4, z + 11, Blocks.dirt, 0, 3);
		world.setBlock(x + 1, y + -4, z + 11, Blocks.dirt, 0, 3);
		world.setBlock(x + 2, y + -4, z + 11, Blocks.cobblestone, 0, 3);
		world.setBlock(x + 3, y + -4, z + 11, Blocks.planks, 1, 3);
		world.setBlock(x + 4, y + -4, z + 11, Blocks.air, 0, 3);
		world.setBlock(x + 5, y + -4, z + 11, Blocks.air, 0, 3);
		world.setBlock(x + 6, y + -4, z + 11, Blocks.air, 0, 3);
		world.setBlock(x + 7, y + -4, z + 11, Blocks.air, 0, 3);
		world.setBlock(x + 8, y + -4, z + 11, Blocks.air, 0, 3);
		world.setBlock(x + 9, y + -4, z + 11, Blocks.air, 0, 3);
		world.setBlock(x + 10, y + -4, z + 11, Blocks.air, 0, 3);
		world.setBlock(x + 11, y + -4, z + 11, Blocks.planks, 1, 3);
		world.setBlock(x + 12, y + -4, z + 11, Blocks.cobblestone, 0, 3);
		world.setBlock(x + 13, y + -4, z + 11, Blocks.dirt, 0, 3);
		world.setBlock(x + 14, y + -4, z + 11, Blocks.dirt, 0, 3);
		world.setBlock(x + 0, y + -4, z + 12, Blocks.dirt, 0, 3);
		world.setBlock(x + 1, y + -4, z + 12, Blocks.dirt, 0, 3);
		world.setBlock(x + 2, y + -4, z + 12, Blocks.cobblestone, 0, 3);
		world.setBlock(x + 3, y + -4, z + 12, Blocks.air, 0, 3);
		world.setBlock(x + 4, y + -4, z + 12, Blocks.air, 0, 3);
		world.setBlock(x + 5, y + -4, z + 12, Blocks.air, 0, 3);
		world.setBlock(x + 6, y + -4, z + 12, Blocks.air, 0, 3);
		world.setBlock(x + 7, y + -4, z + 12, Blocks.air, 0, 3);
		world.setBlock(x + 8, y + -4, z + 12, Blocks.air, 0, 3);
		world.setBlock(x + 9, y + -4, z + 12, Blocks.air, 0, 3);
		world.setBlock(x + 10, y + -4, z + 12, Blocks.air, 0, 3);
		world.setBlock(x + 11, y + -4, z + 12, Blocks.air, 0, 3);
		world.setBlock(x + 12, y + -4, z + 12, Blocks.cobblestone, 0, 3);
		world.setBlock(x + 13, y + -4, z + 12, Blocks.dirt, 0, 3);
		world.setBlock(x + 14, y + -4, z + 12, Blocks.dirt, 0, 3);
		world.setBlock(x + 0, y + -4, z + 13, Blocks.dirt, 0, 3);
		world.setBlock(x + 1, y + -4, z + 13, Blocks.dirt, 0, 3);
		world.setBlock(x + 2, y + -4, z + 13, Blocks.cobblestone, 0, 3);
		world.setBlock(x + 3, y + -4, z + 13, Blocks.air, 0, 3);
		world.setBlock(x + 4, y + -4, z + 13, Blocks.air, 0, 3);
		world.setBlock(x + 5, y + -4, z + 13, Blocks.air, 0, 3);
		world.setBlock(x + 6, y + -4, z + 13, Blocks.air, 0, 3);
		world.setBlock(x + 7, y + -4, z + 13, Blocks.air, 0, 3);
		world.setBlock(x + 8, y + -4, z + 13, Blocks.air, 0, 3);
		world.setBlock(x + 9, y + -4, z + 13, Blocks.air, 0, 3);
		world.setBlock(x + 10, y + -4, z + 13, Blocks.air, 0, 3);
		world.setBlock(x + 11, y + -4, z + 13, Blocks.air, 0, 3);
		world.setBlock(x + 12, y + -4, z + 13, Blocks.cobblestone, 0, 3);
		world.setBlock(x + 13, y + -4, z + 13, Blocks.dirt, 0, 3);
		world.setBlock(x + 14, y + -4, z + 13, Blocks.dirt, 0, 3);
		world.setBlock(x + 0, y + -4, z + 14, Blocks.dirt, 0, 3);
		world.setBlock(x + 1, y + -4, z + 14, Blocks.dirt, 0, 3);
		world.setBlock(x + 2, y + -4, z + 14, Blocks.cobblestone, 0, 3);
		world.setBlock(x + 3, y + -4, z + 14, Blocks.air, 0, 3);
		world.setBlock(x + 4, y + -4, z + 14, Blocks.air, 0, 3);
		world.setBlock(x + 5, y + -4, z + 14, Blocks.air, 0, 3);
		world.setBlock(x + 6, y + -4, z + 14, Blocks.air, 0, 3);
		world.setBlock(x + 7, y + -4, z + 14, Blocks.air, 0, 3);
		world.setBlock(x + 8, y + -4, z + 14, Blocks.air, 0, 3);
		world.setBlock(x + 9, y + -4, z + 14, Blocks.air, 0, 3);
		world.setBlock(x + 10, y + -4, z + 14, Blocks.air, 0, 3);
		world.setBlock(x + 11, y + -4, z + 14, Blocks.air, 0, 3);
		world.setBlock(x + 12, y + -4, z + 14, Blocks.cobblestone, 0, 3);
		world.setBlock(x + 13, y + -4, z + 14, Blocks.dirt, 0, 3);
		world.setBlock(x + 14, y + -4, z + 14, Blocks.dirt, 0, 3);
		world.setBlock(x + 0, y + -4, z + 15, Blocks.dirt, 0, 3);
		world.setBlock(x + 1, y + -4, z + 15, Blocks.dirt, 0, 3);
		world.setBlock(x + 2, y + -4, z + 15, Blocks.cobblestone, 0, 3);
		world.setBlock(x + 3, y + -4, z + 15, Blocks.air, 0, 3);
		world.setBlock(x + 4, y + -4, z + 15, Blocks.air, 0, 3);
		world.setBlock(x + 5, y + -4, z + 15, Blocks.iron_bars, 0, 3);
		world.setBlock(x + 6, y + -4, z + 15, Blocks.air, 0, 3);
		world.setBlock(x + 7, y + -4, z + 15, Blocks.air, 0, 3);
