//Schematic to java Structure by jajo_11 | inspired by "MITHION'S .SCHEMATIC TO JAVA CONVERTINGTOOL"

package net.evildead.mod.worldgen.structure;

import java.util.Random;

import net.minecraft.block.Block;
import net.minecraft.block.material.Material;
import net.minecraft.init.Blocks;
import net.minecraft.world.World;
import net.minecraft.world.gen.feature.WorldGenerator;

public class EvilCabin extends WorldGenerator
{
	public EvilCabin()
	{
		System.out.println("EVIL CABIN CREATED!");
		
	}
	
	
	protected Block[] GetValidSpawnBlocks()
	{
		return new Block[]
		{
			Blocks.grass,
			Blocks.stone,
			Blocks.dirt,
			Blocks.cobblestone,
			Blocks.planks,
			Blocks.sapling,
		};
	}

	public boolean LocationIsValidSpawn(World world, int x, int y, int z)
	{
		int distanceToAir = 0;
		Block checkBlock = world.getBlock(x, y, z);

		while (checkBlock != Blocks.air)
		{
			distanceToAir++;
			checkBlock = world.getBlock(x, y + distanceToAir, z);
		}

		if (distanceToAir > 1)
		{
			return false;
		}

		y += distanceToAir - 1;

		Block block = world.getBlock(x, y, z);
		Block blockAbove = world.getBlock(x, y + 1, z);
		Block blockBelow = world.getBlock(x, y - 1, z);

		for (Block i : GetValidSpawnBlocks())
		{
			if (blockAbove != Blocks.air)
			{
				return false;
			}
			if (block == i)
			{
				return true;
			}
			else if (block == Blocks.snow_layer && blockBelow == i)
			{
				return true;
			}
			else if (block.getMaterial() == Material.plants && blockBelow == i)
			{
				return true;
			}
		}
		return false;
	}

	public boolean generate(World world, Random rand, int x, int y, int z)
	{
		System.out.println("CABIN GEN!");
		int i = 0;//rand.nextInt(1);

		if(i == 0)
		{
		    generate_r0(world, rand, x, y, z);
		}

       return true;

	}

	public boolean generate_r0(World world, Random rand, int x, int y, int z)
	{
		System.out.println("CHECKING VALID!");
		if(!LocationIsValidSpawn(world, x, y, z) || !LocationIsValidSpawn(world, x + 10, y, z) || !LocationIsValidSpawn(world, x + 10, y, z + 18) || !LocationIsValidSpawn(world, x, y, z + 18))
		{
			return false;
		}

		System.out.println("SETTING CABIN BLOCKS!");
		world.setBlock(x + 0, y + -4, z + 0, Blocks.dirt, 0, 3);
		world.setBlock(x + 1, y + -4, z + 0, Blocks.dirt, 0, 3);
		world.setBlock(x + 2, y + -4, z + 0, Blocks.dirt, 0, 3);
		world.setBlock(x + 3, y + -4, z + 0, Blocks.dirt, 0, 3);
		world.setBlock(x + 4, y + -4, z + 0, Blocks.dirt, 0, 3);
		world.setBlock(x + 5, y + -4, z + 0, Blocks.dirt, 0, 3);
		world.setBlock(x + 6, y + -4, z + 0, Blocks.dirt, 0, 3);
		world.setBlock(x + 7, y + -4, z + 0, Blocks.dirt, 0, 3);
		world.setBlock(x + 8, y + -4, z + 0, Blocks.dirt, 0, 3);
		world.setBlock(x + 9, y + -4, z + 0, Blocks.dirt, 0, 3);
		world.setBlock(x + 10, y + -4, z + 0, Blocks.dirt, 0, 3);
		world.setBlock(x + 0, y + -4, z + 1, Blocks.dirt, 0, 3);
		world.setBlock(x + 1, y + -4, z + 1, Blocks.dirt, 0, 3);
		world.setBlock(x + 2, y + -4, z + 1, Blocks.dirt, 0, 3);
		world.setBlock(x + 3, y + -4, z + 1, Blocks.dirt, 0, 3);
		world.setBlock(x + 4, y + -4, z + 1, Blocks.dirt, 0, 3);
		world.setBlock(x + 5, y + -4, z + 1, Blocks.dirt, 0, 3);
		world.setBlock(x + 6, y + -4, z + 1, Blocks.dirt, 0, 3);
		world.setBlock(x + 7, y + -4, z + 1, Blocks.dirt, 0, 3);
		world.setBlock(x + 8, y + -4, z + 1, Blocks.dirt, 0, 3);
		world.setBlock(x + 9, y + -4, z + 1, Blocks.dirt, 0, 3);
		world.setBlock(x + 10, y + -4, z + 1, Blocks.dirt, 0, 3);
		world.setBlock(x + 0, y + -4, z + 2, Blocks.dirt, 0, 3);
		world.setBlock(x + 1, y + -4, z + 2, Blocks.dirt, 0, 3);
		world.setBlock(x + 2, y + -4, z + 2, Blocks.dirt, 0, 3);
		world.setBlock(x + 3, y + -4, z + 2, Blocks.dirt, 0, 3);
		world.setBlock(x + 4, y + -4, z + 2, Blocks.dirt, 0, 3);
		world.setBlock(x + 5, y + -4, z + 2, Blocks.dirt, 0, 3);
		world.setBlock(x + 6, y + -4, z + 2, Blocks.dirt, 0, 3);
		world.setBlock(x + 7, y + -4, z + 2, Blocks.dirt, 0, 3);
		world.setBlock(x + 8, y + -4, z + 2, Blocks.dirt, 0, 3);
		world.setBlock(x + 9, y + -4, z + 2, Blocks.dirt, 0, 3);
		world.setBlock(x + 10, y + -4, z + 2, Blocks.dirt, 0, 3);
		world.setBlock(x + 0, y + -4, z + 3, Blocks.dirt, 0, 3);
		world.setBlock(x + 1, y + -4, z + 3, Blocks.dirt, 0, 3);
		world.setBlock(x + 2, y + -4, z + 3, Blocks.dirt, 0, 3);
		world.setBlock(x + 3, y + -4, z + 3, Blocks.dirt, 0, 3);
		world.setBlock(x + 4, y + -4, z + 3, Blocks.dirt, 0, 3);
		world.setBlock(x + 5, y + -4, z + 3, Blocks.dirt, 0, 3);
		world.setBlock(x + 6, y + -4, z + 3, Blocks.dirt, 0, 3);
		world.setBlock(x + 7, y + -4, z + 3, Blocks.dirt, 0, 3);
		world.setBlock(x + 8, y + -4, z + 3, Blocks.dirt, 0, 3);
		world.setBlock(x + 9, y + -4, z + 3, Blocks.dirt, 0, 3);
		world.setBlock(x + 10, y + -4, z + 3, Blocks.dirt, 0, 3);
		world.setBlock(x + 0, y + -4, z + 4, Blocks.dirt, 0, 3);
		world.setBlock(x + 1, y + -4, z + 4, Blocks.dirt, 0, 3);
		world.setBlock(x + 2, y + -4, z + 4, Blocks.dirt, 0, 3);
		world.setBlock(x + 3, y + -4, z + 4, Blocks.dirt, 0, 3);
		world.setBlock(x + 4, y + -4, z + 4, Blocks.dirt, 0, 3);
		world.setBlock(x + 5, y + -4, z + 4, Blocks.dirt, 0, 3);
		world.setBlock(x + 6, y + -4, z + 4, Blocks.dirt, 0, 3);
		world.setBlock(x + 7, y + -4, z + 4, Blocks.dirt, 0, 3);
		world.setBlock(x + 8, y + -4, z + 4, Blocks.dirt, 0, 3);
		world.setBlock(x + 9, y + -4, z + 4, Blocks.dirt, 0, 3);
		world.setBlock(x + 10, y + -4, z + 4, Blocks.dirt, 0, 3);
		world.setBlock(x + 0, y + -4, z + 5, Blocks.air, 0, 3);
		world.setBlock(x + 1, y + -4, z + 5, Blocks.air, 0, 3);
		world.setBlock(x + 2, y + -4, z + 5, Blocks.cobblestone, 0, 3);
		world.setBlock(x + 3, y + -4, z + 5, Blocks.cobblestone, 0, 3);
		world.setBlock(x + 4, y + -4, z + 5, Blocks.cobblestone, 0, 3);
		world.setBlock(x + 5, y + -4, z + 5, Blocks.cobblestone, 0, 3);
		world.setBlock(x + 6, y + -4, z + 5, Blocks.cobblestone, 0, 3);
		world.setBlock(x + 7, y + -4, z + 5, Blocks.cobblestone, 0, 3);
		world.setBlock(x + 8, y + -4, z + 5, Blocks.cobblestone, 0, 3);
		world.setBlock(x + 9, y + -4, z + 5, Blocks.dirt, 0, 3);
		world.setBlock(x + 10, y + -4, z + 5, Blocks.dirt, 0, 3);
		world.setBlock(x + 0, y + -4, z + 6, Blocks.air, 0, 3);
		world.setBlock(x + 1, y + -4, z + 6, Blocks.air, 0, 3);
		world.setBlock(x + 2, y + -4, z + 6, Blocks.air, 0, 3);
		world.setBlock(x + 3, y + -4, z + 6, Blocks.air, 0, 3);
		world.setBlock(x + 4, y + -4, z + 6, Blocks.air, 0, 3);
		world.setBlock(x + 5, y + -4, z + 6, Blocks.air, 0, 3);
		world.setBlock(x + 6, y + -4, z + 6, Blocks.air, 0, 3);
		world.setBlock(x + 7, y + -4, z + 6, Blocks.air, 0, 3);
		world.setBlock(x + 8, y + -4, z + 6, Blocks.air, 0, 3);
		world.setBlock(x + 9, y + -4, z + 6, Blocks.cobblestone, 0, 3);
		world.setBlock(x + 10, y + -4, z + 6, Blocks.dirt, 0, 3);
		world.setBlock(x + 0, y + -4, z + 7, Blocks.air, 0, 3);
		world.setBlock(x + 1, y + -4, z + 7, Blocks.air, 0, 3);
		world.setBlock(x + 2, y + -4, z + 7, Blocks.air, 0, 3);
		world.setBlock(x + 3, y + -4, z + 7, Blocks.air, 0, 3);
		world.setBlock(x + 4, y + -4, z + 7, Blocks.air, 0, 3);
		world.setBlock(x + 5, y + -4, z + 7, Blocks.air, 0, 3);
		world.setBlock(x + 6, y + -4, z + 7, Blocks.air, 0, 3);
		world.setBlock(x + 7, y + -4, z + 7, Blocks.air, 0, 3);
		world.setBlock(x + 8, y + -4, z + 7, Blocks.air, 0, 3);
		world.setBlock(x + 9, y + -4, z + 7, Blocks.cobblestone, 0, 3);
		world.setBlock(x + 10, y + -4, z + 7, Blocks.dirt, 0, 3);
		world.setBlock(x + 0, y + -4, z + 8, Blocks.air, 0, 3);
		world.setBlock(x + 1, y + -4, z + 8, Blocks.air, 0, 3);
		world.setBlock(x + 2, y + -4, z + 8, Blocks.air, 0, 3);
		world.setBlock(x + 3, y + -4, z + 8, Blocks.air, 0, 3);
		world.setBlock(x + 4, y + -4, z + 8, Blocks.air, 0, 3);
		world.setBlock(x + 5, y + -4, z + 8, Blocks.air, 0, 3);
		world.setBlock(x + 6, y + -4, z + 8, Blocks.air, 0, 3);
		world.setBlock(x + 7, y + -4, z + 8, Blocks.air, 0, 3);
		world.setBlock(x + 8, y + -4, z + 8, Blocks.oak_stairs, 6, 3);
		world.setBlock(x + 9, y + -4, z + 8, Blocks.cobblestone, 0, 3);
		world.setBlock(x + 10, y + -4, z + 8, Blocks.dirt, 0, 3);
		world.setBlock(x + 0, y + -4, z + 9, Blocks.air, 0, 3);
		world.setBlock(x + 1, y + -4, z + 9, Blocks.air, 0, 3);
		world.setBlock(x + 2, y + -4, z + 9, Blocks.air, 0, 3);
		world.setBlock(x + 3, y + -4, z + 9, Blocks.air, 0, 3);
		world.setBlock(x + 4, y + -4, z + 9, Blocks.air, 0, 3);
		world.setBlock(x + 5, y + -4, z + 9, Blocks.air, 0, 3);
		world.setBlock(x + 6, y + -4, z + 9, Blocks.air, 0, 3);
		world.setBlock(x + 7, y + -4, z + 9, Blocks.air, 0, 3);
		world.setBlock(x + 8, y + -4, z + 9, Blocks.oak_stairs, 3, 3);
		world.setBlock(x + 9, y + -4, z + 9, Blocks.cobblestone, 0, 3);
		world.setBlock(x + 10, y + -4, z + 9, Blocks.dirt, 0, 3);
		world.setBlock(x + 0, y + -4, z + 10, Blocks.dirt, 0, 3);
		world.setBlock(x + 1, y + -4, z + 10, Blocks.air, 0, 3);
		world.setBlock(x + 2, y + -4, z + 10, Blocks.air, 0, 3);
		world.setBlock(x + 3, y + -4, z + 10, Blocks.air, 0, 3);
		world.setBlock(x + 4, y + -4, z + 10, Blocks.air, 0, 3);
		world.setBlock(x + 5, y + -4, z + 10, Blocks.air, 0, 3);
		world.setBlock(x + 6, y + -4, z + 10, Blocks.air, 0, 3);
		world.setBlock(x + 7, y + -4, z + 10, Blocks.air, 0, 3);
		world.setBlock(x + 8, y + -4, z + 10, Blocks.air, 0, 3);
		world.setBlock(x + 9, y + -4, z + 10, Blocks.cobblestone, 0, 3);
		world.setBlock(x + 10, y + -4, z + 10, Blocks.dirt, 0, 3);
		world.setBlock(x + 0, y + -4, z + 11, Blocks.dirt, 0, 3);
		world.setBlock(x + 1, y + -4, z + 11, Blocks.air, 0, 3);
		world.setBlock(x + 2, y + -4, z + 11, Blocks.air, 0, 3);
		world.setBlock(x + 3, y + -4, z + 11, Blocks.air, 0, 3);
		world.setBlock(x + 4, y + -4, z + 11, Blocks.air, 0, 3);
		world.setBlock(x + 5, y + -4, z + 11, Blocks.air, 0, 3);
		world.setBlock(x + 6, y + -4, z + 11, Blocks.air, 0, 3);
		world.setBlock(x + 7, y + -4, z + 11, Blocks.air, 0, 3);
		world.setBlock(x + 8, y + -4, z + 11, Blocks.air, 0, 3);
		world.setBlock(x + 9, y + -4, z + 11, Blocks.cobblestone, 0, 3);
		world.setBlock(x + 10, y + -4, z + 11, Blocks.dirt, 0, 3);
		world.setBlock(x + 0, y + -4, z + 12, Blocks.dirt, 0, 3);
		world.setBlock(x + 1, y + -4, z + 12, Blocks.air, 0, 3);
		world.setBlock(x + 2, y + -4, z + 12, Blocks.air, 0, 3);
		world.setBlock(x + 3, y + -4, z + 12, Blocks.air, 0, 3);
		world.setBlock(x + 4, y + -4, z + 12, Blocks.air, 0, 3);
		world.setBlock(x + 5, y + -4, z + 12, Blocks.air, 0, 3);
		world.setBlock(x + 6, y + -4, z + 12, Blocks.air, 0, 3);
		world.setBlock(x + 7, y + -4, z + 12, Blocks.air, 0, 3);
		world.setBlock(x + 8, y + -4, z + 12, Blocks.air, 0, 3);
		world.setBlock(x + 9, y + -4, z + 12, Blocks.cobblestone, 0, 3);
		world.setBlock(x + 10, y + -4, z + 12, Blocks.dirt, 0, 3);
		world.setBlock(x + 0, y + -4, z + 13, Blocks.dirt, 0, 3);
		world.setBlock(x + 1, y + -4, z + 13, Blocks.air, 0, 3);
		world.setBlock(x + 2, y + -4, z + 13, Blocks.air, 0, 3);
		world.setBlock(x + 3, y + -4, z + 13, Blocks.air, 0, 3);
		world.setBlock(x + 4, y + -4, z + 13, Blocks.air, 0, 3);
		world.setBlock(x + 5, y + -4, z + 13, Blocks.air, 0, 3);
		world.setBlock(x + 6, y + -4, z + 13, Blocks.air, 0, 3);
		world.setBlock(x + 7, y + -4, z + 13, Blocks.air, 0, 3);
		world.setBlock(x + 8, y + -4, z + 13, Blocks.air, 0, 3);
		world.setBlock(x + 9, y + -4, z + 13, Blocks.cobblestone, 0, 3);
		world.setBlock(x + 10, y + -4, z + 13, Blocks.dirt, 0, 3);
		world.setBlock(x + 0, y + -4, z + 14, Blocks.dirt, 0, 3);
		world.setBlock(x + 1, y + -4, z + 14, Blocks.air, 0, 3);
		world.setBlock(x + 2, y + -4, z + 14, Blocks.air, 0, 3);
		world.setBlock(x + 3, y + -4, z + 14, Blocks.air, 0, 3);
		world.setBlock(x + 4, y + -4, z + 14, Blocks.air, 0, 3);
		world.setBlock(x + 5, y + -4, z + 14, Blocks.air, 0, 3);
		world.setBlock(x + 6, y + -4, z + 14, Blocks.air, 0, 3);
		world.setBlock(x + 7, y + -4, z + 14, Blocks.air, 0, 3);
		world.setBlock(x + 8, y + -4, z + 14, Blocks.air, 0, 3);
		world.setBlock(x + 9, y + -4, z + 14, Blocks.cobblestone, 0, 3);
		world.setBlock(x + 10, y + -4, z + 14, Blocks.dirt, 0, 3);
		world.setBlock(x + 0, y + -4, z + 15, Blocks.dirt, 0, 3);
		world.setBlock(x + 1, y + -4, z + 15, Blocks.air, 0, 3);
		world.setBlock(x + 2, y + -4, z + 15, Blocks.air, 0, 3);
		world.setBlock(x + 3, y + -4, z + 15, Blocks.air, 0, 3);
		world.setBlock(x + 4, y + -4, z + 15, Blocks.air, 0, 3);
		world.setBlock(x + 5, y + -4, z + 15, Blocks.air, 0, 3);
		world.setBlock(x + 6, y + -4, z + 15, Blocks.air, 0, 3);
		world.setBlock(x + 7, y + -4, z + 15, Blocks.air, 0, 3);
		world.setBlock(x + 8, y + -4, z + 15, Blocks.air, 0, 3);
		world.setBlock(x + 9, y + -4, z + 15, Blocks.cobblestone, 0, 3);
		world.setBlock(x + 10, y + -4, z + 15, Blocks.dirt, 0, 3);
		world.setBlock(x + 0, y + -4, z + 16, Blocks.dirt, 0, 3);
		world.setBlock(x + 1, y + -4, z + 16, Blocks.air, 0, 3);
		world.setBlock(x + 2, y + -4, z + 16, Blocks.air, 0, 3);
		world.setBlock(x + 3, y + -4, z + 16, Blocks.air, 0, 3);
		world.setBlock(x + 4, y + -4, z + 16, Blocks.air, 0, 3);
		world.setBlock(x + 5, y + -4, z + 16, Blocks.air, 0, 3);
		world.setBlock(x + 6, y + -4, z + 16, Blocks.air, 0, 3);
		world.setBlock(x + 7, y + -4, z + 16, Blocks.air, 0, 3);
		world.setBlock(x + 8, y + -4, z + 16, Blocks.air, 0, 3);
		world.setBlock(x + 9, y + -4, z + 16, Blocks.cobblestone, 0, 3);
		world.setBlock(x + 10, y + -4, z + 16, Blocks.dirt, 0, 3);
		world.setBlock(x + 0, y + -4, z + 17, Blocks.dirt, 0, 3);
		world.setBlock(x + 1, y + -4, z + 17, Blocks.air, 0, 3);
		world.setBlock(x + 2, y + -4, z + 17, Blocks.air, 0, 3);
		world.setBlock(x + 3, y + -4, z + 17, Blocks.air, 0, 3);
		world.setBlock(x + 4, y + -4, z + 17, Blocks.air, 0, 3);
		world.setBlock(x + 5, y + -4, z + 17, Blocks.air, 0, 3);
		world.setBlock(x + 6, y + -4, z + 17, Blocks.air, 0, 3);
		world.setBlock(x + 7, y + -4, z + 17, Blocks.air, 0, 3);
		world.setBlock(x + 8, y + -4, z + 17, Blocks.air, 0, 3);
		world.setBlock(x + 9, y + -4, z + 17, Blocks.cobblestone, 0, 3);
		world.setBlock(x + 10, y + -4, z + 17, Blocks.dirt, 0, 3);
		world.setBlock(x + 0, y + -4, z + 18, Blocks.stone, 0, 3);
		world.setBlock(x + 1, y + -4, z + 18, Blocks.stone, 0, 3);
		world.setBlock(x + 2, y + -4, z + 18, Blocks.stone, 0, 3);
		world.setBlock(x + 3, y + -4, z + 18, Blocks.stone, 0, 3);
		world.setBlock(x + 4, y + -4, z + 18, Blocks.stone, 0, 3);
		world.setBlock(x + 5, y + -4, z + 18, Blocks.stone, 0, 3);
		world.setBlock(x + 6, y + -4, z + 18, Blocks.stone, 0, 3);
		world.setBlock(x + 7, y + -4, z + 18, Blocks.stone, 0, 3);
		world.setBlock(x + 8, y + -4, z + 18, Blocks.stone, 0, 3);
		world.setBlock(x + 9, y + -4, z + 18, Blocks.stone, 0, 3);
		world.setBlock(x + 10, y + -4, z + 18, Blocks.stone, 0, 3);
		world.setBlock(x + 0, y + -3, z + 0, Blocks.dirt, 0, 3);
		world.setBlock(x + 1, y + -3, z + 0, Blocks.dirt, 0, 3);
		world.setBlock(x + 2, y + -3, z + 0, Blocks.dirt, 0, 3);
		world.setBlock(x + 3, y + -3, z + 0, Blocks.dirt, 0, 3);
		world.setBlock(x + 4, y + -3, z + 0, Blocks.dirt, 0, 3);
		world.setBlock(x + 5, y + -3, z + 0, Blocks.dirt, 0, 3);
		world.setBlock(x + 6, y + -3, z + 0, Blocks.dirt, 0, 3);
		world.setBlock(x + 7, y + -3, z + 0, Blocks.dirt, 0, 3);
		world.setBlock(x + 8, y + -3, z + 0, Blocks.dirt, 0, 3);
		world.setBlock(x + 9, y + -3, z + 0, Blocks.dirt, 0, 3);
		world.setBlock(x + 10, y + -3, z + 0, Blocks.dirt, 0, 3);
		world.setBlock(x + 0, y + -3, z + 1, Blocks.dirt, 0, 3);
		world.setBlock(x + 1, y + -3, z + 1, Blocks.dirt, 0, 3);
		world.setBlock(x + 2, y + -3, z + 1, Blocks.dirt, 0, 3);
		world.setBlock(x + 3, y + -3, z + 1, Blocks.dirt, 0, 3);
		world.setBlock(x + 4, y + -3, z + 1, Blocks.dirt, 0, 3);
		world.setBlock(x + 5, y + -3, z + 1, Blocks.dirt, 0, 3);
		world.setBlock(x + 6, y + -3, z + 1, Blocks.dirt, 0, 3);
		world.setBlock(x + 7, y + -3, z + 1, Blocks.dirt, 0, 3);
		world.setBlock(x + 8, y + -3, z + 1, Blocks.dirt, 0, 3);
		world.setBlock(x + 9, y + -3, z + 1, Blocks.dirt, 0, 3);
		world.setBlock(x + 10, y + -3, z + 1, Blocks.dirt, 0, 3);
		world.setBlock(x + 0, y + -3, z + 2, Blocks.dirt, 0, 3);
		world.setBlock(x + 1, y + -3, z + 2, Blocks.dirt, 0, 3);
		world.setBlock(x + 2, y + -3, z + 2, Blocks.dirt, 0, 3);
		world.setBlock(x + 3, y + -3, z + 2, Blocks.dirt, 0, 3);
		world.setBlock(x + 4, y + -3, z + 2, Blocks.dirt, 0, 3);
		world.setBlock(x + 5, y + -3, z + 2, Blocks.dirt, 0, 3);
		world.setBlock(x + 6, y + -3, z + 2, Blocks.dirt, 0, 3);
		world.setBlock(x + 7, y + -3, z + 2, Blocks.dirt, 0, 3);
		world.setBlock(x + 8, y + -3, z + 2, Blocks.dirt, 0, 3);
		world.setBlock(x + 9, y + -3, z + 2, Blocks.dirt, 0, 3);
		world.setBlock(x + 10, y + -3, z + 2, Blocks.dirt, 0, 3);
		world.setBlock(x + 0, y + -3, z + 3, Blocks.dirt, 0, 3);
		world.setBlock(x + 1, y + -3, z + 3, Blocks.dirt, 0, 3);
		world.setBlock(x + 2, y + -3, z + 3, Blocks.dirt, 0, 3);
		world.setBlock(x + 3, y + -3, z + 3, Blocks.dirt, 0, 3);
		world.setBlock(x + 4, y + -3, z + 3, Blocks.dirt, 0, 3);
		world.setBlock(x + 5, y + -3, z + 3, Blocks.dirt, 0, 3);
		world.setBlock(x + 6, y + -3, z + 3, Blocks.dirt, 0, 3);
		world.setBlock(x + 7, y + -3, z + 3, Blocks.dirt, 0, 3);
		world.setBlock(x + 8, y + -3, z + 3, Blocks.dirt, 0, 3);
		world.setBlock(x + 9, y + -3, z + 3, Blocks.dirt, 0, 3);
		world.setBlock(x + 10, y + -3, z + 3, Blocks.dirt, 0, 3);
		world.setBlock(x + 0, y + -3, z + 4, Blocks.dirt, 0, 3);
		world.setBlock(x + 1, y + -3, z + 4, Blocks.dirt, 0, 3);
		world.setBlock(x + 2, y + -3, z + 4, Blocks.dirt, 0, 3);
		world.setBlock(x + 3, y + -3, z + 4, Blocks.dirt, 0, 3);
		world.setBlock(x + 4, y + -3, z + 4, Blocks.dirt, 0, 3);
		world.setBlock(x + 5, y + -3, z + 4, Blocks.dirt, 0, 3);
		world.setBlock(x + 6, y + -3, z + 4, Blocks.dirt, 0, 3);
		world.setBlock(x + 7, y + -3, z + 4, Blocks.dirt, 0, 3);
		world.setBlock(x + 8, y + -3, z + 4, Blocks.dirt, 0, 3);
		world.setBlock(x + 9, y + -3, z + 4, Blocks.dirt, 0, 3);
		world.setBlock(x + 10, y + -3, z + 4, Blocks.dirt, 0, 3);
		world.setBlock(x + 0, y + -3, z + 5, Blocks.air, 0, 3);
		world.setBlock(x + 1, y + -3, z + 5, Blocks.air, 0, 3);
		world.setBlock(x + 2, y + -3, z + 5, Blocks.cobblestone, 0, 3);
		world.setBlock(x + 3, y + -3, z + 5, Blocks.cobblestone, 0, 3);
		world.setBlock(x + 4, y + -3, z + 5, Blocks.cobblestone, 0, 3);
		world.setBlock(x + 5, y + -3, z + 5, Blocks.cobblestone, 0, 3);
		world.setBlock(x + 6, y + -3, z + 5, Blocks.cobblestone, 0, 3);
		world.setBlock(x + 7, y + -3, z + 5, Blocks.cobblestone, 0, 3);
		world.setBlock(x + 8, y + -3, z + 5, Blocks.cobblestone, 0, 3);
		world.setBlock(x + 9, y + -3, z + 5, Blocks.dirt, 0, 3);
		world.setBlock(x + 10, y + -3, z + 5, Blocks.dirt, 0, 3);
		world.setBlock(x + 0, y + -3, z + 6, Blocks.air, 0, 3);
		world.setBlock(x + 1, y + -3, z + 6, Blocks.air, 0, 3);
		world.setBlock(x + 2, y + -3, z + 6, Blocks.air, 0, 3);
		world.setBlock(x + 3, y + -3, z + 6, Blocks.air, 0, 3);
		world.setBlock(x + 4, y + -3, z + 6, Blocks.air, 0, 3);
		world.setBlock(x + 5, y + -3, z + 6, Blocks.air, 0, 3);
		world.setBlock(x + 6, y + -3, z + 6, Blocks.air, 0, 3);
		world.setBlock(x + 7, y + -3, z + 6, Blocks.air, 0, 3);
		world.setBlock(x + 8, y + -3, z + 6, Blocks.air, 0, 3);
		world.setBlock(x + 9, y + -3, z + 6, Blocks.cobblestone, 0, 3);
		world.setBlock(x + 10, y + -3, z + 6, Blocks.dirt, 0, 3);
		world.setBlock(x + 0, y + -3, z + 7, Blocks.air, 0, 3);
		world.setBlock(x + 1, y + -3, z + 7, Blocks.air, 0, 3);
		world.setBlock(x + 2, y + -3, z + 7, Blocks.air, 0, 3);
		world.setBlock(x + 3, y + -3, z + 7, Blocks.air, 0, 3);
		world.setBlock(x + 4, y + -3, z + 7, Blocks.air, 0, 3);
		world.setBlock(x + 5, y + -3, z + 7, Blocks.air, 0, 3);
		world.setBlock(x + 6, y + -3, z + 7, Blocks.air, 0, 3);
		world.setBlock(x + 7, y + -3, z + 7, Blocks.air, 0, 3);
		world.setBlock(x + 8, y + -3, z + 7, Blocks.oak_stairs, 6, 3);
		world.setBlock(x + 9, y + -3, z + 7, Blocks.cobblestone, 0, 3);
		world.setBlock(x + 10, y + -3, z + 7, Blocks.dirt, 0, 3);
		world.setBlock(x + 0, y + -3, z + 8, Blocks.air, 0, 3);
		world.setBlock(x + 1, y + -3, z + 8, Blocks.air, 0, 3);
		world.setBlock(x + 2, y + -3, z + 8, Blocks.air, 0, 3);
		world.setBlock(x + 3, y + -3, z + 8, Blocks.air, 0, 3);
		world.setBlock(x + 4, y + -3, z + 8, Blocks.air, 0, 3);
		world.setBlock(x + 5, y + -3, z + 8, Blocks.air, 0, 3);
		world.setBlock(x + 6, y + -3, z + 8, Blocks.air, 0, 3);
		world.setBlock(x + 7, y + -3, z + 8, Blocks.air, 0, 3);
		world.setBlock(x + 8, y + -3, z + 8, Blocks.oak_stairs, 3, 3);
		world.setBlock(x + 9, y + -3, z + 8, Blocks.cobblestone, 0, 3);
		world.setBlock(x + 10, y + -3, z + 8, Blocks.dirt, 0, 3);
		world.setBlock(x + 0, y + -3, z + 9, Blocks.dirt, 0, 3);
		world.setBlock(x + 1, y + -3, z + 9, Blocks.air, 0, 3);
		world.setBlock(x + 2, y + -3, z + 9, Blocks.air, 0, 3);
		world.setBlock(x + 3, y + -3, z + 9, Blocks.air, 0, 3);
		world.setBlock(x + 4, y + -3, z + 9, Blocks.air, 0, 3);
		world.setBlock(x + 5, y + -3, z + 9, Blocks.air, 0, 3);
		world.setBlock(x + 6, y + -3, z + 9, Blocks.air, 0, 3);
		world.setBlock(x + 7, y + -3, z + 9, Blocks.air, 0, 3);
		world.setBlock(x + 8, y + -3, z + 9, Blocks.air, 0, 3);
		world.setBlock(x + 9, y + -3, z + 9, Blocks.cobblestone, 0, 3);
		world.setBlock(x + 10, y + -3, z + 9, Blocks.dirt, 0, 3);
		world.setBlock(x + 0, y + -3, z + 10, Blocks.dirt, 0, 3);
		world.setBlock(x + 1, y + -3, z + 10, Blocks.air, 0, 3);
		world.setBlock(x + 2, y + -3, z + 10, Blocks.air, 0, 3);
		world.setBlock(x + 3, y + -3, z + 10, Blocks.air, 0, 3);
		world.setBlock(x + 4, y + -3, z + 10, Blocks.air, 0, 3);
		world.setBlock(x + 5, y + -3, z + 10, Blocks.air, 0, 3);
		world.setBlock(x + 6, y + -3, z + 10, Blocks.air, 0, 3);
		world.setBlock(x + 7, y + -3, z + 10, Blocks.air, 0, 3);
		world.setBlock(x + 8, y + -3, z + 10, Blocks.air, 0, 3);
		world.setBlock(x + 9, y + -3, z + 10, Blocks.cobblestone, 0, 3);
		world.setBlock(x + 10, y + -3, z + 10, Blocks.dirt, 0, 3);
		world.setBlock(x + 0, y + -3, z + 11, Blocks.dirt, 0, 3);
		world.setBlock(x + 1, y + -3, z + 11, Blocks.air, 0, 3);
		world.setBlock(x + 2, y + -3, z + 11, Blocks.air, 0, 3);
		world.setBlock(x + 3, y + -3, z + 11, Blocks.air, 0, 3);
		world.setBlock(x + 4, y + -3, z + 11, Blocks.air, 0, 3);
		world.setBlock(x + 5, y + -3, z + 11, Blocks.air, 0, 3);
		world.setBlock(x + 6, y + -3, z + 11, Blocks.air, 0, 3);
		world.setBlock(x + 7, y + -3, z + 11, Blocks.air, 0, 3);
		world.setBlock(x + 8, y + -3, z + 11, Blocks.air, 0, 3);
		world.setBlock(x + 9, y + -3, z + 11, Blocks.cobblestone, 0, 3);
		world.setBlock(x + 10, y + -3, z + 11, Blocks.dirt, 0, 3);
		world.setBlock(x + 0, y + -3, z + 12, Blocks.dirt, 0, 3);
		world.setBlock(x + 1, y + -3, z + 12, Blocks.air, 0, 3);
		world.setBlock(x + 2, y + -3, z + 12, Blocks.air, 0, 3);
		world.setBlock(x + 3, y + -3, z + 12, Blocks.air, 0, 3);
		world.setBlock(x + 4, y + -3, z + 12, Blocks.air, 0, 3);
		world.setBlock(x + 5, y + -3, z + 12, Blocks.air, 0, 3);
		world.setBlock(x + 6, y + -3, z + 12, Blocks.air, 0, 3);
		world.setBlock(x + 7, y + -3, z + 12, Blocks.air, 0, 3);
		world.setBlock(x + 8, y + -3, z + 12, Blocks.air, 0, 3);
		world.setBlock(x + 9, y + -3, z + 12, Blocks.cobblestone, 0, 3);
		world.setBlock(x + 10, y + -3, z + 12, Blocks.dirt, 0, 3);
		world.setBlock(x + 0, y + -3, z + 13, Blocks.dirt, 0, 3);
		world.setBlock(x + 1, y + -3, z + 13, Blocks.air, 0, 3);
		world.setBlock(x + 2, y + -3, z + 13, Blocks.air, 0, 3);
		world.setBlock(x + 3, y + -3, z + 13, Blocks.air, 0, 3);
		world.setBlock(x + 4, y + -3, z + 13, Blocks.air, 0, 3);
		world.setBlock(x + 5, y + -3, z + 13, Blocks.air, 0, 3);
		world.setBlock(x + 6, y + -3, z + 13, Blocks.air, 0, 3);
		world.setBlock(x + 7, y + -3, z + 13, Blocks.air, 0, 3);
		world.setBlock(x + 8, y + -3, z + 13, Blocks.air, 0, 3);
		world.setBlock(x + 9, y + -3, z + 13, Blocks.cobblestone, 0, 3);
		world.setBlock(x + 10, y + -3, z + 13, Blocks.dirt, 0, 3);
		world.setBlock(x + 0, y + -3, z + 14, Blocks.dirt, 0, 3);
		world.setBlock(x + 1, y + -3, z + 14, Blocks.air, 0, 3);
		world.setBlock(x + 2, y + -3, z + 14, Blocks.air, 0, 3);
		world.setBlock(x + 3, y + -3, z + 14, Blocks.air, 0, 3);
		world.setBlock(x + 4, y + -3, z + 14, Blocks.air, 0, 3);
		world.setBlock(x + 5, y + -3, z + 14, Blocks.air, 0, 3);
		world.setBlock(x + 6, y + -3, z + 14, Blocks.air, 0, 3);
		world.setBlock(x + 7, y + -3, z + 14, Blocks.air, 0, 3);
		world.setBlock(x + 8, y + -3, z + 14, Blocks.air, 0, 3);
		world.setBlock(x + 9, y + -3, z + 14, Blocks.cobblestone, 0, 3);
		world.setBlock(x + 10, y + -3, z + 14, Blocks.dirt, 0, 3);
		world.setBlock(x + 0, y + -3, z + 15, Blocks.dirt, 0, 3);
		world.setBlock(x + 1, y + -3, z + 15, Blocks.air, 0, 3);
		world.setBlock(x + 2, y + -3, z + 15, Blocks.air, 0, 3);
		world.setBlock(x + 3, y + -3, z + 15, Blocks.air, 0, 3);
		world.setBlock(x + 4, y + -3, z + 15, Blocks.air, 0, 3);
		world.setBlock(x + 5, y + -3, z + 15, Blocks.air, 0, 3);
		world.setBlock(x + 6, y + -3, z + 15, Blocks.air, 0, 3);
		world.setBlock(x + 7, y + -3, z + 15, Blocks.air, 0, 3);
		world.setBlock(x + 8, y + -3, z + 15, Blocks.air, 0, 3);
		world.setBlock(x + 9, y + -3, z + 15, Blocks.cobblestone, 0, 3);
		world.setBlock(x + 10, y + -3, z + 15, Blocks.dirt, 0, 3);
		world.setBlock(x + 0, y + -3, z + 16, Blocks.dirt, 0, 3);
		world.setBlock(x + 1, y + -3, z + 16, Blocks.air, 0, 3);
		world.setBlock(x + 2, y + -3, z + 16, Blocks.air, 0, 3);
		world.setBlock(x + 3, y + -3, z + 16, Blocks.air, 0, 3);
		world.setBlock(x + 4, y + -3, z + 16, Blocks.air, 0, 3);
		world.setBlock(x + 5, y + -3, z + 16, Blocks.air, 0, 3);
		world.setBlock(x + 6, y + -3, z + 16, Blocks.air, 0, 3);
		world.setBlock(x + 7, y + -3, z + 16, Blocks.air, 0, 3);
		world.setBlock(x + 8, y + -3, z + 16, Blocks.air, 0, 3);
		world.setBlock(x + 9, y + -3, z + 16, Blocks.cobblestone, 0, 3);
		world.setBlock(x + 10, y + -3, z + 16, Blocks.dirt, 0, 3);
		world.setBlock(x + 0, y + -3, z + 17, Blocks.dirt, 0, 3);
		world.setBlock(x + 1, y + -3, z + 17, Blocks.air, 0, 3);
		world.setBlock(x + 2, y + -3, z + 17, Blocks.air, 0, 3);
		world.setBlock(x + 3, y + -3, z + 17, Blocks.air, 0, 3);
		world.setBlock(x + 4, y + -3, z + 17, Blocks.air, 0, 3);
		world.setBlock(x + 5, y + -3, z + 17, Blocks.air, 0, 3);
		world.setBlock(x + 6, y + -3, z + 17, Blocks.air, 0, 3);
		world.setBlock(x + 7, y + -3, z + 17, Blocks.air, 0, 3);
		world.setBlock(x + 8, y + -3, z + 17, Blocks.air, 0, 3);
		world.setBlock(x + 9, y + -3, z + 17, Blocks.cobblestone, 0, 3);
		world.setBlock(x + 10, y + -3, z + 17, Blocks.dirt, 0, 3);
		world.setBlock(x + 0, y + -3, z + 18, Blocks.stone, 0, 3);
		world.setBlock(x + 1, y + -3, z + 18, Blocks.stone, 0, 3);
		world.setBlock(x + 2, y + -3, z + 18, Blocks.stone, 0, 3);
		world.setBlock(x + 3, y + -3, z + 18, Blocks.stone, 0, 3);
		world.setBlock(x + 4, y + -3, z + 18, Blocks.stone, 0, 3);
		world.setBlock(x + 5, y + -3, z + 18, Blocks.stone, 0, 3);
		world.setBlock(x + 6, y + -3, z + 18, Blocks.stone, 0, 3);
		world.setBlock(x + 7, y + -3, z + 18, Blocks.stone, 0, 3);
		world.setBlock(x + 8, y + -3, z + 18, Blocks.stone, 0, 3);
		world.setBlock(x + 9, y + -3, z + 18, Blocks.stone, 0, 3);
		world.setBlock(x + 10, y + -3, z + 18, Blocks.stone, 0, 3);
		world.setBlock(x + 0, y + -2, z + 0, Blocks.dirt, 0, 3);
		world.setBlock(x + 1, y + -2, z + 0, Blocks.dirt, 0, 3);
		world.setBlock(x + 2, y + -2, z + 0, Blocks.dirt, 0, 3);
		world.setBlock(x + 3, y + -2, z + 0, Blocks.dirt, 0, 3);
		world.setBlock(x + 4, y + -2, z + 0, Blocks.dirt, 0, 3);
		world.setBlock(x + 5, y + -2, z + 0, Blocks.dirt, 0, 3);
		world.setBlock(x + 6, y + -2, z + 0, Blocks.dirt, 0, 3);
		world.setBlock(x + 7, y + -2, z + 0, Blocks.dirt, 0, 3);
		world.setBlock(x + 8, y + -2, z + 0, Blocks.dirt, 0, 3);
		world.setBlock(x + 9, y + -2, z + 0, Blocks.dirt, 0, 3);
		world.setBlock(x + 10, y + -2, z + 0, Blocks.dirt, 0, 3);
		world.setBlock(x + 0, y + -2, z + 1, Blocks.dirt, 0, 3);
		world.setBlock(x + 1, y + -2, z + 1, Blocks.dirt, 0, 3);
		world.setBlock(x + 2, y + -2, z + 1, Blocks.dirt, 0, 3);
		world.setBlock(x + 3, y + -2, z + 1, Blocks.dirt, 0, 3);
		world.setBlock(x + 4, y + -2, z + 1, Blocks.dirt, 0, 3);
		world.setBlock(x + 5, y + -2, z + 1, Blocks.dirt, 0, 3);
		world.setBlock(x + 6, y + -2, z + 1, Blocks.dirt, 0, 3);
		world.setBlock(x + 7, y + -2, z + 1, Blocks.dirt, 0, 3);
		world.setBlock(x + 8, y + -2, z + 1, Blocks.dirt, 0, 3);
		world.setBlock(x + 9, y + -2, z + 1, Blocks.dirt, 0, 3);
		world.setBlock(x + 10, y + -2, z + 1, Blocks.dirt, 0, 3);
		world.setBlock(x + 0, y + -2, z + 2, Blocks.dirt, 0, 3);
		world.setBlock(x + 1, y + -2, z + 2, Blocks.dirt, 0, 3);
		world.setBlock(x + 2, y + -2, z + 2, Blocks.dirt, 0, 3);
		world.setBlock(x + 3, y + -2, z + 2, Blocks.dirt, 0, 3);
		world.setBlock(x + 4, y + -2, z + 2, Blocks.dirt, 0, 3);
		world.setBlock(x + 5, y + -2, z + 2, Blocks.dirt, 0, 3);
		world.setBlock(x + 6, y + -2, z + 2, Blocks.dirt, 0, 3);
		world.setBlock(x + 7, y + -2, z + 2, Blocks.dirt, 0, 3);
		world.setBlock(x + 8, y + -2, z + 2, Blocks.dirt, 0, 3);
		world.setBlock(x + 9, y + -2, z + 2, Blocks.dirt, 0, 3);
		world.setBlock(x + 10, y + -2, z + 2, Blocks.dirt, 0, 3);
		world.setBlock(x + 0, y + -2, z + 3, Blocks.dirt, 0, 3);
		world.setBlock(x + 1, y + -2, z + 3, Blocks.dirt, 0, 3);
		world.setBlock(x + 2, y + -2, z + 3, Blocks.dirt, 0, 3);
		world.setBlock(x + 3, y + -2, z + 3, Blocks.dirt, 0, 3);
		world.setBlock(x + 4, y + -2, z + 3, Blocks.dirt, 0, 3);
		world.setBlock(x + 5, y + -2, z + 3, Blocks.dirt, 0, 3);
		world.setBlock(x + 6, y + -2, z + 3, Blocks.dirt, 0, 3);
		world.setBlock(x + 7, y + -2, z + 3, Blocks.dirt, 0, 3);
		world.setBlock(x + 8, y + -2, z + 3, Blocks.dirt, 0, 3);
		world.setBlock(x + 9, y + -2, z + 3, Blocks.dirt, 0, 3);
		world.setBlock(x + 10, y + -2, z + 3, Blocks.dirt, 0, 3);
		world.setBlock(x + 0, y + -2, z + 4, Blocks.dirt, 0, 3);
		world.setBlock(x + 1, y + -2, z + 4, Blocks.dirt, 0, 3);
		world.setBlock(x + 2, y + -2, z + 4, Blocks.dirt, 0, 3);
		world.setBlock(x + 3, y + -2, z + 4, Blocks.dirt, 0, 3);
		world.setBlock(x + 4, y + -2, z + 4, Blocks.dirt, 0, 3);
		world.setBlock(x + 5, y + -2, z + 4, Blocks.dirt, 0, 3);
		world.setBlock(x + 6, y + -2, z + 4, Blocks.dirt, 0, 3);
		world.setBlock(x + 7, y + -2, z + 4, Blocks.dirt, 0, 3);
		world.setBlock(x + 8, y + -2, z + 4, Blocks.dirt, 0, 3);
		world.setBlock(x + 9, y + -2, z + 4, Blocks.dirt, 0, 3);
		world.setBlock(x + 10, y + -2, z + 4, Blocks.dirt, 0, 3);
		world.setBlock(x + 0, y + -2, z + 5, Blocks.air, 0, 3);
		world.setBlock(x + 1, y + -2, z + 5, Blocks.air, 0, 3);
		world.setBlock(x + 2, y + -2, z + 5, Blocks.cobblestone, 0, 3);
		world.setBlock(x + 3, y + -2, z + 5, Blocks.cobblestone, 0, 3);
		world.setBlock(x + 4, y + -2, z + 5, Blocks.cobblestone, 0, 3);
		world.setBlock(x + 5, y + -2, z + 5, Blocks.cobblestone, 0, 3);
		world.setBlock(x + 6, y + -2, z + 5, Blocks.cobblestone, 0, 3);
		world.setBlock(x + 7, y + -2, z + 5, Blocks.cobblestone, 0, 3);
		world.setBlock(x + 8, y + -2, z + 5, Blocks.cobblestone, 0, 3);
		world.setBlock(x + 9, y + -2, z + 5, Blocks.dirt, 0, 3);
		world.setBlock(x + 10, y + -2, z + 5, Blocks.dirt, 0, 3);
		world.setBlock(x + 0, y + -2, z + 6, Blocks.air, 0, 3);
		world.setBlock(x + 1, y + -2, z + 6, Blocks.air, 0, 3);
		world.setBlock(x + 2, y + -2, z + 6, Blocks.air, 0, 3);
		world.setBlock(x + 3, y + -2, z + 6, Blocks.air, 0, 3);
		world.setBlock(x + 4, y + -2, z + 6, Blocks.air, 0, 3);
		world.setBlock(x + 5, y + -2, z + 6, Blocks.air, 0, 3);
		world.setBlock(x + 6, y + -2, z + 6, Blocks.air, 0, 3);
		world.setBlock(x + 7, y + -2, z + 6, Blocks.air, 0, 3);
		world.setBlock(x + 8, y + -2, z + 6, Blocks.oak_stairs, 6, 3);
		world.setBlock(x + 9, y + -2, z + 6, Blocks.cobblestone, 0, 3);
		world.setBlock(x + 10, y + -2, z + 6, Blocks.dirt, 0, 3);
		world.setBlock(x + 0, y + -2, z + 7, Blocks.air, 0, 3);
		world.setBlock(x + 1, y + -2, z + 7, Blocks.air, 0, 3);
		world.setBlock(x + 2, y + -2, z + 7, Blocks.air, 0, 3);
		world.setBlock(x + 3, y + -2, z + 7, Blocks.air, 0, 3);
		world.setBlock(x + 4, y + -2, z + 7, Blocks.air, 0, 3);
		world.setBlock(x + 5, y + -2, z + 7, Blocks.air, 0, 3);
		world.setBlock(x + 6, y + -2, z + 7, Blocks.air, 0, 3);
		world.setBlock(x + 7, y + -2, z + 7, Blocks.air, 0, 3);
		world.setBlock(x + 8, y + -2, z + 7, Blocks.oak_stairs, 3, 3);
		world.setBlock(x + 9, y + -2, z + 7, Blocks.cobblestone, 0, 3);
		world.setBlock(x + 10, y + -2, z + 7, Blocks.dirt, 0, 3);
		world.setBlock(x + 0, y + -2, z + 8, Blocks.air, 0, 3);
		world.setBlock(x + 1, y + -2, z + 8, Blocks.air, 0, 3);
		world.setBlock(x + 2, y + -2, z + 8, Blocks.air, 0, 3);
		world.setBlock(x + 3, y + -2, z + 8, Blocks.air, 0, 3);
		world.setBlock(x + 4, y + -2, z + 8, Blocks.air, 0, 3);
		world.setBlock(x + 5, y + -2, z + 8, Blocks.air, 0, 3);
		world.setBlock(x + 6, y + -2, z + 8, Blocks.air, 0, 3);
		world.setBlock(x + 7, y + -2, z + 8, Blocks.air, 0, 3);
		world.setBlock(x + 8, y + -2, z + 8, Blocks.air, 0, 3);
		world.setBlock(x + 9, y + -2, z + 8, Blocks.cobblestone, 0, 3);
		world.setBlock(x + 10, y + -2, z + 8, Blocks.dirt, 0, 3);
		world.setBlock(x + 0, y + -2, z + 9, Blocks.dirt, 0, 3);
		world.setBlock(x + 1, y + -2, z + 9, Blocks.air, 0, 3);
		world.setBlock(x + 2, y + -2, z + 9, Blocks.air, 0, 3);
		world.setBlock(x + 3, y + -2, z + 9, Blocks.air, 0, 3);
		world.setBlock(x + 4, y + -2, z + 9, Blocks.air, 0, 3);
		world.setBlock(x + 5, y + -2, z + 9, Blocks.air, 0, 3);
		world.setBlock(x + 6, y + -2, z + 9, Blocks.air, 0, 3);
		world.setBlock(x + 7, y + -2, z + 9, Blocks.air, 0, 3);
		world.setBlock(x + 8, y + -2, z + 9, Blocks.air, 0, 3);
		world.setBlock(x + 9, y + -2, z + 9, Blocks.cobblestone, 0, 3);
		world.setBlock(x + 10, y + -2, z + 9, Blocks.dirt, 0, 3);
		world.setBlock(x + 0, y + -2, z + 10, Blocks.dirt, 0, 3);
		world.setBlock(x + 1, y + -2, z + 10, Blocks.air, 0, 3);
		world.setBlock(x + 2, y + -2, z + 10, Blocks.air, 0, 3);
		world.setBlock(x + 3, y + -2, z + 10, Blocks.air, 0, 3);
		world.setBlock(x + 4, y + -2, z + 10, Blocks.air, 0, 3);
		world.setBlock(x + 5, y + -2, z + 10, Blocks.air, 0, 3);
		world.setBlock(x + 6, y + -2, z + 10, Blocks.air, 0, 3);
		world.setBlock(x + 7, y + -2, z + 10, Blocks.air, 0, 3);
		world.setBlock(x + 8, y + -2, z + 10, Blocks.air, 0, 3);
		world.setBlock(x + 9, y + -2, z + 10, Blocks.cobblestone, 0, 3);
		world.setBlock(x + 10, y + -2, z + 10, Blocks.dirt, 0, 3);
		world.setBlock(x + 0, y + -2, z + 11, Blocks.dirt, 0, 3);
		world.setBlock(x + 1, y + -2, z + 11, Blocks.air, 0, 3);
		world.setBlock(x + 2, y + -2, z + 11, Blocks.air, 0, 3);
		world.setBlock(x + 3, y + -2, z + 11, Blocks.air, 0, 3);
		world.setBlock(x + 4, y + -2, z + 11, Blocks.air, 0, 3);
		world.setBlock(x + 5, y + -2, z + 11, Blocks.air, 0, 3);
		world.setBlock(x + 6, y + -2, z + 11, Blocks.air, 0, 3);
		world.setBlock(x + 7, y + -2, z + 11, Blocks.air, 0, 3);
		world.setBlock(x + 8, y + -2, z + 11, Blocks.air, 0, 3);
		world.setBlock(x + 9, y + -2, z + 11, Blocks.cobblestone, 0, 3);
		world.setBlock(x + 10, y + -2, z + 11, Blocks.dirt, 0, 3);
		world.setBlock(x + 0, y + -2, z + 12, Blocks.dirt, 0, 3);
		world.setBlock(x + 1, y + -2, z + 12, Blocks.air, 0, 3);
		world.setBlock(x + 2, y + -2, z + 12, Blocks.air, 0, 3);
		world.setBlock(x + 3, y + -2, z + 12, Blocks.air, 0, 3);
		world.setBlock(x + 4, y + -2, z + 12, Blocks.air, 0, 3);
		world.setBlock(x + 5, y + -2, z + 12, Blocks.air, 0, 3);
		world.setBlock(x + 6, y + -2, z + 12, Blocks.air, 0, 3);
		world.setBlock(x + 7, y + -2, z + 12, Blocks.air, 0, 3);
		world.setBlock(x + 8, y + -2, z + 12, Blocks.air, 0, 3);
		world.setBlock(x + 9, y + -2, z + 12, Blocks.cobblestone, 0, 3);
		world.setBlock(x + 10, y + -2, z + 12, Blocks.dirt, 0, 3);
		world.setBlock(x + 0, y + -2, z + 13, Blocks.dirt, 0, 3);
		world.setBlock(x + 1, y + -2, z + 13, Blocks.air, 0, 3);
		world.setBlock(x + 2, y + -2, z + 13, Blocks.air, 0, 3);
		world.setBlock(x + 3, y + -2, z + 13, Blocks.air, 0, 3);
		world.setBlock(x + 4, y + -2, z + 13, Blocks.air, 0, 3);
		world.setBlock(x + 5, y + -2, z + 13, Blocks.air, 0, 3);
		world.setBlock(x + 6, y + -2, z + 13, Blocks.air, 0, 3);
		world.setBlock(x + 7, y + -2, z + 13, Blocks.air, 0, 3);
		world.setBlock(x + 8, y + -2, z + 13, Blocks.air, 0, 3);
		world.setBlock(x + 9, y + -2, z + 13, Blocks.cobblestone, 0, 3);
		world.setBlock(x + 10, y + -2, z + 13, Blocks.dirt, 0, 3);
		world.setBlock(x + 0, y + -2, z + 14, Blocks.dirt, 0, 3);
		world.setBlock(x + 1, y + -2, z + 14, Blocks.air, 0, 3);
		world.setBlock(x + 2, y + -2, z + 14, Blocks.air, 0, 3);
		world.setBlock(x + 3, y + -2, z + 14, Blocks.air, 0, 3);
		world.setBlock(x + 4, y + -2, z + 14, Blocks.air, 0, 3);
		world.setBlock(x + 5, y + -2, z + 14, Blocks.air, 0, 3);
		world.setBlock(x + 6, y + -2, z + 14, Blocks.air, 0, 3);
		world.setBlock(x + 7, y + -2, z + 14, Blocks.air, 0, 3);
		world.setBlock(x + 8, y + -2, z + 14, Blocks.air, 0, 3);
		world.setBlock(x + 9, y + -2, z + 14, Blocks.cobblestone, 0, 3);
		world.setBlock(x + 10, y + -2, z + 14, Blocks.dirt, 0, 3);
		world.setBlock(x + 0, y + -2, z + 15, Blocks.dirt, 0, 3);
		world.setBlock(x + 1, y + -2, z + 15, Blocks.air, 0, 3);
		world.setBlock(x + 2, y + -2, z + 15, Blocks.air, 0, 3);
		world.setBlock(x + 3, y + -2, z + 15, Blocks.air, 0, 3);
		world.setBlock(x + 4, y + -2, z + 15, Blocks.air, 0, 3);
		world.setBlock(x + 5, y + -2, z + 15, Blocks.air, 0, 3);
		world.setBlock(x + 6, y + -2, z + 15, Blocks.air, 0, 3);
		world.setBlock(x + 7, y + -2, z + 15, Blocks.air, 0, 3);
		world.setBlock(x + 8, y + -2, z + 15, Blocks.air, 0, 3);
		world.setBlock(x + 9, y + -2, z + 15, Blocks.cobblestone, 0, 3);
		world.setBlock(x + 10, y + -2, z + 15, Blocks.dirt, 0, 3);
		world.setBlock(x + 0, y + -2, z + 16, Blocks.dirt, 0, 3);
		world.setBlock(x + 1, y + -2, z + 16, Blocks.air, 0, 3);
		world.setBlock(x + 2, y + -2, z + 16, Blocks.air, 0, 3);
		world.setBlock(x + 3, y + -2, z + 16, Blocks.air, 0, 3);
		world.setBlock(x + 4, y + -2, z + 16, Blocks.air, 0, 3);
		world.setBlock(x + 5, y + -2, z + 16, Blocks.air, 0, 3);
		world.setBlock(x + 6, y + -2, z + 16, Blocks.air, 0, 3);
		world.setBlock(x + 7, y + -2, z + 16, Blocks.air, 0, 3);
		world.setBlock(x + 8, y + -2, z + 16, Blocks.air, 0, 3);
		world.setBlock(x + 9, y + -2, z + 16, Blocks.cobblestone, 0, 3);
		world.setBlock(x + 10, y + -2, z + 16, Blocks.dirt, 0, 3);
		world.setBlock(x + 0, y + -2, z + 17, Blocks.dirt, 0, 3);
		world.setBlock(x + 1, y + -2, z + 17, Blocks.air, 0, 3);
		world.setBlock(x + 2, y + -2, z + 17, Blocks.air, 0, 3);
		world.setBlock(x + 3, y + -2, z + 17, Blocks.air, 0, 3);
		world.setBlock(x + 4, y + -2, z + 17, Blocks.air, 0, 3);
		world.setBlock(x + 5, y + -2, z + 17, Blocks.air, 0, 3);
		world.setBlock(x + 6, y + -2, z + 17, Blocks.air, 0, 3);
		world.setBlock(x + 7, y + -2, z + 17, Blocks.air, 0, 3);
		world.setBlock(x + 8, y + -2, z + 17, Blocks.air, 0, 3);
		world.setBlock(x + 9, y + -2, z + 17, Blocks.cobblestone, 0, 3);
		world.setBlock(x + 10, y + -2, z + 17, Blocks.dirt, 0, 3);
		world.setBlock(x + 0, y + -2, z + 18, Blocks.stone, 0, 3);
		world.setBlock(x + 1, y + -2, z + 18, Blocks.stone, 0, 3);
		world.setBlock(x + 2, y + -2, z + 18, Blocks.stone, 0, 3);
		world.setBlock(x + 3, y + -2, z + 18, Blocks.stone, 0, 3);
		world.setBlock(x + 4, y + -2, z + 18, Blocks.stone, 0, 3);
		world.setBlock(x + 5, y + -2, z + 18, Blocks.stone, 0, 3);
		world.setBlock(x + 6, y + -2, z + 18, Blocks.stone, 0, 3);
		world.setBlock(x + 7, y + -2, z + 18, Blocks.stone, 0, 3);
		world.setBlock(x + 8, y + -2, z + 18, Blocks.stone, 0, 3);
		world.setBlock(x + 9, y + -2, z + 18, Blocks.stone, 0, 3);
		world.setBlock(x + 10, y + -2, z + 18, Blocks.stone, 0, 3);
		world.setBlock(x + 0, y + -1, z + 0, Blocks.grass, 0, 3);
		world.setBlock(x + 1, y + -1, z + 0, Blocks.grass, 0, 3);
		world.setBlock(x + 2, y + -1, z + 0, Blocks.grass, 0, 3);
		world.setBlock(x + 3, y + -1, z + 0, Blocks.grass, 0, 3);
		world.setBlock(x + 4, y + -1, z + 0, Blocks.grass, 0, 3);
		world.setBlock(x + 5, y + -1, z + 0, Blocks.grass, 0, 3);
		world.setBlock(x + 6, y + -1, z + 0, Blocks.grass, 0, 3);
		world.setBlock(x + 7, y + -1, z + 0, Blocks.grass, 0, 3);
		world.setBlock(x + 8, y + -1, z + 0, Blocks.grass, 0, 3);
		world.setBlock(x + 9, y + -1, z + 0, Blocks.grass, 0, 3);
		world.setBlock(x + 10, y + -1, z + 0, Blocks.grass, 0, 3);
		world.setBlock(x + 0, y + -1, z + 1, Blocks.grass, 0, 3);
		world.setBlock(x + 1, y + -1, z + 1, Blocks.grass, 0, 3);
		world.setBlock(x + 2, y + -1, z + 1, Blocks.grass, 0, 3);
		world.setBlock(x + 3, y + -1, z + 1, Blocks.grass, 0, 3);
		world.setBlock(x + 4, y + -1, z + 1, Blocks.grass, 0, 3);
		world.setBlock(x + 5, y + -1, z + 1, Blocks.grass, 0, 3);
		world.setBlock(x + 6, y + -1, z + 1, Blocks.grass, 0, 3);
		world.setBlock(x + 7, y + -1, z + 1, Blocks.grass, 0, 3);
		world.setBlock(x + 8, y + -1, z + 1, Blocks.grass, 0, 3);
		world.setBlock(x + 9, y + -1, z + 1, Blocks.grass, 0, 3);
		world.setBlock(x + 10, y + -1, z + 1, Blocks.grass, 0, 3);
		world.setBlock(x + 0, y + -1, z + 2, Blocks.grass, 0, 3);
		world.setBlock(x + 1, y + -1, z + 2, Blocks.grass, 0, 3);
		world.setBlock(x + 2, y + -1, z + 2, Blocks.grass, 0, 3);
		world.setBlock(x + 3, y + -1, z + 2, Blocks.grass, 0, 3);
		world.setBlock(x + 4, y + -1, z + 2, Blocks.monster_egg, 3, 3);
		world.setBlock(x + 5, y + -1, z + 2, Blocks.monster_egg, 4, 3);
		world.setBlock(x + 6, y + -1, z + 2, Blocks.monster_egg, 4, 3);
		world.setBlock(x + 7, y + -1, z + 2, Blocks.grass, 0, 3);
		world.setBlock(x + 8, y + -1, z + 2, Blocks.grass, 0, 3);
		world.setBlock(x + 9, y + -1, z + 2, Blocks.grass, 0, 3);
		world.setBlock(x + 10, y + -1, z + 2, Blocks.grass, 0, 3);
		world.setBlock(x + 0, y + -1, z + 3, Blocks.grass, 0, 3);
		world.setBlock(x + 1, y + -1, z + 3, Blocks.dirt, 0, 3);
		world.setBlock(x + 2, y + -1, z + 3, Blocks.dirt, 0, 3);
		world.setBlock(x + 3, y + -1, z + 3, Blocks.dirt, 0, 3);
		world.setBlock(x + 4, y + -1, z + 3, Blocks.dirt, 0, 3);
		world.setBlock(x + 5, y + -1, z + 3, Blocks.dirt, 0, 3);
		world.setBlock(x + 6, y + -1, z + 3, Blocks.dirt, 0, 3);
		world.setBlock(x + 7, y + -1, z + 3, Blocks.dirt, 0, 3);
		world.setBlock(x + 8, y + -1, z + 3, Blocks.dirt, 0, 3);
		world.setBlock(x + 9, y + -1, z + 3, Blocks.dirt, 0, 3);
		world.setBlock(x + 10, y + -1, z + 3, Blocks.grass, 0, 3);
		world.setBlock(x + 0, y + -1, z + 4, Blocks.grass, 0, 3);
		world.setBlock(x + 1, y + -1, z + 4, Blocks.dirt, 0, 3);
		world.setBlock(x + 2, y + -1, z + 4, Blocks.dirt, 0, 3);
		world.setBlock(x + 3, y + -1, z + 4, Blocks.dirt, 0, 3);
		world.setBlock(x + 4, y + -1, z + 4, Blocks.dirt, 0, 3);
		world.setBlock(x + 5, y + -1, z + 4, Blocks.dirt, 0, 3);
		world.setBlock(x + 6, y + -1, z + 4, Blocks.dirt, 0, 3);
		world.setBlock(x + 7, y + -1, z + 4, Blocks.dirt, 0, 3);
		world.setBlock(x + 8, y + -1, z + 4, Blocks.dirt, 0, 3);
		world.setBlock(x + 9, y + -1, z + 4, Blocks.dirt, 0, 3);
		world.setBlock(x + 10, y + -1, z + 4, Blocks.grass, 0, 3);
		world.setBlock(x + 0, y + -1, z + 5, Blocks.dirt, 0, 3);
		world.setBlock(x + 1, y + -1, z + 5, Blocks.dirt, 0, 3);
		world.setBlock(x + 2, y + -1, z + 5, Blocks.cobblestone, 0, 3);
		world.setBlock(x + 3, y + -1, z + 5, Blocks.cobblestone, 0, 3);
		world.setBlock(x + 4, y + -1, z + 5, Blocks.cobblestone, 0, 3);
		world.setBlock(x + 5, y + -1, z + 5, Blocks.cobblestone, 0, 3);
		world.setBlock(x + 6, y + -1, z + 5, Blocks.cobblestone, 0, 3);
		world.setBlock(x + 7, y + -1, z + 5, Blocks.cobblestone, 0, 3);
		world.setBlock(x + 8, y + -1, z + 5, Blocks.cobblestone, 0, 3);
		world.setBlock(x + 9, y + -1, z + 5, Blocks.dirt, 0, 3);
		world.setBlock(x + 10, y + -1, z + 5, Blocks.dirt, 0, 3);
		world.setBlock(x + 0, y + -1, z + 6, Blocks.dirt, 0, 3);
		world.setBlock(x + 1, y + -1, z + 6, Blocks.air, 0, 3);
		world.setBlock(x + 2, y + -1, z + 6, Blocks.air, 0, 3);
		world.setBlock(x + 3, y + -1, z + 6, Blocks.air, 0, 3);
		world.setBlock(x + 4, y + -1, z + 6, Blocks.air, 0, 3);
		world.setBlock(x + 5, y + -1, z + 6, Blocks.air, 0, 3);
		world.setBlock(x + 6, y + -1, z + 6, Blocks.air, 0, 3);
		world.setBlock(x + 7, y + -1, z + 6, Blocks.air, 0, 3);
		world.setBlock(x + 8, y + -1, z + 6, Blocks.double_wooden_slab, 1, 3);
		world.setBlock(x + 9, y + -1, z + 6, Blocks.cobblestone, 0, 3);
		world.setBlock(x + 10, y + -1, z + 6, Blocks.dirt, 0, 3);
		world.setBlock(x + 0, y + -1, z + 7, Blocks.dirt, 0, 3);
		world.setBlock(x + 1, y + -1, z + 7, Blocks.air, 0, 3);
		world.setBlock(x + 2, y + -1, z + 7, Blocks.wooden_slab, 9, 3);
		world.setBlock(x + 3, y + -1, z + 7, Blocks.wooden_slab, 9, 3);
		world.setBlock(x + 4, y + -1, z + 7, Blocks.air, 0, 3);
		world.setBlock(x + 5, y + -1, z + 7, Blocks.air, 0, 3);
		world.setBlock(x + 6, y + -1, z + 7, Blocks.air, 0, 3);
		world.setBlock(x + 7, y + -1, z + 7, Blocks.air, 0, 3);
		world.setBlock(x + 8, y + -1, z + 7, Blocks.air, 0, 3);
		world.setBlock(x + 9, y + -1, z + 7, Blocks.cobblestone, 0, 3);
		world.setBlock(x + 10, y + -1, z + 7, Blocks.dirt, 0, 3);
		world.setBlock(x + 0, y + -1, z + 8, Blocks.dirt, 0, 3);
		world.setBlock(x + 1, y + -1, z + 8, Blocks.wooden_slab, 9, 3);
		world.setBlock(x + 2, y + -1, z + 8, Blocks.wooden_slab, 9, 3);
		world.setBlock(x + 3, y + -1, z + 8, Blocks.wooden_slab, 9, 3);
		world.setBlock(x + 4, y + -1, z + 8, Blocks.wooden_slab, 9, 3);
		world.setBlock(x + 5, y + -1, z + 8, Blocks.air, 0, 3);
		world.setBlock(x + 6, y + -1, z + 8, Blocks.air, 0, 3);
		world.setBlock(x + 7, y + -1, z + 8, Blocks.air, 0, 3);
		world.setBlock(x + 8, y + -1, z + 8, Blocks.air, 0, 3);
		world.setBlock(x + 9, y + -1, z + 8, Blocks.cobblestone, 0, 3);
		world.setBlock(x + 10, y + -1, z + 8, Blocks.dirt, 0, 3);
		world.setBlock(x + 0, y + -1, z + 9, Blocks.dirt, 0, 3);
		world.setBlock(x + 1, y + -1, z + 9, Blocks.wooden_slab, 9, 3);
		world.setBlock(x + 2, y + -1, z + 9, Blocks.wooden_slab, 9, 3);
		world.setBlock(x + 3, y + -1, z + 9, Blocks.wooden_slab, 9, 3);
		world.setBlock(x + 4, y + -1, z + 9, Blocks.wooden_slab, 9, 3);
		world.setBlock(x + 5, y + -1, z + 9, Blocks.air, 0, 3);
		world.setBlock(x + 6, y + -1, z + 9, Blocks.air, 0, 3);
		world.setBlock(x + 7, y + -1, z + 9, Blocks.air, 0, 3);
		world.setBlock(x + 8, y + -1, z + 9, Blocks.air, 0, 3);
		world.setBlock(x + 9, y + -1, z + 9, Blocks.cobblestone, 0, 3);
		world.setBlock(x + 10, y + -1, z + 9, Blocks.dirt, 0, 3);
		world.setBlock(x + 0, y + -1, z + 10, Blocks.dirt, 0, 3);
		world.setBlock(x + 1, y + -1, z + 10, Blocks.air, 0, 3);
		world.setBlock(x + 2, y + -1, z + 10, Blocks.wooden_slab, 9, 3);
		world.setBlock(x + 3, y + -1, z + 10, Blocks.wooden_slab, 9, 3);
		world.setBlock(x + 4, y + -1, z + 10, Blocks.air, 0, 3);
		world.setBlock(x + 5, y + -1, z + 10, Blocks.air, 0, 3);
		world.setBlock(x + 6, y + -1, z + 10, Blocks.air, 0, 3);
		world.setBlock(x + 7, y + -1, z + 10, Blocks.air, 0, 3);
		world.setBlock(x + 8, y + -1, z + 10, Blocks.air, 0, 3);
		world.setBlock(x + 9, y + -1, z + 10, Blocks.cobblestone, 0, 3);
		world.setBlock(x + 10, y + -1, z + 10, Blocks.dirt, 0, 3);
		world.setBlock(x + 0, y + -1, z + 11, Blocks.dirt, 0, 3);
		world.setBlock(x + 1, y + -1, z + 11, Blocks.air, 0, 3);
		world.setBlock(x + 2, y + -1, z + 11, Blocks.air, 0, 3);
		world.setBlock(x + 3, y + -1, z + 11, Blocks.air, 0, 3);
		world.setBlock(x + 4, y + -1, z + 11, Blocks.air, 0, 3);
		world.setBlock(x + 5, y + -1, z + 11, Blocks.air, 0, 3);
		world.setBlock(x + 6, y + -1, z + 11, Blocks.air, 0, 3);
		world.setBlock(x + 7, y + -1, z + 11, Blocks.air, 0, 3);
		world.setBlock(x + 8, y + -1, z + 11, Blocks.air, 0, 3);
		world.setBlock(x + 9, y + -1, z + 11, Blocks.cobblestone, 0, 3);
		world.setBlock(x + 10, y + -1, z + 11, Blocks.dirt, 0, 3);
		world.setBlock(x + 0, y + -1, z + 12, Blocks.dirt, 0, 3);
		world.setBlock(x + 1, y + -1, z + 12, Blocks.air, 0, 3);
		world.setBlock(x + 2, y + -1, z + 12, Blocks.air, 0, 3);
		world.setBlock(x + 3, y + -1, z + 12, Blocks.air, 0, 3);
		world.setBlock(x + 4, y + -1, z + 12, Blocks.air, 0, 3);
		world.setBlock(x + 5, y + -1, z + 12, Blocks.air, 0, 3);
		world.setBlock(x + 6, y + -1, z + 12, Blocks.air, 0, 3);
		world.setBlock(x + 7, y + -1, z + 12, Blocks.air, 0, 3);
		world.setBlock(x + 8, y + -1, z + 12, Blocks.air, 0, 3);
		world.setBlock(x + 9, y + -1, z + 12, Blocks.cobblestone, 0, 3);
		world.setBlock(x + 10, y + -1, z + 12, Blocks.dirt, 0, 3);
		world.setBlock(x + 0, y + -1, z + 13, Blocks.dirt, 0, 3);
		world.setBlock(x + 1, y + -1, z + 13, Blocks.air, 0, 3);
		world.setBlock(x + 2, y + -1, z + 13, Blocks.air, 0, 3);
		world.setBlock(x + 3, y + -1, z + 13, Blocks.air, 0, 3);
		world.setBlock(x + 4, y + -1, z + 13, Blocks.air, 0, 3);
		world.setBlock(x + 5, y + -1, z + 13, Blocks.air, 0, 3);
		world.setBlock(x + 6, y + -1, z + 13, Blocks.air, 0, 3);
		world.setBlock(x + 7, y + -1, z + 13, Blocks.air, 0, 3);
		world.setBlock(x + 8, y + -1, z + 13, Blocks.air, 0, 3);
		world.setBlock(x + 9, y + -1, z + 13, Blocks.cobblestone, 0, 3);
		world.setBlock(x + 10, y + -1, z + 13, Blocks.dirt, 0, 3);
		world.setBlock(x + 0, y + -1, z + 14, Blocks.dirt, 0, 3);
		world.setBlock(x + 1, y + -1, z + 14, Blocks.air, 0, 3);
		world.setBlock(x + 2, y + -1, z + 14, Blocks.air, 0, 3);
		world.setBlock(x + 3, y + -1, z + 14, Blocks.air, 0, 3);
		world.setBlock(x + 4, y + -1, z + 14, Blocks.air, 0, 3);
		world.setBlock(x + 5, y + -1, z + 14, Blocks.air, 0, 3);
		world.setBlock(x + 6, y + -1, z + 14, Blocks.air, 0, 3);
		world.setBlock(x + 7, y + -1, z + 14, Blocks.air, 0, 3);
		world.setBlock(x + 8, y + -1, z + 14, Blocks.air, 0, 3);
		world.setBlock(x + 9, y + -1, z + 14, Blocks.cobblestone, 0, 3);
		world.setBlock(x + 10, y + -1, z + 14, Blocks.dirt, 0, 3);
		world.setBlock(x + 0, y + -1, z + 15, Blocks.dirt, 0, 3);
		world.setBlock(x + 1, y + -1, z + 15, Blocks.air, 0, 3);
		world.setBlock(x + 2, y + -1, z + 15, Blocks.air, 0, 3);
		world.setBlock(x + 3, y + -1, z + 15, Blocks.air, 0, 3);
		world.setBlock(x + 4, y + -1, z + 15, Blocks.air, 0, 3);
		world.setBlock(x + 5, y + -1, z + 15, Blocks.air, 0, 3);
		world.setBlock(x + 6, y + -1, z + 15, Blocks.air, 0, 3);
		world.setBlock(x + 7, y + -1, z + 15, Blocks.air, 0, 3);
		world.setBlock(x + 8, y + -1, z + 15, Blocks.air, 0, 3);
		world.setBlock(x + 9, y + -1, z + 15, Blocks.cobblestone, 0, 3);
		world.setBlock(x + 10, y + -1, z + 15, Blocks.dirt, 0, 3);
		world.setBlock(x + 0, y + -1, z + 16, Blocks.dirt, 0, 3);
		world.setBlock(x + 1, y + -1, z + 16, Blocks.air, 0, 3);
		world.setBlock(x + 2, y + -1, z + 16, Blocks.air, 0, 3);
		world.setBlock(x + 3, y + -1, z + 16, Blocks.air, 0, 3);
		world.setBlock(x + 4, y + -1, z + 16, Blocks.air, 0, 3);
		world.setBlock(x + 5, y + -1, z + 16, Blocks.air, 0, 3);
		world.setBlock(x + 6, y + -1, z + 16, Blocks.air, 0, 3);
		world.setBlock(x + 7, y + -1, z + 16, Blocks.air, 0, 3);
		world.setBlock(x + 8, y + -1, z + 16, Blocks.air, 0, 3);
		world.setBlock(x + 9, y + -1, z + 16, Blocks.cobblestone, 0, 3);
		world.setBlock(x + 10, y + -1, z + 16, Blocks.dirt, 0, 3);
		world.setBlock(x + 0, y + -1, z + 17, Blocks.dirt, 0, 3);
		world.setBlock(x + 1, y + -1, z + 17, Blocks.air, 0, 3);
		world.setBlock(x + 2, y + -1, z + 17, Blocks.air, 0, 3);
		world.setBlock(x + 3, y + -1, z + 17, Blocks.air, 0, 3);
		world.setBlock(x + 4, y + -1, z + 17, Blocks.air, 0, 3);
		world.setBlock(x + 5, y + -1, z + 17, Blocks.air, 0, 3);
		world.setBlock(x + 6, y + -1, z + 17, Blocks.air, 0, 3);
		world.setBlock(x + 7, y + -1, z + 17, Blocks.air, 0, 3);
		world.setBlock(x + 8, y + -1, z + 17, Blocks.air, 0, 3);
		world.setBlock(x + 9, y + -1, z + 17, Blocks.cobblestone, 0, 3);
		world.setBlock(x + 10, y + -1, z + 17, Blocks.dirt, 0, 3);
		world.setBlock(x + 0, y + -1, z + 18, Blocks.stone, 0, 3);
		world.setBlock(x + 1, y + -1, z + 18, Blocks.stone, 0, 3);
		world.setBlock(x + 2, y + -1, z + 18, Blocks.stone, 0, 3);
		world.setBlock(x + 3, y + -1, z + 18, Blocks.stone, 0, 3);
		world.setBlock(x + 4, y + -1, z + 18, Blocks.stone, 0, 3);
		world.setBlock(x + 5, y + -1, z + 18, Blocks.stone, 0, 3);
		world.setBlock(x + 6, y + -1, z + 18, Blocks.stone, 0, 3);
		world.setBlock(x + 7, y + -1, z + 18, Blocks.stone, 0, 3);
		world.setBlock(x + 8, y + -1, z + 18, Blocks.stone, 0, 3);
		world.setBlock(x + 9, y + -1, z + 18, Blocks.stone, 0, 3);
		world.setBlock(x + 10, y + -1, z + 18, Blocks.stone, 0, 3);
		world.setBlock(x + 0, y + 0, z + 0, Blocks.air, 0, 3);
		world.setBlock(x + 1, y + 0, z + 0, Blocks.air, 0, 3);
		world.setBlock(x + 2, y + 0, z + 0, Blocks.air, 0, 3);
		world.setBlock(x + 3, y + 0, z + 0, Blocks.air, 0, 3);
		world.setBlock(x + 4, y + 0, z + 0, Blocks.air, 0, 3);
		world.setBlock(x + 5, y + 0, z + 0, Blocks.air, 0, 3);
		world.setBlock(x + 6, y + 0, z + 0, Blocks.air, 0, 3);
		world.setBlock(x + 7, y + 0, z + 0, Blocks.air, 0, 3);
		world.setBlock(x + 8, y + 0, z + 0, Blocks.air, 0, 3);
		world.setBlock(x + 9, y + 0, z + 0, Blocks.air, 0, 3);
		world.setBlock(x + 10, y + 0, z + 0, Blocks.air, 0, 3);
		world.setBlock(x + 0, y + 0, z + 1, Blocks.air, 0, 3);
		world.setBlock(x + 1, y + 0, z + 1, Blocks.air, 0, 3);
		world.setBlock(x + 2, y + 0, z + 1, Blocks.air, 0, 3);
		world.setBlock(x + 3, y + 0, z + 1, Blocks.air, 0, 3);
		world.setBlock(x + 4, y + 0, z + 1, Blocks.air, 0, 3);
		world.setBlock(x + 5, y + 0, z + 1, Blocks.air, 0, 3);
		world.setBlock(x + 6, y + 0, z + 1, Blocks.air, 0, 3);
		world.setBlock(x + 7, y + 0, z + 1, Blocks.air, 0, 3);
		world.setBlock(x + 8, y + 0, z + 1, Blocks.air, 0, 3);
		world.setBlock(x + 9, y + 0, z + 1, Blocks.yellow_flower, 0, 3);
		world.setBlock(x + 10, y + 0, z + 1, Blocks.tallgrass, 1, 3);
		world.setBlock(x + 0, y + 0, z + 2, Blocks.fence, 0, 3);
		world.setBlock(x + 1, y + 0, z + 2, Blocks.air, 0, 3);
		world.setBlock(x + 2, y + 0, z + 2, Blocks.air, 0, 3);
		world.setBlock(x + 3, y + 0, z + 2, Blocks.air, 0, 3);
		world.setBlock(x + 4, y + 0, z + 2, Blocks.fence, 0, 3);
		world.setBlock(x + 5, y + 0, z + 2, Blocks.air, 0, 3);
		world.setBlock(x + 6, y + 0, z + 2, Blocks.fence, 0, 3);
		world.setBlock(x + 7, y + 0, z + 2, Blocks.air, 0, 3);
		world.setBlock(x + 8, y + 0, z + 2, Blocks.air, 0, 3);
		world.setBlock(x + 9, y + 0, z + 2, Blocks.air, 0, 3);
		world.setBlock(x + 10, y + 0, z + 2, Blocks.fence, 0, 3);
		world.setBlock(x + 0, y + 0, z + 3, Blocks.wooden_slab, 1, 3);
		world.setBlock(x + 1, y + 0, z + 3, Blocks.wooden_slab, 1, 3);
		world.setBlock(x + 2, y + 0, z + 3, Blocks.wooden_slab, 1, 3);
		world.setBlock(x + 3, y + 0, z + 3, Blocks.wooden_slab, 1, 3);
		world.setBlock(x + 4, y + 0, z + 3, Blocks.wooden_slab, 1, 3);
		world.setBlock(x + 5, y + 0, z + 3, Blocks.wooden_slab, 1, 3);
		world.setBlock(x + 6, y + 0, z + 3, Blocks.wooden_slab, 1, 3);
		world.setBlock(x + 7, y + 0, z + 3, Blocks.wooden_slab, 1, 3);
		world.setBlock(x + 8, y + 0, z + 3, Blocks.wooden_slab, 1, 3);
		world.setBlock(x + 9, y + 0, z + 3, Blocks.wooden_slab, 1, 3);
		world.setBlock(x + 10, y + 0, z + 3, Blocks.spruce_stairs, 0, 3);
		world.setBlock(x + 0, y + 0, z + 4, Blocks.wooden_slab, 1, 3);
		world.setBlock(x + 1, y + 0, z + 4, Blocks.wooden_slab, 1, 3);
		world.setBlock(x + 2, y + 0, z + 4, Blocks.wooden_slab, 1, 3);
		world.setBlock(x + 3, y + 0, z + 4, Blocks.wooden_slab, 1, 3);
		world.setBlock(x + 4, y + 0, z + 4, Blocks.wooden_slab, 1, 3);
		world.setBlock(x + 5, y + 0, z + 4, Blocks.planks, 5, 3);
		world.setBlock(x + 6, y + 0, z + 4, Blocks.wooden_slab, 1, 3);
		world.setBlock(x + 7, y + 0, z + 4, Blocks.wooden_slab, 1, 3);
		world.setBlock(x + 8, y + 0, z + 4, Blocks.wooden_slab, 1, 3);
		world.setBlock(x + 9, y + 0, z + 4, Blocks.wooden_slab, 1, 3);
		world.setBlock(x + 10, y + 0, z + 4, Blocks.spruce_stairs, 0, 3);
		world.setBlock(x + 0, y + 0, z + 5, Blocks.planks, 1, 3);
		world.setBlock(x + 1, y + 0, z + 5, Blocks.planks, 1, 3);
		world.setBlock(x + 2, y + 0, z + 5, Blocks.planks, 1, 3);
		world.setBlock(x + 3, y + 0, z + 5, Blocks.planks, 1, 3);
		world.setBlock(x + 4, y + 0, z + 5, Blocks.planks, 1, 3);
		world.setBlock(x + 5, y + 0, z + 5, Blocks.double_wooden_slab, 5, 3);
		world.setBlock(x + 6, y + 0, z + 5, Blocks.planks, 1, 3);
		world.setBlock(x + 7, y + 0, z + 5, Blocks.planks, 1, 3);
		world.setBlock(x + 8, y + 0, z + 5, Blocks.planks, 1, 3);
		world.setBlock(x + 9, y + 0, z + 5, Blocks.planks, 1, 3);
		world.setBlock(x + 10, y + 0, z + 5, Blocks.planks, 1, 3);
		world.setBlock(x + 0, y + 0, z + 6, Blocks.planks, 1, 3);
		world.setBlock(x + 1, y + 0, z + 6, Blocks.spruce_stairs, 3, 3);
		world.setBlock(x + 2, y + 0, z + 6, Blocks.wooden_slab, 1, 3);
		world.setBlock(x + 3, y + 0, z + 6, Blocks.spruce_stairs, 3, 3);
		world.setBlock(x + 4, y + 0, z + 6, Blocks.wooden_slab, 1, 3);
		world.setBlock(x + 5, y + 0, z + 6, Blocks.spruce_stairs, 3, 3);
		world.setBlock(x + 6, y + 0, z + 6, Blocks.wooden_slab, 1, 3);
		world.setBlock(x + 7, y + 0, z + 6, Blocks.wooden_slab, 1, 3);
		world.setBlock(x + 8, y + 0, z + 6, Blocks.air, 0, 3);
		world.setBlock(x + 9, y + 0, z + 6, Blocks.spruce_stairs, 3, 3);
		world.setBlock(x + 10, y + 0, z + 6, Blocks.planks, 1, 3);
		world.setBlock(x + 0, y + 0, z + 7, Blocks.planks, 1, 3);
		world.setBlock(x + 1, y + 0, z + 7, Blocks.wooden_slab, 1, 3);
		world.setBlock(x + 2, y + 0, z + 7, Blocks.carpet, 12, 3);
		world.setBlock(x + 3, y + 0, z + 7, Blocks.carpet, 12, 3);
		world.setBlock(x + 4, y + 0, z + 7, Blocks.wooden_slab, 1, 3);
		world.setBlock(x + 5, y + 0, z + 7, Blocks.wooden_slab, 1, 3);
		world.setBlock(x + 6, y + 0, z + 7, Blocks.wooden_slab, 1, 3);
		world.setBlock(x + 7, y + 0, z + 7, Blocks.trapdoor, 3, 3);
		world.setBlock(x + 8, y + 0, z + 7, Blocks.trapdoor, 6, 3);
		world.setBlock(x + 9, y + 0, z + 7, Blocks.wooden_slab, 1, 3);
		world.setBlock(x + 10, y + 0, z + 7, Blocks.planks, 1, 3);
		world.setBlock(x + 0, y + 0, z + 8, Blocks.stone_stairs, 3, 3);
		world.setBlock(x + 1, y + 0, z + 8, Blocks.carpet, 12, 3);
		world.setBlock(x + 2, y + 0, z + 8, Blocks.carpet, 12, 3);
		world.setBlock(x + 3, y + 0, z + 8, Blocks.carpet, 12, 3);
		world.setBlock(x + 4, y + 0, z + 8, Blocks.carpet, 12, 3);
		world.setBlock(x + 5, y + 0, z + 8, Blocks.wooden_slab, 1, 3);
		world.setBlock(x + 6, y + 0, z + 8, Blocks.wooden_slab, 1, 3);
		world.setBlock(x + 7, y + 0, z + 8, Blocks.trapdoor, 3, 3);
		world.setBlock(x + 8, y + 0, z + 8, Blocks.trapdoor, 6, 3);
		world.setBlock(x + 9, y + 0, z + 8, Blocks.wooden_slab, 1, 3);
		world.setBlock(x + 10, y + 0, z + 8, Blocks.planks, 1, 3);
		world.setBlock(x + 0, y + 0, z + 9, Blocks.stone_stairs, 2, 3);
		world.setBlock(x + 1, y + 0, z + 9, Blocks.carpet, 12, 3);
		world.setBlock(x + 2, y + 0, z + 9, Blocks.carpet, 12, 3);
		world.setBlock(x + 3, y + 0, z + 9, Blocks.carpet, 12, 3);
		world.setBlock(x + 4, y + 0, z + 9, Blocks.carpet, 12, 3);
		world.setBlock(x + 5, y + 0, z + 9, Blocks.wooden_slab, 1, 3);
		world.setBlock(x + 6, y + 0, z + 9, Blocks.wooden_slab, 1, 3);
		world.setBlock(x + 7, y + 0, z + 9, Blocks.wooden_slab, 1, 3);
		world.setBlock(x + 8, y + 0, z + 9, Blocks.spruce_stairs, 2, 3);
		world.setBlock(x + 9, y + 0, z + 9, Blocks.spruce_stairs, 2, 3);
		world.setBlock(x + 10, y + 0, z + 9, Blocks.planks, 1, 3);
		world.setBlock(x + 0, y + 0, z + 10, Blocks.planks, 1, 3);
		world.setBlock(x + 1, y + 0, z + 10, Blocks.wooden_slab, 1, 3);
		world.setBlock(x + 2, y + 0, z + 10, Blocks.carpet, 12, 3);
		world.setBlock(x + 3, y + 0, z + 10, Blocks.carpet, 12, 3);
		world.setBlock(x + 4, y + 0, z + 10, Blocks.wooden_slab, 1, 3);
		world.setBlock(x + 5, y + 0, z + 10, Blocks.wooden_slab, 1, 3);
		world.setBlock(x + 6, y + 0, z + 10, Blocks.wooden_slab, 1, 3);
		world.setBlock(x + 7, y + 0, z + 10, Blocks.wooden_slab, 1, 3);
		world.setBlock(x + 8, y + 0, z + 10, Blocks.wool, 14, 3);
		world.setBlock(x + 9, y + 0, z + 10, Blocks.wool, 14, 3);
		world.setBlock(x + 10, y + 0, z + 10, Blocks.planks, 1, 3);
		world.setBlock(x + 0, y + 0, z + 11, Blocks.planks, 1, 3);
		world.setBlock(x + 1, y + 0, z + 11, Blocks.wooden_slab, 1, 3);
		world.setBlock(x + 2, y + 0, z + 11, Blocks.wooden_slab, 1, 3);
		world.setBlock(x + 3, y + 0, z + 11, Blocks.spruce_stairs, 1, 3);
		world.setBlock(x + 4, y + 0, z + 11, Blocks.wooden_slab, 1, 3);
		world.setBlock(x + 5, y + 0, z + 11, Blocks.wooden_slab, 1, 3);
		world.setBlock(x + 6, y + 0, z + 11, Blocks.wooden_slab, 1, 3);
		world.setBlock(x + 7, y + 0, z + 11, Blocks.wooden_slab, 1, 3);
		world.setBlock(x + 8, y + 0, z + 11, Blocks.wool, 14, 3);
		world.setBlock(x + 9, y + 0, z + 11, Blocks.wool, 14, 3);
		world.setBlock(x + 10, y + 0, z + 11, Blocks.planks, 1, 3);
		world.setBlock(x + 0, y + 0, z + 12, Blocks.planks, 1, 3);
		world.setBlock(x + 1, y + 0, z + 12, Blocks.trapped_chest, 2, 3);
		world.setBlock(x + 2, y + 0, z + 12, Blocks.bookshelf, 0, 3);
		world.setBlock(x + 3, y + 0, z + 12, Blocks.oak_stairs, 0, 3);
		world.setBlock(x + 4, y + 0, z + 12, Blocks.wooden_slab, 1, 3);
		world.setBlock(x + 5, y + 0, z + 12, Blocks.spruce_stairs, 2, 3);
		world.setBlock(x + 6, y + 0, z + 12, Blocks.wooden_slab, 1, 3);
		world.setBlock(x + 7, y + 0, z + 12, Blocks.spruce_stairs, 2, 3);
		world.setBlock(x + 8, y + 0, z + 12, Blocks.spruce_stairs, 3, 3);
		world.setBlock(x + 9, y + 0, z + 12, Blocks.spruce_stairs, 3, 3);
		world.setBlock(x + 10, y + 0, z + 12, Blocks.planks, 1, 3);
		world.setBlock(x + 0, y + 0, z + 13, Blocks.planks, 1, 3);
		world.setBlock(x + 1, y + 0, z + 13, Blocks.planks, 1, 3);
		world.setBlock(x + 2, y + 0, z + 13, Blocks.planks, 1, 3);
		world.setBlock(x + 3, y + 0, z + 13, Blocks.planks, 1, 3);
		world.setBlock(x + 4, y + 0, z + 13, Blocks.planks, 1, 3);
		world.setBlock(x + 5, y + 0, z + 13, Blocks.planks, 1, 3);
		world.setBlock(x + 6, y + 0, z + 13, Blocks.planks, 1, 3);
		world.setBlock(x + 7, y + 0, z + 13, Blocks.planks, 1, 3);
		world.setBlock(x + 8, y + 0, z + 13, Blocks.planks, 1, 3);
		world.setBlock(x + 9, y + 0, z + 13, Blocks.planks, 1, 3);
		world.setBlock(x + 10, y + 0, z + 13, Blocks.planks, 1, 3);
		world.setBlock(x + 0, y + 0, z + 14, Blocks.planks, 1, 3);
		world.setBlock(x + 1, y + 0, z + 14, Blocks.planks, 1, 3);
		world.setBlock(x + 2, y + 0, z + 14, Blocks.planks, 1, 3);
		world.setBlock(x + 3, y + 0, z + 14, Blocks.planks, 1, 3);
		world.setBlock(x + 4, y + 0, z + 14, Blocks.planks, 1, 3);
		world.setBlock(x + 5, y + 0, z + 14, Blocks.planks, 1, 3);
		world.setBlock(x + 6, y + 0, z + 14, Blocks.planks, 1, 3);
		world.setBlock(x + 7, y + 0, z + 14, Blocks.planks, 1, 3);
		world.setBlock(x + 8, y + 0, z + 14, Blocks.planks, 1, 3);
		world.setBlock(x + 9, y + 0, z + 14, Blocks.planks, 1, 3);
		world.setBlock(x + 10, y + 0, z + 14, Blocks.planks, 1, 3);
		world.setBlock(x + 0, y + 0, z + 15, Blocks.planks, 1, 3);
		world.setBlock(x + 1, y + 0, z + 15, Blocks.planks, 1, 3);
		world.setBlock(x + 2, y + 0, z + 15, Blocks.planks, 1, 3);
		world.setBlock(x + 3, y + 0, z + 15, Blocks.planks, 1, 3);
		world.setBlock(x + 4, y + 0, z + 15, Blocks.planks, 1, 3);
		world.setBlock(x + 5, y + 0, z + 15, Blocks.planks, 1, 3);
		world.setBlock(x + 6, y + 0, z + 15, Blocks.planks, 1, 3);
		world.setBlock(x + 7, y + 0, z + 15, Blocks.planks, 1, 3);
		world.setBlock(x + 8, y + 0, z + 15, Blocks.planks, 1, 3);
		world.setBlock(x + 9, y + 0, z + 15, Blocks.planks, 1, 3);
		world.setBlock(x + 10, y + 0, z + 15, Blocks.planks, 1, 3);
		world.setBlock(x + 0, y + 0, z + 16, Blocks.planks, 1, 3);
		world.setBlock(x + 1, y + 0, z + 16, Blocks.planks, 1, 3);
		world.setBlock(x + 2, y + 0, z + 16, Blocks.planks, 1, 3);
		world.setBlock(x + 3, y + 0, z + 16, Blocks.planks, 1, 3);
		world.setBlock(x + 4, y + 0, z + 16, Blocks.planks, 1, 3);
		world.setBlock(x + 5, y + 0, z + 16, Blocks.planks, 1, 3);
		world.setBlock(x + 6, y + 0, z + 16, Blocks.planks, 1, 3);
		world.setBlock(x + 7, y + 0, z + 16, Blocks.planks, 1, 3);
		world.setBlock(x + 8, y + 0, z + 16, Blocks.planks, 1, 3);
		world.setBlock(x + 9, y + 0, z + 16, Blocks.planks, 1, 3);
		world.setBlock(x + 10, y + 0, z + 16, Blocks.planks, 1, 3);
		world.setBlock(x + 0, y + 0, z + 17, Blocks.planks, 1, 3);
		world.setBlock(x + 1, y + 0, z + 17, Blocks.planks, 1, 3);
		world.setBlock(x + 2, y + 0, z + 17, Blocks.planks, 1, 3);
		world.setBlock(x + 3, y + 0, z + 17, Blocks.planks, 1, 3);
		world.setBlock(x + 4, y + 0, z + 17, Blocks.planks, 1, 3);
		world.setBlock(x + 5, y + 0, z + 17, Blocks.planks, 1, 3);
		world.setBlock(x + 6, y + 0, z + 17, Blocks.planks, 1, 3);
		world.setBlock(x + 7, y + 0, z + 17, Blocks.planks, 1, 3);
		world.setBlock(x + 8, y + 0, z + 17, Blocks.planks, 1, 3);
		world.setBlock(x + 9, y + 0, z + 17, Blocks.planks, 1, 3);
		world.setBlock(x + 10, y + 0, z + 17, Blocks.planks, 1, 3);
		world.setBlock(x + 0, y + 1, z + 0, Blocks.air, 0, 3);
		world.setBlock(x + 1, y + 1, z + 0, Blocks.air, 0, 3);
		world.setBlock(x + 2, y + 1, z + 0, Blocks.air, 0, 3);
		world.setBlock(x + 3, y + 1, z + 0, Blocks.air, 0, 3);
		world.setBlock(x + 4, y + 1, z + 0, Blocks.air, 0, 3);
		world.setBlock(x + 5, y + 1, z + 0, Blocks.air, 0, 3);
		world.setBlock(x + 6, y + 1, z + 0, Blocks.air, 0, 3);
		world.setBlock(x + 7, y + 1, z + 0, Blocks.air, 0, 3);
		world.setBlock(x + 8, y + 1, z + 0, Blocks.air, 0, 3);
		world.setBlock(x + 9, y + 1, z + 0, Blocks.air, 0, 3);
		world.setBlock(x + 10, y + 1, z + 0, Blocks.air, 0, 3);
		world.setBlock(x + 0, y + 1, z + 1, Blocks.air, 0, 3);
		world.setBlock(x + 1, y + 1, z + 1, Blocks.air, 0, 3);
		world.setBlock(x + 2, y + 1, z + 1, Blocks.air, 0, 3);
		world.setBlock(x + 3, y + 1, z + 1, Blocks.air, 0, 3);
		world.setBlock(x + 4, y + 1, z + 1, Blocks.air, 0, 3);
		world.setBlock(x + 5, y + 1, z + 1, Blocks.air, 0, 3);
		world.setBlock(x + 6, y + 1, z + 1, Blocks.air, 0, 3);
		world.setBlock(x + 7, y + 1, z + 1, Blocks.air, 0, 3);
		world.setBlock(x + 8, y + 1, z + 1, Blocks.air, 0, 3);
		world.setBlock(x + 9, y + 1, z + 1, Blocks.air, 0, 3);
		world.setBlock(x + 10, y + 1, z + 1, Blocks.air, 0, 3);
		world.setBlock(x + 0, y + 1, z + 2, Blocks.fence, 0, 3);
		world.setBlock(x + 1, y + 1, z + 2, Blocks.nether_brick_fence, 0, 3);
		world.setBlock(x + 2, y + 1, z + 2, Blocks.air, 0, 3);
		world.setBlock(x + 3, y + 1, z + 2, Blocks.air, 0, 3);
		world.setBlock(x + 4, y + 1, z + 2, Blocks.fence, 0, 3);
		world.setBlock(x + 5, y + 1, z + 2, Blocks.air, 0, 3);
		world.setBlock(x + 6, y + 1, z + 2, Blocks.fence, 0, 3);
		world.setBlock(x + 7, y + 1, z + 2, Blocks.air, 0, 3);
		world.setBlock(x + 8, y + 1, z + 2, Blocks.air, 0, 3);
		world.setBlock(x + 9, y + 1, z + 2, Blocks.air, 0, 3);
		world.setBlock(x + 10, y + 1, z + 2, Blocks.fence, 0, 3);
		world.setBlock(x + 0, y + 1, z + 3, Blocks.air, 0, 3);
		world.setBlock(x + 1, y + 1, z + 3, Blocks.dark_oak_stairs, 1, 3);
		world.setBlock(x + 2, y + 1, z + 3, Blocks.air, 0, 3);
		world.setBlock(x + 3, y + 1, z + 3, Blocks.air, 0, 3);
		world.setBlock(x + 4, y + 1, z + 3, Blocks.air, 0, 3);
		world.setBlock(x + 5, y + 1, z + 3, Blocks.air, 0, 3);
		world.setBlock(x + 6, y + 1, z + 3, Blocks.air, 0, 3);
		world.setBlock(x + 7, y + 1, z + 3, Blocks.air, 0, 3);
		world.setBlock(x + 8, y + 1, z + 3, Blocks.air, 0, 3);
		world.setBlock(x + 9, y + 1, z + 3, Blocks.air, 0, 3);
		world.setBlock(x + 10, y + 1, z + 3, Blocks.fence, 0, 3);
		world.setBlock(x + 0, y + 1, z + 4, Blocks.air, 0, 3);
		world.setBlock(x + 1, y + 1, z + 4, Blocks.dark_oak_stairs, 1, 3);
		world.setBlock(x + 2, y + 1, z + 4, Blocks.air, 0, 3);
		world.setBlock(x + 3, y + 1, z + 4, Blocks.air, 0, 3);
		world.setBlock(x + 4, y + 1, z + 4, Blocks.air, 0, 3);
		world.setBlock(x + 5, y + 1, z + 4, Blocks.air, 0, 3);
		world.setBlock(x + 6, y + 1, z + 4, Blocks.air, 0, 3);
		world.setBlock(x + 7, y + 1, z + 4, Blocks.air, 0, 3);
		world.setBlock(x + 8, y + 1, z + 4, Blocks.air, 0, 3);
		world.setBlock(x + 9, y + 1, z + 4, Blocks.air, 0, 3);
		world.setBlock(x + 10, y + 1, z + 4, Blocks.fence, 0, 3);
		world.setBlock(x + 0, y + 1, z + 5, Blocks.planks, 1, 3);
		world.setBlock(x + 1, y + 1, z + 5, Blocks.planks, 1, 3);
		world.setBlock(x + 2, y + 1, z + 5, Blocks.stained_glass, 15, 3);
		world.setBlock(x + 3, y + 1, z + 5, Blocks.planks, 1, 3);
		world.setBlock(x + 4, y + 1, z + 5, Blocks.planks, 1, 3);
		world.setBlock(x + 5, y + 1, z + 5, Blocks.wooden_door, 1, 3);
		world.setBlock(x + 6, y + 1, z + 5, Blocks.planks, 1, 3);
		world.setBlock(x + 7, y + 1, z + 5, Blocks.planks, 1, 3);
		world.setBlock(x + 8, y + 1, z + 5, Blocks.stained_glass, 15, 3);
		world.setBlock(x + 9, y + 1, z + 5, Blocks.planks, 1, 3);
		world.setBlock(x + 10, y + 1, z + 5, Blocks.planks, 1, 3);
		world.setBlock(x + 0, y + 1, z + 6, Blocks.planks, 1, 3);
		world.setBlock(x + 1, y + 1, z + 6, Blocks.wooden_slab, 3, 3);
		world.setBlock(x + 2, y + 1, z + 6, Blocks.air, 0, 3);
		world.setBlock(x + 3, y + 1, z + 6, Blocks.jungle_stairs, 0, 3);
		world.setBlock(x + 4, y + 1, z + 6, Blocks.air, 0, 3);
		world.setBlock(x + 5, y + 1, z + 6, Blocks.air, 0, 3);
		world.setBlock(x + 6, y + 1, z + 6, Blocks.air, 0, 3);
		world.setBlock(x + 7, y + 1, z + 6, Blocks.air, 0, 3);
		world.setBlock(x + 8, y + 1, z + 6, Blocks.air, 0, 3);
		world.setBlock(x + 9, y + 1, z + 6, Blocks.wooden_slab, 3, 3);
		world.setBlock(x + 10, y + 1, z + 6, Blocks.planks, 1, 3);
		world.setBlock(x + 0, y + 1, z + 7, Blocks.planks, 1, 3);
		world.setBlock(x + 1, y + 1, z + 7, Blocks.air, 0, 3);
		world.setBlock(x + 2, y + 1, z + 7, Blocks.air, 0, 3);
		world.setBlock(x + 3, y + 1, z + 7, Blocks.air, 0, 3);
		world.setBlock(x + 4, y + 1, z + 7, Blocks.air, 0, 3);
		world.setBlock(x + 5, y + 1, z + 7, Blocks.air, 0, 3);
		world.setBlock(x + 6, y + 1, z + 7, Blocks.air, 0, 3);
		world.setBlock(x + 7, y + 1, z + 7, Blocks.air, 0, 3);
		world.setBlock(x + 8, y + 1, z + 7, Blocks.air, 0, 3);
		world.setBlock(x + 9, y + 1, z + 7, Blocks.air, 0, 3);
		world.setBlock(x + 10, y + 1, z + 7, Blocks.planks, 1, 3);
		world.setBlock(x + 0, y + 1, z + 8, Blocks.cobblestone, 0, 3);
		world.setBlock(x + 1, y + 1, z + 8, Blocks.air, 0, 3);
		world.setBlock(x + 2, y + 1, z + 8, Blocks.air, 0, 3);
		world.setBlock(x + 3, y + 1, z + 8, Blocks.air, 0, 3);
		world.setBlock(x + 4, y + 1, z + 8, Blocks.air, 0, 3);
		world.setBlock(x + 5, y + 1, z + 8, Blocks.air, 0, 3);
		world.setBlock(x + 6, y + 1, z + 8, Blocks.air, 0, 3);
		world.setBlock(x + 7, y + 1, z + 8, Blocks.air, 0, 3);
		world.setBlock(x + 8, y + 1, z + 8, Blocks.air, 0, 3);
		world.setBlock(x + 9, y + 1, z + 8, Blocks.air, 0, 3);
		world.setBlock(x + 10, y + 1, z + 8, Blocks.planks, 1, 3);
		world.setBlock(x + 0, y + 1, z + 9, Blocks.cobblestone, 0, 3);
		world.setBlock(x + 1, y + 1, z + 9, Blocks.air, 0, 3);
		world.setBlock(x + 2, y + 1, z + 9, Blocks.air, 0, 3);
		world.setBlock(x + 3, y + 1, z + 9, Blocks.air, 0, 3);
		world.setBlock(x + 4, y + 1, z + 9, Blocks.air, 0, 3);
		world.setBlock(x + 5, y + 1, z + 9, Blocks.air, 0, 3);
		world.setBlock(x + 6, y + 1, z + 9, Blocks.air, 0, 3);
		world.setBlock(x + 7, y + 1, z + 9, Blocks.air, 0, 3);
		world.setBlock(x + 8, y + 1, z + 9, Blocks.air, 0, 3);
		world.setBlock(x + 9, y + 1, z + 9, Blocks.air, 0, 3);
		world.setBlock(x + 10, y + 1, z + 9, Blocks.stained_glass, 15, 3);
		world.setBlock(x + 0, y + 1, z + 10, Blocks.planks, 1, 3);
		world.setBlock(x + 1, y + 1, z + 10, Blocks.air, 0, 3);
		world.setBlock(x + 2, y + 1, z + 10, Blocks.air, 0, 3);
		world.setBlock(x + 3, y + 1, z + 10, Blocks.air, 0, 3);
		world.setBlock(x + 4, y + 1, z + 10, Blocks.air, 0, 3);
		world.setBlock(x + 5, y + 1, z + 10, Blocks.air, 0, 3);
		world.setBlock(x + 6, y + 1, z + 10, Blocks.air, 0, 3);
		world.setBlock(x + 7, y + 1, z + 10, Blocks.air, 0, 3);
		world.setBlock(x + 8, y + 1, z + 10, Blocks.air, 0, 3);
		world.setBlock(x + 9, y + 1, z + 10, Blocks.wool, 14, 3);
		world.setBlock(x + 10, y + 1, z + 10, Blocks.planks, 1, 3);
		world.setBlock(x + 0, y + 1, z + 11, Blocks.stained_glass, 15, 3);
		world.setBlock(x + 1, y + 1, z + 11, Blocks.air, 0, 3);
		world.setBlock(x + 2, y + 1, z + 11, Blocks.air, 0, 3);
		world.setBlock(x + 3, y + 1, z + 11, Blocks.jungle_stairs, 2, 3);
		world.setBlock(x + 4, y + 1, z + 11, Blocks.air, 0, 3);
		world.setBlock(x + 5, y + 1, z + 11, Blocks.air, 0, 3);
		world.setBlock(x + 6, y + 1, z + 11, Blocks.air, 0, 3);
		world.setBlock(x + 7, y + 1, z + 11, Blocks.air, 0, 3);
		world.setBlock(x + 8, y + 1, z + 11, Blocks.air, 0, 3);
		world.setBlock(x + 9, y + 1, z + 11, Blocks.wool, 14, 3);
		world.setBlock(x + 10, y + 1, z + 11, Blocks.planks, 1, 3);
		world.setBlock(x + 0, y + 1, z + 12, Blocks.planks, 1, 3);
		world.setBlock(x + 1, y + 1, z + 12, Blocks.stone_slab, 6, 3);
		world.setBlock(x + 2, y + 1, z + 12, Blocks.stone_slab, 6, 3);
		world.setBlock(x + 3, y + 1, z + 12, Blocks.stone_slab, 6, 3);
		world.setBlock(x + 4, y + 1, z + 12, Blocks.air, 0, 3);
		world.setBlock(x + 5, y + 1, z + 12, Blocks.air, 0, 3);
		world.setBlock(x + 6, y + 1, z + 12, Blocks.air, 0, 3);
		world.setBlock(x + 7, y + 1, z + 12, Blocks.air, 0, 3);
		world.setBlock(x + 8, y + 1, z + 12, Blocks.dark_oak_stairs, 6, 3);
		world.setBlock(x + 9, y + 1, z + 12, Blocks.dark_oak_stairs, 6, 3);
		world.setBlock(x + 10, y + 1, z + 12, Blocks.planks, 1, 3);
		world.setBlock(x + 0, y + 1, z + 13, Blocks.planks, 1, 3);
		world.setBlock(x + 1, y + 1, z + 13, Blocks.planks, 1, 3);
		world.setBlock(x + 2, y + 1, z + 13, Blocks.planks, 1, 3);
		world.setBlock(x + 3, y + 1, z + 13, Blocks.planks, 1, 3);
		world.setBlock(x + 4, y + 1, z + 13, Blocks.planks, 1, 3);
		world.setBlock(x + 5, y + 1, z + 13, Blocks.wooden_door, 5, 3);
		world.setBlock(x + 6, y + 1, z + 13, Blocks.planks, 1, 3);
		world.setBlock(x + 7, y + 1, z + 13, Blocks.wooden_door, 1, 3);
		world.setBlock(x + 8, y + 1, z + 13, Blocks.planks, 1, 3);
		world.setBlock(x + 9, y + 1, z + 13, Blocks.planks, 1, 3);
		world.setBlock(x + 10, y + 1, z + 13, Blocks.planks, 1, 3);
		world.setBlock(x + 0, y + 1, z + 14, Blocks.planks, 1, 3);
		world.setBlock(x + 1, y + 1, z + 14, Blocks.air, 0, 3);
		world.setBlock(x + 2, y + 1, z + 14, Blocks.air, 0, 3);
		world.setBlock(x + 3, y + 1, z + 14, Blocks.air, 0, 3);
		world.setBlock(x + 4, y + 1, z + 14, Blocks.air, 0, 3);
		world.setBlock(x + 5, y + 1, z + 14, Blocks.air, 0, 3);
		world.setBlock(x + 6, y + 1, z + 14, Blocks.air, 0, 3);
		world.setBlock(x + 7, y + 1, z + 14, Blocks.air, 0, 3);
		world.setBlock(x + 8, y + 1, z + 14, Blocks.air, 0, 3);
		world.setBlock(x + 9, y + 1, z + 14, Blocks.air, 0, 3);
		world.setBlock(x + 10, y + 1, z + 14, Blocks.planks, 1, 3);
		world.setBlock(x + 0, y + 1, z + 15, Blocks.planks, 1, 3);
		world.setBlock(x + 1, y + 1, z + 15, Blocks.air, 0, 3);
		world.setBlock(x + 2, y + 1, z + 15, Blocks.air, 0, 3);
		world.setBlock(x + 3, y + 1, z + 15, Blocks.air, 0, 3);
		world.setBlock(x + 4, y + 1, z + 15, Blocks.air, 0, 3);
		world.setBlock(x + 5, y + 1, z + 15, Blocks.air, 0, 3);
		world.setBlock(x + 6, y + 1, z + 15, Blocks.air, 0, 3);
		world.setBlock(x + 7, y + 1, z + 15, Blocks.air, 0, 3);
		world.setBlock(x + 8, y + 1, z + 15, Blocks.air, 0, 3);
		world.setBlock(x + 9, y + 1, z + 15, Blocks.air, 0, 3);
		world.setBlock(x + 10, y + 1, z + 15, Blocks.planks, 1, 3);
		world.setBlock(x + 0, y + 1, z + 16, Blocks.planks, 1, 3);
		world.setBlock(x + 1, y + 1, z + 16, Blocks.air, 0, 3);
		world.setBlock(x + 2, y + 1, z + 16, Blocks.air, 0, 3);
		world.setBlock(x + 3, y + 1, z + 16, Blocks.air, 0, 3);
		world.setBlock(x + 4, y + 1, z + 16, Blocks.air, 0, 3);
		world.setBlock(x + 5, y + 1, z + 16, Blocks.air, 0, 3);
		world.setBlock(x + 6, y + 1, z + 16, Blocks.air, 0, 3);
		world.setBlock(x + 7, y + 1, z + 16, Blocks.air, 0, 3);
		world.setBlock(x + 8, y + 1, z + 16, Blocks.air, 0, 3);
		world.setBlock(x + 9, y + 1, z + 16, Blocks.air, 0, 3);
		world.setBlock(x + 10, y + 1, z + 16, Blocks.planks, 1, 3);
		world.setBlock(x + 0, y + 1, z + 17, Blocks.planks, 1, 3);
		world.setBlock(x + 1, y + 1, z + 17, Blocks.planks, 1, 3);
		world.setBlock(x + 2, y + 1, z + 17, Blocks.planks, 1, 3);
		world.setBlock(x + 3, y + 1, z + 17, Blocks.planks, 1, 3);
		world.setBlock(x + 4, y + 1, z + 17, Blocks.planks, 1, 3);
		world.setBlock(x + 5, y + 1, z + 17, Blocks.planks, 1, 3);
		world.setBlock(x + 6, y + 1, z + 17, Blocks.planks, 1, 3);
		world.setBlock(x + 7, y + 1, z + 17, Blocks.planks, 1, 3);
		world.setBlock(x + 8, y + 1, z + 17, Blocks.planks, 1, 3);
		world.setBlock(x + 9, y + 1, z + 17, Blocks.planks, 1, 3);
		world.setBlock(x + 10, y + 1, z + 17, Blocks.planks, 1, 3);
		world.setBlock(x + 9, y + 1, z + 18, Blocks.air, 0, 3);
		world.setBlock(x + 0, y + 2, z + 0, Blocks.air, 0, 3);
		world.setBlock(x + 1, y + 2, z + 0, Blocks.air, 0, 3);
		world.setBlock(x + 2, y + 2, z + 0, Blocks.air, 0, 3);
		world.setBlock(x + 3, y + 2, z + 0, Blocks.air, 0, 3);
		world.setBlock(x + 4, y + 2, z + 0, Blocks.air, 0, 3);
		world.setBlock(x + 5, y + 2, z + 0, Blocks.air, 0, 3);
		world.setBlock(x + 6, y + 2, z + 0, Blocks.air, 0, 3);
		world.setBlock(x + 7, y + 2, z + 0, Blocks.air, 0, 3);
		world.setBlock(x + 8, y + 2, z + 0, Blocks.air, 0, 3);
		world.setBlock(x + 9, y + 2, z + 0, Blocks.air, 0, 3);
		world.setBlock(x + 10, y + 2, z + 0, Blocks.air, 0, 3);
		world.setBlock(x + 0, y + 2, z + 1, Blocks.air, 0, 3);
		world.setBlock(x + 1, y + 2, z + 1, Blocks.air, 0, 3);
		world.setBlock(x + 2, y + 2, z + 1, Blocks.air, 0, 3);
		world.setBlock(x + 3, y + 2, z + 1, Blocks.air, 0, 3);
		world.setBlock(x + 4, y + 2, z + 1, Blocks.air, 0, 3);
		world.setBlock(x + 5, y + 2, z + 1, Blocks.air, 0, 3);
		world.setBlock(x + 6, y + 2, z + 1, Blocks.air, 0, 3);
		world.setBlock(x + 7, y + 2, z + 1, Blocks.air, 0, 3);
		world.setBlock(x + 8, y + 2, z + 1, Blocks.air, 0, 3);
		world.setBlock(x + 9, y + 2, z + 1, Blocks.air, 0, 3);
		world.setBlock(x + 10, y + 2, z + 1, Blocks.air, 0, 3);
		world.setBlock(x + 0, y + 2, z + 2, Blocks.fence, 0, 3);
		world.setBlock(x + 1, y + 2, z + 2, Blocks.nether_brick_fence, 0, 3);
		world.setBlock(x + 2, y + 2, z + 2, Blocks.air, 0, 3);
		world.setBlock(x + 3, y + 2, z + 2, Blocks.air, 0, 3);
		world.setBlock(x + 4, y + 2, z + 2, Blocks.fence, 0, 3);
		world.setBlock(x + 5, y + 2, z + 2, Blocks.air, 0, 3);
		world.setBlock(x + 6, y + 2, z + 2, Blocks.fence, 0, 3);
		world.setBlock(x + 7, y + 2, z + 2, Blocks.air, 0, 3);
		world.setBlock(x + 8, y + 2, z + 2, Blocks.air, 0, 3);
		world.setBlock(x + 9, y + 2, z + 2, Blocks.air, 0, 3);
		world.setBlock(x + 10, y + 2, z + 2, Blocks.fence, 0, 3);
		world.setBlock(x + 0, y + 2, z + 3, Blocks.air, 0, 3);
		world.setBlock(x + 1, y + 2, z + 3, Blocks.air, 0, 3);
		world.setBlock(x + 2, y + 2, z + 3, Blocks.air, 0, 3);
		world.setBlock(x + 3, y + 2, z + 3, Blocks.air, 0, 3);
		world.setBlock(x + 4, y + 2, z + 3, Blocks.air, 0, 3);
		world.setBlock(x + 5, y + 2, z + 3, Blocks.air, 0, 3);
		world.setBlock(x + 6, y + 2, z + 3, Blocks.air, 0, 3);
		world.setBlock(x + 7, y + 2, z + 3, Blocks.air, 0, 3);
		world.setBlock(x + 8, y + 2, z + 3, Blocks.air, 0, 3);
		world.setBlock(x + 9, y + 2, z + 3, Blocks.air, 0, 3);
		world.setBlock(x + 10, y + 2, z + 3, Blocks.fence, 0, 3);
		world.setBlock(x + 0, y + 2, z + 4, Blocks.air, 0, 3);
		world.setBlock(x + 1, y + 2, z + 4, Blocks.nether_brick_fence, 0, 3);
		world.setBlock(x + 2, y + 2, z + 4, Blocks.air, 0, 3);
		world.setBlock(x + 3, y + 2, z + 4, Blocks.air, 0, 3);
		world.setBlock(x + 5, y + 2, z + 4, Blocks.air, 0, 3);
		world.setBlock(x + 6, y + 2, z + 4, Blocks.air, 0, 3);
		world.setBlock(x + 7, y + 2, z + 4, Blocks.air, 0, 3);
		world.setBlock(x + 8, y + 2, z + 4, Blocks.air, 0, 3);
		world.setBlock(x + 9, y + 2, z + 4, Blocks.air, 0, 3);
		world.setBlock(x + 10, y + 2, z + 4, Blocks.fence, 0, 3);
		world.setBlock(x + 0, y + 2, z + 5, Blocks.planks, 1, 3);
		world.setBlock(x + 1, y + 2, z + 5, Blocks.planks, 1, 3);
		world.setBlock(x + 2, y + 2, z + 5, Blocks.stained_glass, 15, 3);
		world.setBlock(x + 3, y + 2, z + 5, Blocks.planks, 1, 3);
		world.setBlock(x + 4, y + 2, z + 5, Blocks.planks, 1, 3);
		world.setBlock(x + 5, y + 2, z + 5, Blocks.wooden_door, 8, 3);
		world.setBlock(x + 6, y + 2, z + 5, Blocks.planks, 1, 3);
		world.setBlock(x + 7, y + 2, z + 5, Blocks.planks, 1, 3);
		world.setBlock(x + 8, y + 2, z + 5, Blocks.stained_glass, 15, 3);
		world.setBlock(x + 9, y + 2, z + 5, Blocks.planks, 1, 3);
		world.setBlock(x + 10, y + 2, z + 5, Blocks.planks, 1, 3);
		world.setBlock(x + 0, y + 2, z + 6, Blocks.planks, 1, 3);
		world.setBlock(x + 1, y + 2, z + 6, Blocks.air, 0, 3);
		world.setBlock(x + 2, y + 2, z + 6, Blocks.air, 0, 3);
		world.setBlock(x + 3, y + 2, z + 6, Blocks.air, 0, 3);
		world.setBlock(x + 4, y + 2, z + 6, Blocks.air, 0, 3);
		world.setBlock(x + 5, y + 2, z + 6, Blocks.air, 0, 3);
		world.setBlock(x + 6, y + 2, z + 6, Blocks.air, 0, 3);
		world.setBlock(x + 7, y + 2, z + 6, Blocks.air, 0, 3);
		world.setBlock(x + 8, y + 2, z + 6, Blocks.air, 0, 3);
		world.setBlock(x + 9, y + 2, z + 6, Blocks.air, 0, 3);
		world.setBlock(x + 10, y + 2, z + 6, Blocks.planks, 1, 3);
		world.setBlock(x + 0, y + 2, z + 7, Blocks.planks, 1, 3);
		world.setBlock(x + 1, y + 2, z + 7, Blocks.air, 0, 3);
		world.setBlock(x + 2, y + 2, z + 7, Blocks.air, 0, 3);
		world.setBlock(x + 3, y + 2, z + 7, Blocks.air, 0, 3);
		world.setBlock(x + 4, y + 2, z + 7, Blocks.air, 0, 3);
		world.setBlock(x + 5, y + 2, z + 7, Blocks.air, 0, 3);
		world.setBlock(x + 6, y + 2, z + 7, Blocks.air, 0, 3);
		world.setBlock(x + 7, y + 2, z + 7, Blocks.air, 0, 3);
		world.setBlock(x + 8, y + 2, z + 7, Blocks.air, 0, 3);
		world.setBlock(x + 9, y + 2, z + 7, Blocks.air, 0, 3);
		world.setBlock(x + 10, y + 2, z + 7, Blocks.planks, 1, 3);
		world.setBlock(x + 0, y + 2, z + 8, Blocks.spruce_stairs, 5, 3);
		world.setBlock(x + 1, y + 2, z + 8, Blocks.air, 0, 3);
		world.setBlock(x + 2, y + 2, z + 8, Blocks.air, 0, 3);
		world.setBlock(x + 3, y + 2, z + 8, Blocks.air, 0, 3);
		world.setBlock(x + 4, y + 2, z + 8, Blocks.air, 0, 3);
		world.setBlock(x + 5, y + 2, z + 8, Blocks.air, 0, 3);
		world.setBlock(x + 6, y + 2, z + 8, Blocks.air, 0, 3);
		world.setBlock(x + 7, y + 2, z + 8, Blocks.air, 0, 3);
		world.setBlock(x + 8, y + 2, z + 8, Blocks.air, 0, 3);
		world.setBlock(x + 9, y + 2, z + 8, Blocks.air, 0, 3);
		world.setBlock(x + 10, y + 2, z + 8, Blocks.planks, 1, 3);
		world.setBlock(x + 0, y + 2, z + 9, Blocks.spruce_stairs, 5, 3);
		world.setBlock(x + 1, y + 2, z + 9, Blocks.air, 0, 3);
		world.setBlock(x + 2, y + 2, z + 9, Blocks.air, 0, 3);
		world.setBlock(x + 3, y + 2, z + 9, Blocks.air, 0, 3);
		world.setBlock(x + 4, y + 2, z + 9, Blocks.air, 0, 3);
		world.setBlock(x + 5, y + 2, z + 9, Blocks.air, 0, 3);
		world.setBlock(x + 6, y + 2, z + 9, Blocks.air, 0, 3);
		world.setBlock(x + 7, y + 2, z + 9, Blocks.air, 0, 3);
		world.setBlock(x + 8, y + 2, z + 9, Blocks.air, 0, 3);
		world.setBlock(x + 9, y + 2, z + 9, Blocks.air, 0, 3);
		world.setBlock(x + 10, y + 2, z + 9, Blocks.stained_glass, 15, 3);
		world.setBlock(x + 0, y + 2, z + 10, Blocks.planks, 1, 3);
		world.setBlock(x + 1, y + 2, z + 10, Blocks.air, 0, 3);
		world.setBlock(x + 2, y + 2, z + 10, Blocks.air, 0, 3);
		world.setBlock(x + 3, y + 2, z + 10, Blocks.air, 0, 3);
		world.setBlock(x + 4, y + 2, z + 10, Blocks.air, 0, 3);
		world.setBlock(x + 5, y + 2, z + 10, Blocks.air, 0, 3);
		world.setBlock(x + 6, y + 2, z + 10, Blocks.air, 0, 3);
		world.setBlock(x + 7, y + 2, z + 10, Blocks.air, 0, 3);
		world.setBlock(x + 8, y + 2, z + 10, Blocks.air, 0, 3);
		world.setBlock(x + 9, y + 2, z + 10, Blocks.air, 0, 3);
		world.setBlock(x + 10, y + 2, z + 10, Blocks.planks, 1, 3);
		world.setBlock(x + 0, y + 2, z + 11, Blocks.stained_glass, 15, 3);
		world.setBlock(x + 1, y + 2, z + 11, Blocks.air, 0, 3);
		world.setBlock(x + 2, y + 2, z + 11, Blocks.air, 0, 3);
		world.setBlock(x + 3, y + 2, z + 11, Blocks.air, 0, 3);
		world.setBlock(x + 4, y + 2, z + 11, Blocks.air, 0, 3);
		world.setBlock(x + 5, y + 2, z + 11, Blocks.air, 0, 3);
		world.setBlock(x + 6, y + 2, z + 11, Blocks.air, 0, 3);
		world.setBlock(x + 7, y + 2, z + 11, Blocks.air, 0, 3);
		world.setBlock(x + 8, y + 2, z + 11, Blocks.air, 0, 3);
		world.setBlock(x + 9, y + 2, z + 11, Blocks.air, 0, 3);
		world.setBlock(x + 10, y + 2, z + 11, Blocks.planks, 1, 3);
		world.setBlock(x + 0, y + 2, z + 12, Blocks.planks, 1, 3);
		world.setBlock(x + 1, y + 2, z + 12, Blocks.air, 0, 3);
		world.setBlock(x + 2, y + 2, z + 12, Blocks.dark_oak_stairs, 6, 3);
		world.setBlock(x + 3, y + 2, z + 12, Blocks.dark_oak_stairs, 6, 3);
		world.setBlock(x + 4, y + 2, z + 12, Blocks.air, 0, 3);
		world.setBlock(x + 5, y + 2, z + 12, Blocks.air, 0, 3);
		world.setBlock(x + 6, y + 2, z + 12, Blocks.air, 0, 3);
		world.setBlock(x + 7, y + 2, z + 12, Blocks.air, 0, 3);
		world.setBlock(x + 8, y + 2, z + 12, Blocks.dark_oak_stairs, 6, 3);
		world.setBlock(x + 9, y + 2, z + 12, Blocks.dark_oak_stairs, 6, 3);
		world.setBlock(x + 10, y + 2, z + 12, Blocks.planks, 1, 3);
		world.setBlock(x + 0, y + 2, z + 13, Blocks.planks, 1, 3);
		world.setBlock(x + 1, y + 2, z + 13, Blocks.planks, 1, 3);
		world.setBlock(x + 2, y + 2, z + 13, Blocks.planks, 1, 3);
		world.setBlock(x + 3, y + 2, z + 13, Blocks.planks, 1, 3);
		world.setBlock(x + 4, y + 2, z + 13, Blocks.planks, 1, 3);
		world.setBlock(x + 5, y + 2, z + 13, Blocks.wooden_door, 8, 3);
		world.setBlock(x + 6, y + 2, z + 13, Blocks.planks, 1, 3);
		world.setBlock(x + 7, y + 2, z + 13, Blocks.wooden_door, 8, 3);
		world.setBlock(x + 8, y + 2, z + 13, Blocks.planks, 1, 3);
		world.setBlock(x + 9, y + 2, z + 13, Blocks.planks, 1, 3);
		world.setBlock(x + 10, y + 2, z + 13, Blocks.planks, 1, 3);
		world.setBlock(x + 0, y + 2, z + 14, Blocks.planks, 1, 3);
		world.setBlock(x + 1, y + 2, z + 14, Blocks.air, 0, 3);
		world.setBlock(x + 2, y + 2, z + 14, Blocks.air, 0, 3);
		world.setBlock(x + 3, y + 2, z + 14, Blocks.air, 0, 3);
		world.setBlock(x + 4, y + 2, z + 14, Blocks.air, 0, 3);
		world.setBlock(x + 5, y + 2, z + 14, Blocks.air, 0, 3);
		world.setBlock(x + 6, y + 2, z + 14, Blocks.air, 0, 3);
		world.setBlock(x + 7, y + 2, z + 14, Blocks.air, 0, 3);
		world.setBlock(x + 8, y + 2, z + 14, Blocks.air, 0, 3);
		world.setBlock(x + 9, y + 2, z + 14, Blocks.air, 0, 3);
		world.setBlock(x + 10, y + 2, z + 14, Blocks.planks, 1, 3);
		world.setBlock(x + 0, y + 2, z + 15, Blocks.planks, 1, 3);
		world.setBlock(x + 1, y + 2, z + 15, Blocks.air, 0, 3);
		world.setBlock(x + 2, y + 2, z + 15, Blocks.air, 0, 3);
		world.setBlock(x + 3, y + 2, z + 15, Blocks.air, 0, 3);
		world.setBlock(x + 4, y + 2, z + 15, Blocks.air, 0, 3);
		world.setBlock(x + 5, y + 2, z + 15, Blocks.air, 0, 3);
		world.setBlock(x + 6, y + 2, z + 15, Blocks.air, 0, 3);
		world.setBlock(x + 7, y + 2, z + 15, Blocks.air, 0, 3);
		world.setBlock(x + 8, y + 2, z + 15, Blocks.air, 0, 3);
		world.setBlock(x + 9, y + 2, z + 15, Blocks.air, 0, 3);
		world.setBlock(x + 10, y + 2, z + 15, Blocks.planks, 1, 3);
		world.setBlock(x + 0, y + 2, z + 16, Blocks.planks, 1, 3);
		world.setBlock(x + 1, y + 2, z + 16, Blocks.air, 0, 3);
		world.setBlock(x + 2, y + 2, z + 16, Blocks.air, 0, 3);
		world.setBlock(x + 3, y + 2, z + 16, Blocks.air, 0, 3);
		world.setBlock(x + 4, y + 2, z + 16, Blocks.air, 0, 3);
		world.setBlock(x + 5, y + 2, z + 16, Blocks.air, 0, 3);
		world.setBlock(x + 6, y + 2, z + 16, Blocks.air, 0, 3);
		world.setBlock(x + 7, y + 2, z + 16, Blocks.air, 0, 3);
		world.setBlock(x + 8, y + 2, z + 16, Blocks.air, 0, 3);
		world.setBlock(x + 9, y + 2, z + 16, Blocks.air, 0, 3);
		world.setBlock(x + 10, y + 2, z + 16, Blocks.planks, 1, 3);
		world.setBlock(x + 0, y + 2, z + 17, Blocks.planks, 1, 3);
		world.setBlock(x + 1, y + 2, z + 17, Blocks.planks, 1, 3);
		world.setBlock(x + 2, y + 2, z + 17, Blocks.planks, 1, 3);
		world.setBlock(x + 3, y + 2, z + 17, Blocks.planks, 1, 3);
		world.setBlock(x + 4, y + 2, z + 17, Blocks.planks, 1, 3);
		world.setBlock(x + 5, y + 2, z + 17, Blocks.planks, 1, 3);
		world.setBlock(x + 6, y + 2, z + 17, Blocks.planks, 1, 3);
		world.setBlock(x + 7, y + 2, z + 17, Blocks.planks, 1, 3);
		world.setBlock(x + 8, y + 2, z + 17, Blocks.planks, 1, 3);
		world.setBlock(x + 9, y + 2, z + 17, Blocks.planks, 1, 3);
		world.setBlock(x + 10, y + 2, z + 17, Blocks.planks, 1, 3);
		world.setBlock(x + 0, y + 3, z + 0, Blocks.air, 0, 3);
		world.setBlock(x + 1, y + 3, z + 0, Blocks.air, 0, 3);
		world.setBlock(x + 2, y + 3, z + 0, Blocks.air, 0, 3);
		world.setBlock(x + 3, y + 3, z + 0, Blocks.air, 0, 3);
		world.setBlock(x + 4, y + 3, z + 0, Blocks.air, 0, 3);
		world.setBlock(x + 5, y + 3, z + 0, Blocks.air, 0, 3);
		world.setBlock(x + 6, y + 3, z + 0, Blocks.air, 0, 3);
		world.setBlock(x + 7, y + 3, z + 0, Blocks.air, 0, 3);
		world.setBlock(x + 8, y + 3, z + 0, Blocks.air, 0, 3);
		world.setBlock(x + 9, y + 3, z + 0, Blocks.air, 0, 3);
		world.setBlock(x + 10, y + 3, z + 0, Blocks.air, 0, 3);
		world.setBlock(x + 0, y + 3, z + 1, Blocks.air, 0, 3);
		world.setBlock(x + 1, y + 3, z + 1, Blocks.air, 0, 3);
		world.setBlock(x + 2, y + 3, z + 1, Blocks.air, 0, 3);
		world.setBlock(x + 3, y + 3, z + 1, Blocks.air, 0, 3);
		world.setBlock(x + 4, y + 3, z + 1, Blocks.air, 0, 3);
		world.setBlock(x + 5, y + 3, z + 1, Blocks.air, 0, 3);
		world.setBlock(x + 6, y + 3, z + 1, Blocks.air, 0, 3);
		world.setBlock(x + 7, y + 3, z + 1, Blocks.air, 0, 3);
		world.setBlock(x + 8, y + 3, z + 1, Blocks.air, 0, 3);
		world.setBlock(x + 9, y + 3, z + 1, Blocks.air, 0, 3);
		world.setBlock(x + 10, y + 3, z + 1, Blocks.air, 0, 3);
		world.setBlock(x + 0, y + 3, z + 2, Blocks.wooden_slab, 5, 3);
		world.setBlock(x + 1, y + 3, z + 2, Blocks.wooden_slab, 5, 3);
		world.setBlock(x + 2, y + 3, z + 2, Blocks.wooden_slab, 5, 3);
		world.setBlock(x + 3, y + 3, z + 2, Blocks.wooden_slab, 5, 3);
		world.setBlock(x + 4, y + 3, z + 2, Blocks.wooden_slab, 5, 3);
		world.setBlock(x + 5, y + 3, z + 2, Blocks.wooden_slab, 5, 3);
		world.setBlock(x + 6, y + 3, z + 2, Blocks.wooden_slab, 5, 3);
		world.setBlock(x + 7, y + 3, z + 2, Blocks.wooden_slab, 5, 3);
		world.setBlock(x + 8, y + 3, z + 2, Blocks.wooden_slab, 5, 3);
		world.setBlock(x + 9, y + 3, z + 2, Blocks.wooden_slab, 5, 3);
		world.setBlock(x + 10, y + 3, z + 2, Blocks.wooden_slab, 5, 3);
		world.setBlock(x + 0, y + 3, z + 3, Blocks.dark_oak_stairs, 2, 3);
		world.setBlock(x + 1, y + 3, z + 3, Blocks.dark_oak_stairs, 2, 3);
		world.setBlock(x + 2, y + 3, z + 3, Blocks.dark_oak_stairs, 2, 3);
		world.setBlock(x + 3, y + 3, z + 3, Blocks.dark_oak_stairs, 2, 3);

		generate_r02(world, rand, x, y, z);
		return true;

	}
	
	public boolean generate_r02(World world, Random rand, int x, int y, int z)
	{

		world.setBlock(x + 4, y + 3, z + 3, Blocks.dark_oak_stairs, 2, 3);
		world.setBlock(x + 5, y + 3, z + 3, Blocks.dark_oak_stairs, 2, 3);
		world.setBlock(x + 6, y + 3, z + 3, Blocks.dark_oak_stairs, 2, 3);
		world.setBlock(x + 7, y + 3, z + 3, Blocks.dark_oak_stairs, 2, 3);
		world.setBlock(x + 8, y + 3, z + 3, Blocks.dark_oak_stairs, 2, 3);
		world.setBlock(x + 9, y + 3, z + 3, Blocks.dark_oak_stairs, 2, 3);
		world.setBlock(x + 10, y + 3, z + 3, Blocks.dark_oak_stairs, 2, 3);
		world.setBlock(x + 0, y + 3, z + 4, Blocks.wooden_slab, 13, 3);
		world.setBlock(x + 1, y + 3, z + 4, Blocks.wooden_slab, 13, 3);
		world.setBlock(x + 2, y + 3, z + 4, Blocks.wooden_slab, 13, 3);
		world.setBlock(x + 3, y + 3, z + 4, Blocks.wooden_slab, 13, 3);
		world.setBlock(x + 4, y + 3, z + 4, Blocks.wooden_slab, 13, 3);
		world.setBlock(x + 5, y + 3, z + 4, Blocks.wooden_slab, 13, 3);
		world.setBlock(x + 6, y + 3, z + 4, Blocks.wooden_slab, 13, 3);
		world.setBlock(x + 7, y + 3, z + 4, Blocks.wooden_slab, 13, 3);
		world.setBlock(x + 8, y + 3, z + 4, Blocks.wooden_slab, 13, 3);
		world.setBlock(x + 9, y + 3, z + 4, Blocks.wooden_slab, 13, 3);
		world.setBlock(x + 10, y + 3, z + 4, Blocks.wooden_slab, 13, 3);
		world.setBlock(x + 0, y + 3, z + 5, Blocks.planks, 1, 3);
		world.setBlock(x + 1, y + 3, z + 5, Blocks.planks, 1, 3);
		world.setBlock(x + 2, y + 3, z + 5, Blocks.planks, 1, 3);
		world.setBlock(x + 3, y + 3, z + 5, Blocks.planks, 1, 3);
		world.setBlock(x + 4, y + 3, z + 5, Blocks.planks, 1, 3);
		world.setBlock(x + 5, y + 3, z + 5, Blocks.planks, 1, 3);
		world.setBlock(x + 6, y + 3, z + 5, Blocks.planks, 1, 3);
		world.setBlock(x + 7, y + 3, z + 5, Blocks.planks, 1, 3);
		world.setBlock(x + 8, y + 3, z + 5, Blocks.planks, 1, 3);
		world.setBlock(x + 9, y + 3, z + 5, Blocks.planks, 1, 3);
		world.setBlock(x + 10, y + 3, z + 5, Blocks.planks, 1, 3);
		world.setBlock(x + 0, y + 3, z + 6, Blocks.planks, 1, 3);
		world.setBlock(x + 1, y + 3, z + 6, Blocks.air, 0, 3);
		world.setBlock(x + 2, y + 3, z + 6, Blocks.air, 0, 3);
		world.setBlock(x + 3, y + 3, z + 6, Blocks.air, 0, 3);
		world.setBlock(x + 4, y + 3, z + 6, Blocks.air, 0, 3);
		world.setBlock(x + 5, y + 3, z + 6, Blocks.air, 0, 3);
		world.setBlock(x + 6, y + 3, z + 6, Blocks.air, 0, 3);
		world.setBlock(x + 7, y + 3, z + 6, Blocks.air, 0, 3);
		world.setBlock(x + 8, y + 3, z + 6, Blocks.air, 0, 3);
		world.setBlock(x + 9, y + 3, z + 6, Blocks.web, 0, 3);
		world.setBlock(x + 10, y + 3, z + 6, Blocks.planks, 1, 3);
		world.setBlock(x + 0, y + 3, z + 7, Blocks.planks, 1, 3);
		world.setBlock(x + 1, y + 3, z + 7, Blocks.air, 0, 3);
		world.setBlock(x + 2, y + 3, z + 7, Blocks.air, 0, 3);
		world.setBlock(x + 3, y + 3, z + 7, Blocks.air, 0, 3);
		world.setBlock(x + 4, y + 3, z + 7, Blocks.air, 0, 3);
		world.setBlock(x + 5, y + 3, z + 7, Blocks.air, 0, 3);
		world.setBlock(x + 6, y + 3, z + 7, Blocks.air, 0, 3);
		world.setBlock(x + 7, y + 3, z + 7, Blocks.air, 0, 3);
		world.setBlock(x + 8, y + 3, z + 7, Blocks.air, 0, 3);
		world.setBlock(x + 9, y + 3, z + 7, Blocks.air, 0, 3);
		world.setBlock(x + 10, y + 3, z + 7, Blocks.planks, 1, 3);
		world.setBlock(x + 0, y + 3, z + 8, Blocks.planks, 1, 3);
		world.setBlock(x + 1, y + 3, z + 8, Blocks.air, 0, 3);
		world.setBlock(x + 2, y + 3, z + 8, Blocks.air, 0, 3);
		world.setBlock(x + 3, y + 3, z + 8, Blocks.air, 0, 3);
		world.setBlock(x + 4, y + 3, z + 8, Blocks.air, 0, 3);
		world.setBlock(x + 5, y + 3, z + 8, Blocks.air, 0, 3);
		world.setBlock(x + 6, y + 3, z + 8, Blocks.air, 0, 3);
		world.setBlock(x + 7, y + 3, z + 8, Blocks.air, 0, 3);
		world.setBlock(x + 8, y + 3, z + 8, Blocks.air, 0, 3);
		world.setBlock(x + 9, y + 3, z + 8, Blocks.air, 0, 3);
		world.setBlock(x + 10, y + 3, z + 8, Blocks.planks, 1, 3);
		world.setBlock(x + 0, y + 3, z + 9, Blocks.planks, 1, 3);
		world.setBlock(x + 1, y + 3, z + 9, Blocks.air, 0, 3);
		world.setBlock(x + 2, y + 3, z + 9, Blocks.air, 0, 3);
		world.setBlock(x + 3, y + 3, z + 9, Blocks.air, 0, 3);
		world.setBlock(x + 4, y + 3, z + 9, Blocks.air, 0, 3);
		world.setBlock(x + 5, y + 3, z + 9, Blocks.air, 0, 3);
		world.setBlock(x + 6, y + 3, z + 9, Blocks.air, 0, 3);
		world.setBlock(x + 7, y + 3, z + 9, Blocks.air, 0, 3);
		world.setBlock(x + 8, y + 3, z + 9, Blocks.air, 0, 3);
		world.setBlock(x + 9, y + 3, z + 9, Blocks.air, 0, 3);
		world.setBlock(x + 10, y + 3, z + 9, Blocks.planks, 1, 3);
		world.setBlock(x + 0, y + 3, z + 10, Blocks.planks, 1, 3);
		world.setBlock(x + 1, y + 3, z + 10, Blocks.air, 0, 3);
		world.setBlock(x + 2, y + 3, z + 10, Blocks.air, 0, 3);
		world.setBlock(x + 3, y + 3, z + 10, Blocks.air, 0, 3);
		world.setBlock(x + 4, y + 3, z + 10, Blocks.air, 0, 3);
		world.setBlock(x + 5, y + 3, z + 10, Blocks.air, 0, 3);
		world.setBlock(x + 6, y + 3, z + 10, Blocks.air, 0, 3);
		world.setBlock(x + 7, y + 3, z + 10, Blocks.air, 0, 3);
		world.setBlock(x + 8, y + 3, z + 10, Blocks.air, 0, 3);
		world.setBlock(x + 9, y + 3, z + 10, Blocks.air, 0, 3);
		world.setBlock(x + 10, y + 3, z + 10, Blocks.planks, 1, 3);
		world.setBlock(x + 0, y + 3, z + 11, Blocks.planks, 1, 3);
		world.setBlock(x + 1, y + 3, z + 11, Blocks.air, 0, 3);
		world.setBlock(x + 2, y + 3, z + 11, Blocks.air, 0, 3);
		world.setBlock(x + 3, y + 3, z + 11, Blocks.air, 0, 3);
		world.setBlock(x + 4, y + 3, z + 11, Blocks.air, 0, 3);
		world.setBlock(x + 5, y + 3, z + 11, Blocks.air, 0, 3);
		world.setBlock(x + 6, y + 3, z + 11, Blocks.air, 0, 3);
		world.setBlock(x + 7, y + 3, z + 11, Blocks.air, 0, 3);
		world.setBlock(x + 8, y + 3, z + 11, Blocks.air, 0, 3);
		world.setBlock(x + 9, y + 3, z + 11, Blocks.air, 0, 3);
		world.setBlock(x + 10, y + 3, z + 11, Blocks.planks, 1, 3);
		world.setBlock(x + 0, y + 3, z + 12, Blocks.planks, 1, 3);
		world.setBlock(x + 1, y + 3, z + 12, Blocks.web, 0, 3);
		world.setBlock(x + 2, y + 3, z + 12, Blocks.air, 0, 3);
		world.setBlock(x + 3, y + 3, z + 12, Blocks.air, 0, 3);
		world.setBlock(x + 4, y + 3, z + 12, Blocks.air, 0, 3);
		world.setBlock(x + 5, y + 3, z + 12, Blocks.air, 0, 3);
		world.setBlock(x + 6, y + 3, z + 12, Blocks.air, 0, 3);
		world.setBlock(x + 7, y + 3, z + 12, Blocks.air, 0, 3);
		world.setBlock(x + 8, y + 3, z + 12, Blocks.dark_oak_stairs, 6, 3);
		world.setBlock(x + 9, y + 3, z + 12, Blocks.dark_oak_stairs, 6, 3);
		world.setBlock(x + 10, y + 3, z + 12, Blocks.planks, 1, 3);
		world.setBlock(x + 0, y + 3, z + 13, Blocks.planks, 1, 3);
		world.setBlock(x + 1, y + 3, z + 13, Blocks.planks, 1, 3);
		world.setBlock(x + 2, y + 3, z + 13, Blocks.planks, 1, 3);
		world.setBlock(x + 3, y + 3, z + 13, Blocks.planks, 1, 3);
		world.setBlock(x + 4, y + 3, z + 13, Blocks.planks, 1, 3);
		world.setBlock(x + 5, y + 3, z + 13, Blocks.planks, 1, 3);
		world.setBlock(x + 6, y + 3, z + 13, Blocks.planks, 1, 3);
		world.setBlock(x + 7, y + 3, z + 13, Blocks.planks, 1, 3);
		world.setBlock(x + 8, y + 3, z + 13, Blocks.planks, 1, 3);
		world.setBlock(x + 9, y + 3, z + 13, Blocks.planks, 1, 3);
		world.setBlock(x + 10, y + 3, z + 13, Blocks.planks, 1, 3);
		world.setBlock(x + 0, y + 3, z + 14, Blocks.planks, 1, 3);
		world.setBlock(x + 1, y + 3, z + 14, Blocks.air, 0, 3);
		world.setBlock(x + 2, y + 3, z + 14, Blocks.air, 0, 3);
		world.setBlock(x + 3, y + 3, z + 14, Blocks.air, 0, 3);
		world.setBlock(x + 4, y + 3, z + 14, Blocks.air, 0, 3);
		world.setBlock(x + 5, y + 3, z + 14, Blocks.air, 0, 3);
		world.setBlock(x + 6, y + 3, z + 14, Blocks.air, 0, 3);
		world.setBlock(x + 7, y + 3, z + 14, Blocks.air, 0, 3);
		world.setBlock(x + 8, y + 3, z + 14, Blocks.air, 0, 3);
		world.setBlock(x + 9, y + 3, z + 14, Blocks.air, 0, 3);
		world.setBlock(x + 10, y + 3, z + 14, Blocks.planks, 1, 3);
		world.setBlock(x + 0, y + 3, z + 15, Blocks.planks, 1, 3);
		world.setBlock(x + 1, y + 3, z + 15, Blocks.air, 0, 3);
